Workbook

Sheet Dashboard
A1: EXOS Aerospace Fundraise CRM Dashboard
A3: Round Target | B3: $10.0M Series A | D3: Daily Call Goal | E3: 2 | F3: Stretch Goal | G3: 3
A6: As of | B6: =TODAY() | D6: Pipeline by Stage | G6: Tier Mix
A7: Total Contacts | B7: =COUNTA(CRM_Master!E:E)-1 | D7: Research | E7: =COUNTIF(CRM_Master!L:L,"Research") | G7: Tier 1 | H7: =COUNTIF(CRM_Master!N:N,"Tier 1")
A8: Unique Firms | B8: =COUNTA(Firm_Summary!A:A)-1 | D8: Contacted | E8: =COUNTIF(CRM_Master!L:L,"Contacted") | G8: Tier 2 | H8: =COUNTIF(CRM_Master!N:N,"Tier 2")
A9: Active (not passed) | B9: =COUNTIF(CRM_Master!AC:AC,"Active") | D9: Follow Up | E9: =COUNTIF(CRM_Master!L:L,"Follow Up") | G9: Tier 3 | H9: =COUNTIF(CRM_Master!N:N,"Tier 3")
A10: Due Now | B10: =COUNTIF(CRM_Master!S:S,"DUE") | D10: Meeting Requested | E10: =COUNTIF(CRM_Master!L:L,"Meeting Requested")
A11: Tier 1 Due Now | B11: =COUNTIFS(CRM_Master!S:S,"DUE",CRM_Master!N:N,"Tier 1") | D11: Meeting Held | E11: =COUNTIF(CRM_Master!L:L,"Meeting Held")
A12: Meetings / Engaged | B12: =COUNTIFS(CRM_Master!L:L,"Meeting Requested")+COUNTIFS(CRM_Master!L:L,"Meeting Held")+COUNTIFS(CRM_Master!L:L,"Engaged")+COUNTIFS(CRM_Master!L:L,"Term Sheet / Proposal") | D12: How to use | E12: =COUNTIF(CRM_Master!L:L,"Engaged")
A13: Suggested Calls Today | B13: =MIN($G$3,COUNTIFS(CRM_Master!S:S,"DUE",CRM_Master!AC:AC,"Active",CRM_Master!N:N,"<>Tier 3")) | D13: 1) Work Today_Queue first. 2) Log every touch in CRM_Master. 3) Update Stage, Last Touch, and Notes after each interaction. 4) Keep 2–3 calls/day booked.

Sheet CRM_Master
A1: Record ID | B1: Source Sheets | C1: Category | D1: Company | E1: Contact Name | F1: Title / Role | G1: Primary Email | H1: Additional Emails | I1: Phone | J1: LinkedIn / Bio | K1: Owner | L1: Stage | M1: Fit Thesis | N1: Priority Tier | O1: First Outreach | P1: Last Touch | Q1: Days Since Last Touch | R1: Next Touch | S1: Due? | T1: Meeting Status | U1: Warm Intro / Referral | V1: Offer / Structure | W1: Notes | X1: Source Row(s) | Y1: Next Action | Z1: Cadence (Days) | AA1: Priority Score | AB1: Book Call? | AC1: Status
A2: EXOS-0001 | B2: Derek Contacts | JQ Follow Up | Term Sheets | C2: Financial Investor | D2: AxisCades | E2: Suresh Babu Suryadevara | F2: VP Aerospace & Defense | G2: suresh.s@axiscades.in | H2: arun.arumugam@axiscades.in; rithvick.naidu@axiscades.in | K2: John Quinn | L2: Term Sheet / Proposal | M2: Space / Defense / Aerospace / Advanced Manufacturing | N2: Tier 1 | P2: 46055 | Q2: =IF(P2="","",TODAY()-P2) | R2: =IF(OR(L2="Passed",Z2=""),"",P2+Z2) | S2: =IF(OR(R2="",L2="Passed"),"",IF(R2<=TODAY(),"DUE",IF(R2<=TODAY()+3,"Next 3 Days","Later"))) | T2: Meeting scheduled / held | V2: Strategic Partnership- Equity deal | W2: Missed call toady at 08:30 - Follow-up framework shared outlining a phased, ITAR/EAR-compliant strategic partnership. Proposal includes AxisCades acquiring 51% of SSLC for $10M (phased capital), international sales support with commission structure, and long-term India-based manufacturing under TAA/MLA approvals. Discussions ongoing to confirm alignment on structure, valuation, and next steps. | toured SSLC on 2/16 | met in person at EXOS on 12/19, follow up set for onsite visit 1/19 | request for SSLC visit on hold pending establishment of basic term sheet. | X2: Term Sheets!2 | JQ Follow Up!4 | Derek Contacts!8 | Y2: Review terms and push decision process | Z2: 2 | AA2: =IF(AC2="Archived",0,ROUND((IF(N2="Tier 1",35,IF(N2="Tier 2",20,8))+IF(C2="Financial Investor",15,IF(C2="Intermediary / Banker",12,8))+IF(L2="Term Sheet / Proposal",25,IF(L2="Engaged",20,IF(L2="Meeting Requested",18,IF(L2="Meeting Held",14,IF(L2="Follow Up",10,5)))))+MIN(Q2,30)+IF(S2="DUE",15,IF(S2="Next 3 Days",8,0))),0)) | AB2: =IF(AND(AC2="Active",OR(N2="Tier 1",N2="Tier 2"),OR(S2="DUE",S2="Next 3 Days")),"YES","") | AC2: =IF(L2="Passed","Archived","Active")
A3: EXOS-0002 | B3: Term Sheets | C3: Intermediary / Banker | D3: Bancroft Capital (Bancroft4Vets) | E3: Jason Diamond | G3: jdiamond@bancroft4vets.com | H3: kcariaga@bancroft4vets.com; rmalin@bancroft4vets.com; jgoodman@bancroft4vets.com | K3: John Quinn | L3: Term Sheet / Proposal | M3: Capital raise support / placement | N3: Tier 1 | Q3: =IF(P3="","",TODAY()-P3) | R3: =IF(OR(L3="Passed",Z3=""),"",P3+Z3) | S3: =IF(OR(R3="",L3="Passed"),"",IF(R3<=TODAY(),"DUE",IF(R3<=TODAY()+3,"Next 3 Days","Later"))) | T3: Meeting scheduled / held | V3: Investment Banking / Capital Raise | W3: Introduced via Kipton Cariaga. Terms/presentation shared. Defense- and veteran-focused investment bank. Logged for tracking and follow-up; no term sheet yet. Engaging BTIG 2-26-26 | 01/16/2026 | At their request, sent forward-ready cover email with high-level company overview and $10M raise summary, along with attached presentations. Materials prepared for direct circulation to IB partners and investor network (Jason forwarding internally). Awaiting feedback and/or investor introductions. | X3: Term Sheets!6 | Y3: Review terms and push decision process | Z3: 2 | AA3: =IF(AC3="Archived",0,ROUND((IF(N3="Tier 1",35,IF(N3="Tier 2",20,8))+IF(C3="Financial Investor",15,IF(C3="Intermediary / Banker",12,8))+IF(L3="Term Sheet / Proposal",25,IF(L3="Engaged",20,IF(L3="Meeting Requested",18,IF(L3="Meeting Held",14,IF(L3="Follow Up",10,5)))))+MIN(Q3,30)+IF(S3="DUE",15,IF(S3="Next 3 Days",8,0))),0)) | AB3: =IF(AND(AC3="Active",OR(N3="Tier 1",N3="Tier 2"),OR(S3="DUE",S3="Next 3 Days")),"YES","") | AC3: =IF(L3="Passed","Archived","Active")
A4: EXOS-0003 | B4: John - Investor Contacts | C4: Financial Investor | D4: Cerberus Capital Management | E4: Dan Quayle | G4: dquayle@cerberus.com | K4: John Quinn | L4: Term Sheet / Proposal | M4: Space / Defense / Aerospace / Advanced Manufacturing | N4: Tier 1 | O4: 45968 | P4: 46023 | Q4: =IF(P4="","",TODAY()-P4) | R4: =IF(OR(L4="Passed",Z4=""),"",P4+Z4) | S4: =IF(OR(R4="",L4="Passed"),"",IF(R4<=TODAY(),"DUE",IF(R4<=TODAY()+3,"Next 3 Days","Later"))) | T4: Meeting scheduled / held | V4: Strategic Partner / Growth Capital | W4: 01/14/2026 | Introductory conversation held; John sent story deck, finance-focused deck, and one-pager today. Framed as strategic partner aligned with Scorpius acquisition, revenue expansion, and hypersonics / Golden Dome support. Added as potential strategic partner for board consideration. Awaiting response. | X4: John - Investor Contacts!862 | Y4: Review terms and push decision process | Z4: 2 | AA4: =IF(AC4="Archived",0,ROUND((IF(N4="Tier 1",35,IF(N4="Tier 2",20,8))+IF(C4="Financial Investor",15,IF(C4="Intermediary / Banker",12,8))+IF(L4="Term Sheet / Proposal",25,IF(L4="Engaged",20,IF(L4="Meeting Requested",18,IF(L4="Meeting Held",14,IF(L4="Follow Up",10,5)))))+MIN(Q4,30)+IF(S4="DUE",15,IF(S4="Next 3 Days",8,0))),0)) | AB4: =IF(AND(AC4="Active",OR(N4="Tier 1",N4="Tier 2"),OR(S4="DUE",S4="Next 3 Days")),"YES","") | AC4: =IF(L4="Passed","Archived","Active")
A5: EXOS-0004 | B5: John - Investor Contacts | C5: Financial Investor | D5: Cerberus Capital Management | E5: Frank Bruno | G5: fbruno@cerberus.com | K5: John Quinn | L5: Term Sheet / Proposal | M5: Space / Defense / Aerospace / Advanced Manufacturing | N5: Tier 1 | O5: 45968 | P5: 46023 | Q5: =IF(P5="","",TODAY()-P5) | R5: =IF(OR(L5="Passed",Z5=""),"",P5+Z5) | S5: =IF(OR(R5="",L5="Passed"),"",IF(R5<=TODAY(),"DUE",IF(R5<=TODAY()+3,"Next 3 Days","Later"))) | T5: Meeting scheduled / held | V5: Strategic Partner / Growth Capital | W5: 01/14/2026 | Introductory conversation held; John sent story deck, finance-focused deck, and one-pager today. Framed as strategic partner aligned with Scorpius acquisition, revenue expansion, and hypersonics / Golden Dome support. Added as potential strategic partner for board consideration. Awaiting response. | X5: John - Investor Contacts!861 | Y5: Review terms and push decision process | Z5: 2 | AA5: =IF(AC5="Archived",0,ROUND((IF(N5="Tier 1",35,IF(N5="Tier 2",20,8))+IF(C5="Financial Investor",15,IF(C5="Intermediary / Banker",12,8))+IF(L5="Term Sheet / Proposal",25,IF(L5="Engaged",20,IF(L5="Meeting Requested",18,IF(L5="Meeting Held",14,IF(L5="Follow Up",10,5)))))+MIN(Q5,30)+IF(S5="DUE",15,IF(S5="Next 3 Days",8,0))),0)) | AB5: =IF(AND(AC5="Active",OR(N5="Tier 1",N5="Tier 2"),OR(S5="DUE",S5="Next 3 Days")),"YES","") | AC5: =IF(L5="Passed","Archived","Active")
A6: EXOS-0005 | B6: JQ Follow Up | Term Sheets | C6: Financial Investor | D6: Cerberus Capital Management | E6: Kent (Cerberus Ops) | G6: consult-klietzau@cerberusoperations.com | K6: John Quinn | L6: Term Sheet / Proposal | M6: Space / Defense / Aerospace / Advanced Manufacturing | N6: Tier 1 | P6: 46023 | Q6: =IF(P6="","",TODAY()-P6) | R6: =IF(OR(L6="Passed",Z6=""),"",P6+Z6) | S6: =IF(OR(R6="",L6="Passed"),"",IF(R6<=TODAY(),"DUE",IF(R6<=TODAY()+3,"Next 3 Days","Later"))) | T6: Meeting scheduled / held | V6: Strategic Partner / Growth Capital | W6: Introductory conversation held; John sent story deck, finance-focused deck, and one-pager today. Framed as strategic partner aligned with Scorpius acquisition, revenue expansion, and hypersonics / Golden Dome support. Added as potential strategic partner for board consideration. Awaiting response. | X6: Term Sheets!11 | JQ Follow Up!25 | Y6: Review terms and push decision process | Z6: 2 | AA6: =IF(AC6="Archived",0,ROUND((IF(N6="Tier 1",35,IF(N6="Tier 2",20,8))+IF(C6="Financial Investor",15,IF(C6="Intermediary / Banker",12,8))+IF(L6="Term Sheet / Proposal",25,IF(L6="Engaged",20,IF(L6="Meeting Requested",18,IF(L6="Meeting Held",14,IF(L6="Follow Up",10,5)))))+MIN(Q6,30)+IF(S6="DUE",15,IF(S6="Next 3 Days",8,0))),0)) | AB6: =IF(AND(AC6="Active",OR(N6="Tier 1",N6="Tier 2"),OR(S6="DUE",S6="Next 3 Days")),"YES","") | AC6: =IF(L6="Passed","Archived","Active")
A7: EXOS-0006 | B7: Derek Contacts | JQ Follow Up | Term Sheets | C7: Financial Investor | D7: Cloris Capital Group LLC | E7: Tahmina Khan | F7: CEO | G7: tahmina.investing@gmail.com | H7: hawken@edgewatersg.com; daniel.murillo@edgewatersg.com | K7: John Quinn | L7: Term Sheet / Proposal | M7: Space / Defense / Aerospace / Advanced Manufacturing | N7: Tier 1 | Q7: =IF(P7="","",TODAY()-P7) | R7: =IF(OR(L7="Passed",Z7=""),"",P7+Z7) | S7: =IF(OR(R7="",L7="Passed"),"",IF(R7<=TODAY(),"DUE",IF(R7<=TODAY()+3,"Next 3 Days","Later"))) | T7: Meeting scheduled / held | U7: referred by Dereck | V7: Capital Partner (Equity / Strategic) 2% of transaction | W7: Completed discussions with both ETL and IronGate. No follow-up correspondence received to date. Awaiting next steps or investor feedback. | Investor requested documentation showing revenue for the past three years and indicated interest if trailing 12-month revenue reflects ~$1M. Financial documents sent by John. Awaiting response/feedback. | 11/24 call and materials sent | email outreach has been sent to all | X7: Term Sheets!4 | JQ Follow Up!16 | Derek Contacts!12 | Y7: Review terms and push decision process | Z7: 2 | AA7: =IF(AC7="Archived",0,ROUND((IF(N7="Tier 1",35,IF(N7="Tier 2",20,8))+IF(C7="Financial Investor",15,IF(C7="Intermediary / Banker",12,8))+IF(L7="Term Sheet / Proposal",25,IF(L7="Engaged",20,IF(L7="Meeting Requested",18,IF(L7="Meeting Held",14,IF(L7="Follow Up",10,5)))))+MIN(Q7,30)+IF(S7="DUE",15,IF(S7="Next 3 Days",8,0))),0)) | AB7: =IF(AND(AC7="Active",OR(N7="Tier 1",N7="Tier 2"),OR(S7="DUE",S7="Next 3 Days")),"YES","") | AC7: =IF(L7="Passed","Archived","Active")
A8: EXOS-0007 | B8: Derek Contacts | JQ Follow Up | Term Sheets | C8: Financial Investor | D8: Craft Capital | E8: Brandon Golenda | G8: bgolenda@craftcm.com | H8: alexhamilton@optonline.net; ryanhamilton02@gmail.com | K8: John Quinn | L8: Term Sheet / Proposal | M8: Space / Defense / Aerospace / Advanced Manufacturing | N8: Tier 1 | P8: 46020 | Q8: =IF(P8="","",TODAY()-P8) | R8: =IF(OR(L8="Passed",Z8=""),"",P8+Z8) | S8: =IF(OR(R8="",L8="Passed"),"",IF(R8<=TODAY(),"DUE",IF(R8<=TODAY()+3,"Next 3 Days","Later"))) | T8: Meeting scheduled / held | U8: referred by Dereck | V8: Advisory (Paid) Cost of finance: $30k fixed + 4–8% cash + 8% equity/warrants (if they introduce the capital) How to exclude other funding: The agreement already limits fees to Craft-introduced investors only, but You should formalize exclusions in writing immediately to avoid disputes. | W8: Advisory offer contingent on $30K fee. We chose not to proceed; parked. | $30K Investment bank enagement $10k/mo for 3 months advisor only. no funds. | X8: Term Sheets!21 | JQ Follow Up!9 | Derek Contacts!13 | Y8: Review terms and push decision process | Z8: 2 | AA8: =IF(AC8="Archived",0,ROUND((IF(N8="Tier 1",35,IF(N8="Tier 2",20,8))+IF(C8="Financial Investor",15,IF(C8="Intermediary / Banker",12,8))+IF(L8="Term Sheet / Proposal",25,IF(L8="Engaged",20,IF(L8="Meeting Requested",18,IF(L8="Meeting Held",14,IF(L8="Follow Up",10,5)))))+MIN(Q8,30)+IF(S8="DUE",15,IF(S8="Next 3 Days",8,0))),0)) | AB8: =IF(AND(AC8="Active",OR(N8="Tier 1",N8="Tier 2"),OR(S8="DUE",S8="Next 3 Days")),"YES","") | AC8: =IF(L8="Passed","Archived","Active")
A9: EXOS-0008 | B9: Term Sheets | C9: Financial Investor | D9: DelMorgan & Co | E9: RJ Mollen | G9: rjm@delmorganco.com | K9: John Quinn | L9: Term Sheet / Proposal | M9: Space / Defense / Aerospace / Advanced Manufacturing | N9: Tier 1 | P9: 46037 | Q9: =IF(P9="","",TODAY()-P9) | R9: =IF(OR(L9="Passed",Z9=""),"",P9+Z9) | S9: =IF(OR(R9="",L9="Passed"),"",IF(R9<=TODAY(),"DUE",IF(R9<=TODAY()+3,"Next 3 Days","Later"))) | T9: Meeting scheduled / held | V9: Strategic Advisory / Infrastructure & Capital Access | W9: Talked and rejected offer- RJ proposed two alternative advisory paths outside the DelMorgan framework: (1) Fast Space infrastructure and asset monetization strategy, and (2) Gleam Consulting advisory + investor introductions tied to a $10M raise. Fee-based advisory with equity success bonuses. Not aligned with current priorities; documented for reference. | X9: Term Sheets!24 | Y9: Review terms and push decision process | Z9: 2 | AA9: =IF(AC9="Archived",0,ROUND((IF(N9="Tier 1",35,IF(N9="Tier 2",20,8))+IF(C9="Financial Investor",15,IF(C9="Intermediary / Banker",12,8))+IF(L9="Term Sheet / Proposal",25,IF(L9="Engaged",20,IF(L9="Meeting Requested",18,IF(L9="Meeting Held",14,IF(L9="Follow Up",10,5)))))+MIN(Q9,30)+IF(S9="DUE",15,IF(S9="Next 3 Days",8,0))),0)) | AB9: =IF(AND(AC9="Active",OR(N9="Tier 1",N9="Tier 2"),OR(S9="DUE",S9="Next 3 Days")),"YES","") | AC9: =IF(L9="Passed","Archived","Active")
A10: EXOS-0009 | B10: Term Sheets | C10: Financial Investor | D10: InvestFortuna | E10: Sean Bromley | G10: sbromley@investfortuna.com | H10: veghtesad@investfortuna.com | K10: John Quinn | L10: Term Sheet / Proposal | M10: Space / Defense / Aerospace / Advanced Manufacturing | N10: Tier 1 | P10: 46023 | Q10: =IF(P10="","",TODAY()-P10) | R10: =IF(OR(L10="Passed",Z10=""),"",P10+Z10) | S10: =IF(OR(R10="",L10="Passed"),"",IF(R10<=TODAY(),"DUE",IF(R10<=TODAY()+3,"Next 3 Days","Later"))) | T10: Meeting scheduled / held | V10: Advisory + Bridge / IPO Path | W10: The .4 term sheet, as drafted, is not registrable, not exchange-compliant, and not defensible for directors. It can be salvaged only through structural changes that align it with industry norms that they rejected. | 01/15/2026 | Fortuna proposed an IPO-led advisory structure including a warrant offering, $5M minimum bridge financing (convertible at significant discount), and a $15M IPO financing, with substantial embedded dilution and control provisions. EXOS submitted a formal counter-term sheet replacing discounted instruments and automatic vesting with performance-based earn-out equity tied to post-IPO share price and market cap milestones, preserving a clean cap table and fiduciary compliance. Negotiations ongoing; awaiting Fortuna response. | X10: Term Sheets!16 | Y10: Review terms and push decision process | Z10: 2 | AA10: =IF(AC10="Archived",0,ROUND((IF(N10="Tier 1",35,IF(N10="Tier 2",20,8))+IF(C10="Financial Investor",15,IF(C10="Intermediary / Banker",12,8))+IF(L10="Term Sheet / Proposal",25,IF(L10="Engaged",20,IF(L10="Meeting Requested",18,IF(L10="Meeting Held",14,IF(L10="Follow Up",10,5)))))+MIN(Q10,30)+IF(S10="DUE",15,IF(S10="Next 3 Days",8,0))),0)) | AB10: =IF(AND(AC10="Active",OR(N10="Tier 1",N10="Tier 2"),OR(S10="DUE",S10="Next 3 Days")),"YES","") | AC10: =IF(L10="Passed","Archived","Active")
A11: EXOS-0010 | B11: Term Sheets | C11: Financial Investor | D11: Pickwick Capital | E11: Crescent Varrone | G11: varronec@pickwickcapital.com | H11: alvarezd@pickwickcapital.com; sauterm@pickwickcapital.com | K11: John Quinn | L11: Term Sheet / Proposal | M11: Space / Defense / Aerospace / Advanced Manufacturing | N11: Tier 1 | P11: 46031 | Q11: =IF(P11="","",TODAY()-P11) | R11: =IF(OR(L11="Passed",Z11=""),"",P11+Z11) | S11: =IF(OR(R11="",L11="Passed"),"",IF(R11<=TODAY(),"DUE",IF(R11<=TODAY()+3,"Next 3 Days","Later"))) | T11: Meeting scheduled / held | V11: Capital Partner (Equity / Strategic) $15k/ mon 6 Months | W11: Active discussions underway. Pickwick has expressed interest; no term sheet yet. John had producitive meeting on 1/9. | 01/15/2026 | X11: Term Sheets!15 | Y11: Review terms and push decision process | Z11: 2 | AA11: =IF(AC11="Archived",0,ROUND((IF(N11="Tier 1",35,IF(N11="Tier 2",20,8))+IF(C11="Financial Investor",15,IF(C11="Intermediary / Banker",12,8))+IF(L11="Term Sheet / Proposal",25,IF(L11="Engaged",20,IF(L11="Meeting Requested",18,IF(L11="Meeting Held",14,IF(L11="Follow Up",10,5)))))+MIN(Q11,30)+IF(S11="DUE",15,IF(S11="Next 3 Days",8,0))),0)) | AB11: =IF(AND(AC11="Active",OR(N11="Tier 1",N11="Tier 2"),OR(S11="DUE",S11="Next 3 Days")),"YES","") | AC11: =IF(L11="Passed","Archived","Active")
A12: EXOS-0011 | B12: JQ Follow Up | C12: Financial Investor | D12: Pickwick Capital | E12: Crescent Varrone | G12: alvarezd@pickwickcapital.com | H12: sauterm@pickwickcapital.com | I12: Capital Partner (Equity / Strategic) | K12: John Quinn | L12: Term Sheet / Proposal | M12: Space / Defense / Aerospace / Advanced Manufacturing | N12: Tier 1 | P12: 46031 | Q12: =IF(P12="","",TODAY()-P12) | R12: =IF(OR(L12="Passed",Z12=""),"",P12+Z12) | S12: =IF(OR(R12="",L12="Passed"),"",IF(R12<=TODAY(),"DUE",IF(R12<=TODAY()+3,"Next 3 Days","Later"))) | T12: Meeting scheduled / held | U12: varronec@pickwickcapital.com | V12: Capital Partner (Equity / Strategic) $15k/ mon 6 Months | W12: Active discussions underway. Pickwick has expressed interest; no term sheet yet. John had producitive meeting on 1/9. | 01/15/2026 | X12: JQ Follow Up!29 | Y12: Review terms and push decision process | Z12: 2 | AA12: =IF(AC12="Archived",0,ROUND((IF(N12="Tier 1",35,IF(N12="Tier 2",20,8))+IF(C12="Financial Investor",15,IF(C12="Intermediary / Banker",12,8))+IF(L12="Term Sheet / Proposal",25,IF(L12="Engaged",20,IF(L12="Meeting Requested",18,IF(L12="Meeting Held",14,IF(L12="Follow Up",10,5)))))+MIN(Q12,30)+IF(S12="DUE",15,IF(S12="Next 3 Days",8,0))),0)) | AB12: =IF(AND(AC12="Active",OR(N12="Tier 1",N12="Tier 2"),OR(S12="DUE",S12="Next 3 Days")),"YES","") | AC12: =IF(L12="Passed","Archived","Active")
A13: EXOS-0012 | B13: Term Sheets | C13: Intermediary / Banker | D13: Sunbelt Dallas Metro | E13: Bill Nicholson | G13: bnicholson@sunbeltnetwork.com | K13: John Quinn | L13: Term Sheet / Proposal | M13: Capital raise support / placement | N13: Tier 1 | P13: 46083 | Q13: =IF(P13="","",TODAY()-P13) | R13: =IF(OR(L13="Passed",Z13=""),"",P13+Z13) | S13: =IF(OR(R13="",L13="Passed"),"",IF(R13<=TODAY(),"DUE",IF(R13<=TODAY()+3,"Next 3 Days","Later"))) | T13: Meeting scheduled / held | V13: Proposed intermediary engagement (retainer + success fee model under discussion; Board requesting performance-based structure) | W13: Sunbelt inquired about including a retainer amount in the Engagement Letter. John responded that the EXOS Board is unlikely to approve another open-ended retainer structure due to prior experiences with retainers that did not yield measurable outcomes. The Board is prioritizing: Clearly defined deliverables Performance-aligned compensation Objective execution milestones Defined transaction targets SEC-compliant structure (broker-dealer participation as required) John encouraged Sunbelt to propose a performance-based framework (reduced/deferred retainer, milestone-triggered payments, or primarily success-fee based on capital secured). Bill acknowledged and is coordinating internally to revise the proposal. He requested timing of the next Board meeting. Status: Awaiting revised engagement structure from Sunbelt for Board review. | sent email letting him know board doesn't want to pat retainer fees | X13: Term Sheets!9 | Y13: Review terms and push decision process | Z13: 2 | AA13: =IF(AC13="Archived",0,ROUND((IF(N13="Tier 1",35,IF(N13="Tier 2",20,8))+IF(C13="Financial Investor",15,IF(C13="Intermediary / Banker",12,8))+IF(L13="Term Sheet / Proposal",25,IF(L13="Engaged",20,IF(L13="Meeting Requested",18,IF(L13="Meeting Held",14,IF(L13="Follow Up",10,5)))))+MIN(Q13,30)+IF(S13="DUE",15,IF(S13="Next 3 Days",8,0))),0)) | AB13: =IF(AND(AC13="Active",OR(N13="Tier 1",N13="Tier 2"),OR(S13="DUE",S13="Next 3 Days")),"YES","") | AC13: =IF(L13="Passed","Archived","Active")
A14: EXOS-0013 | B14: JQ Follow Up | Term Sheets | C14: Financial Investor | D14: US Capital | E14: Ashley Curless | G14: acurless@uscapital.com | H14: csims@uscapital.com; bchristopher@uscapital.com; mjlevas@uscapital.com; jhgonzalez@uscapital.com; mcohen@uscapital.com | K14: John Quinn | L14: Term Sheet / Proposal | M14: Space / Defense / Aerospace / Advanced Manufacturing | N14: Tier 1 | P14: 45986 | Q14: =IF(P14="","",TODAY()-P14) | R14: =IF(OR(L14="Passed",Z14=""),"",P14+Z14) | S14: =IF(OR(R14="",L14="Passed"),"",IF(R14<=TODAY(),"DUE",IF(R14<=TODAY()+3,"Next 3 Days","Later"))) | T14: Meeting scheduled / held | U14: referred by Dereck | V14: Capital Raise (Equity / Convertible) | W14: Terms shared; fee-heavy engagement model. $120K + 8% $920K | 01/15/2026 | Submitted formal equity financing proposal for up to $10M. Structure includes 8% cash banking fee, 8% warrant coverage, and $120K upfront compliance/diligence/distribution fees. Process is heavily intermediary-led with broad investor marketing and placement focus. High fees and limited strategic value relative to capital efficiency; not a preferred path at this stage. | in data room ; sent terms but are they a strategic enough partner? | X14: Term Sheets!19 | JQ Follow Up!20 | Y14: Review terms and push decision process | Z14: 2 | AA14: =IF(AC14="Archived",0,ROUND((IF(N14="Tier 1",35,IF(N14="Tier 2",20,8))+IF(C14="Financial Investor",15,IF(C14="Intermediary / Banker",12,8))+IF(L14="Term Sheet / Proposal",25,IF(L14="Engaged",20,IF(L14="Meeting Requested",18,IF(L14="Meeting Held",14,IF(L14="Follow Up",10,5)))))+MIN(Q14,30)+IF(S14="DUE",15,IF(S14="Next 3 Days",8,0))),0)) | AB14: =IF(AND(AC14="Active",OR(N14="Tier 1",N14="Tier 2"),OR(S14="DUE",S14="Next 3 Days")),"YES","") | AC14: =IF(L14="Passed","Archived","Active")
A15: EXOS-0014 | B15: Derek Contacts | C15: Intermediary / Banker | D15: US Capital | E15: Mitch; Steve Wilburn; Charles Sims | F15: CEO | G15: mambe@uscapital.com | H15: csims@craftcm.com | K15: John Quinn | L15: Term Sheet / Proposal | M15: Capital raise support / placement | N15: Tier 1 | P15: 45986 | Q15: =IF(P15="","",TODAY()-P15) | R15: =IF(OR(L15="Passed",Z15=""),"",P15+Z15) | S15: =IF(OR(R15="",L15="Passed"),"",IF(R15<=TODAY(),"DUE",IF(R15<=TODAY()+3,"Next 3 Days","Later"))) | T15: Meeting scheduled / held | V15: Capital Raise (Equity / Convertible) | W15: Terms shared; fee-heavy engagement model. $120K + 8% $920K | 01/15/2026 | Submitted formal equity financing proposal for up to $10M. Structure includes 8% cash banking fee, 8% warrant coverage, and $120K upfront compliance/diligence/distribution fees. Process is heavily intermediary-led with broad investor marketing and placement focus. High fees and limited strategic value relative to capital efficiency; not a preferred path at this stage. | X15: Derek Contacts!57 | Y15: Review terms and push decision process | Z15: 2 | AA15: =IF(AC15="Archived",0,ROUND((IF(N15="Tier 1",35,IF(N15="Tier 2",20,8))+IF(C15="Financial Investor",15,IF(C15="Intermediary / Banker",12,8))+IF(L15="Term Sheet / Proposal",25,IF(L15="Engaged",20,IF(L15="Meeting Requested",18,IF(L15="Meeting Held",14,IF(L15="Follow Up",10,5)))))+MIN(Q15,30)+IF(S15="DUE",15,IF(S15="Next 3 Days",8,0))),0)) | AB15: =IF(AND(AC15="Active",OR(N15="Tier 1",N15="Tier 2"),OR(S15="DUE",S15="Next 3 Days")),"YES","") | AC15: =IF(L15="Passed","Archived","Active")
A16: EXOS-0015 | B16: Term Sheets | C16: Other / Review | D16: Black in Play | K16: John Quinn | L16: Engaged | M16: Needs qualification | N16: Tier 1 | Q16: =IF(P16="","",TODAY()-P16) | R16: =IF(OR(L16="Passed",Z16=""),"",P16+Z16) | S16: =IF(OR(R16="",L16="Passed"),"",IF(R16<=TODAY(),"DUE",IF(R16<=TODAY()+3,"Next 3 Days","Later"))) | T16: Meeting scheduled / held | X16: Term Sheets!28 | Y16: Advance diligence / proposal discussion | Z16: 5 | AA16: =IF(AC16="Archived",0,ROUND((IF(N16="Tier 1",35,IF(N16="Tier 2",20,8))+IF(C16="Financial Investor",15,IF(C16="Intermediary / Banker",12,8))+IF(L16="Term Sheet / Proposal",25,IF(L16="Engaged",20,IF(L16="Meeting Requested",18,IF(L16="Meeting Held",14,IF(L16="Follow Up",10,5)))))+MIN(Q16,30)+IF(S16="DUE",15,IF(S16="Next 3 Days",8,0))),0)) | AB16: =IF(AND(AC16="Active",OR(N16="Tier 1",N16="Tier 2"),OR(S16="DUE",S16="Next 3 Days")),"YES","") | AC16: =IF(L16="Passed","Archived","Active")
A17: EXOS-0016 | B17: Term Sheets | C17: Other / Review | D17: Blue under contract engagement | K17: John Quinn | L17: Engaged | M17: Needs qualification | N17: Tier 1 | Q17: =IF(P17="","",TODAY()-P17) | R17: =IF(OR(L17="Passed",Z17=""),"",P17+Z17) | S17: =IF(OR(R17="",L17="Passed"),"",IF(R17<=TODAY(),"DUE",IF(R17<=TODAY()+3,"Next 3 Days","Later"))) | T17: Meeting scheduled / held | X17: Term Sheets!29 | Y17: Advance diligence / proposal discussion | Z17: 5 | AA17: =IF(AC17="Archived",0,ROUND((IF(N17="Tier 1",35,IF(N17="Tier 2",20,8))+IF(C17="Financial Investor",15,IF(C17="Intermediary / Banker",12,8))+IF(L17="Term Sheet / Proposal",25,IF(L17="Engaged",20,IF(L17="Meeting Requested",18,IF(L17="Meeting Held",14,IF(L17="Follow Up",10,5)))))+MIN(Q17,30)+IF(S17="DUE",15,IF(S17="Next 3 Days",8,0))),0)) | AB17: =IF(AND(AC17="Active",OR(N17="Tier 1",N17="Tier 2"),OR(S17="DUE",S17="Next 3 Days")),"YES","") | AC17: =IF(L17="Passed","Archived","Active")
A18: EXOS-0017 | B18: JQ Follow Up | John - Investor Contacts | Term Sheets | C18: Financial Investor | D18: Concord Ventures | E18: Salim Dada | G18: salim.d@concordventuresinc.com | H18: ted.b@concordventuresinc.com; safia.d@concordventuresinc.com | K18: John Quinn | L18: Engaged | M18: Space / Defense / Aerospace / Advanced Manufacturing | N18: Tier 1 | O18: 45950 | P18: 45958 | Q18: =IF(P18="","",TODAY()-P18) | R18: =IF(OR(L18="Passed",Z18=""),"",P18+Z18) | S18: =IF(OR(R18="",L18="Passed"),"",IF(R18<=TODAY(),"DUE",IF(R18<=TODAY()+3,"Next 3 Days","Later"))) | T18: Meeting scheduled / held | V18: Sell-Side / Marketing Advisory (Exclusive) | W18: Revised agreement sent; no follow-up since; inactive. | offer for $2500/month for 3 months plan | Offer for $2500/month to run program | X18: Term Sheets!23 | JQ Follow Up!11 | John - Investor Contacts!899 | Y18: Advance diligence / proposal discussion | Z18: 5 | AA18: =IF(AC18="Archived",0,ROUND((IF(N18="Tier 1",35,IF(N18="Tier 2",20,8))+IF(C18="Financial Investor",15,IF(C18="Intermediary / Banker",12,8))+IF(L18="Term Sheet / Proposal",25,IF(L18="Engaged",20,IF(L18="Meeting Requested",18,IF(L18="Meeting Held",14,IF(L18="Follow Up",10,5)))))+MIN(Q18,30)+IF(S18="DUE",15,IF(S18="Next 3 Days",8,0))),0)) | AB18: =IF(AND(AC18="Active",OR(N18="Tier 1",N18="Tier 2"),OR(S18="DUE",S18="Next 3 Days")),"YES","") | AC18: =IF(L18="Passed","Archived","Active")
A19: EXOS-0018 | B19: John - Investor Contacts | C19: Financial Investor | D19: Concord Ventures | E19: Salim Dada | K19: John Quinn | L19: Engaged | M19: Space / Defense / Aerospace / Advanced Manufacturing | N19: Tier 1 | O19: 45917 | P19: 45958 | Q19: =IF(P19="","",TODAY()-P19) | R19: =IF(OR(L19="Passed",Z19=""),"",P19+Z19) | S19: =IF(OR(R19="",L19="Passed"),"",IF(R19<=TODAY(),"DUE",IF(R19<=TODAY()+3,"Next 3 Days","Later"))) | T19: Meeting scheduled / held | U19: Salim Dada, Safia Dada | V19: Sell-Side / Marketing Advisory (Exclusive) | W19: Revised agreement sent; no follow-up since; inactive. | X19: John - Investor Contacts!3 | Y19: Advance diligence / proposal discussion | Z19: 5 | AA19: =IF(AC19="Archived",0,ROUND((IF(N19="Tier 1",35,IF(N19="Tier 2",20,8))+IF(C19="Financial Investor",15,IF(C19="Intermediary / Banker",12,8))+IF(L19="Term Sheet / Proposal",25,IF(L19="Engaged",20,IF(L19="Meeting Requested",18,IF(L19="Meeting Held",14,IF(L19="Follow Up",10,5)))))+MIN(Q19,30)+IF(S19="DUE",15,IF(S19="Next 3 Days",8,0))),0)) | AB19: =IF(AND(AC19="Active",OR(N19="Tier 1",N19="Tier 2"),OR(S19="DUE",S19="Next 3 Days")),"YES","") | AC19: =IF(L19="Passed","Archived","Active")
A20: EXOS-0019 | B20: JQ Follow Up | Term Sheets | C20: Other / Review | D20: CounterFlow Solutions | E20: Dan Garretson | G20: dgarretson@counterflowsolutions.com | K20: John Quinn | L20: Engaged | M20: Needs qualification | N20: Tier 1 | P20: 46024 | Q20: =IF(P20="","",TODAY()-P20) | R20: =IF(OR(L20="Passed",Z20=""),"",P20+Z20) | S20: =IF(OR(R20="",L20="Passed"),"",IF(R20<=TODAY(),"DUE",IF(R20<=TODAY()+3,"Next 3 Days","Later"))) | T20: Meeting scheduled / held | V20: Strategic Advisory (Narrative / Framing) | W20: Proposed short sprint to reframe EXOS + Scorpius narrative. Decision pending. | 12/23 john sent follow up reply | Costs for wrong scope | X20: Term Sheets!20 | JQ Follow Up!19 | Y20: Advance diligence / proposal discussion | Z20: 5 | AA20: =IF(AC20="Archived",0,ROUND((IF(N20="Tier 1",35,IF(N20="Tier 2",20,8))+IF(C20="Financial Investor",15,IF(C20="Intermediary / Banker",12,8))+IF(L20="Term Sheet / Proposal",25,IF(L20="Engaged",20,IF(L20="Meeting Requested",18,IF(L20="Meeting Held",14,IF(L20="Follow Up",10,5)))))+MIN(Q20,30)+IF(S20="DUE",15,IF(S20="Next 3 Days",8,0))),0)) | AB20: =IF(AND(AC20="Active",OR(N20="Tier 1",N20="Tier 2"),OR(S20="DUE",S20="Next 3 Days")),"YES","") | AC20: =IF(L20="Passed","Archived","Active")
A21: EXOS-0020 | B21: Term Sheets | C21: Financial Investor | D21: CrossRoads Capital | E21: Rchard Phillips | K21: John Quinn | L21: Engaged | M21: Space / Defense / Aerospace / Advanced Manufacturing | N21: Tier 1 | P21: 46038 | Q21: =IF(P21="","",TODAY()-P21) | R21: =IF(OR(L21="Passed",Z21=""),"",P21+Z21) | S21: =IF(OR(R21="",L21="Passed"),"",IF(R21<=TODAY(),"DUE",IF(R21<=TODAY()+3,"Next 3 Days","Later"))) | T21: Meeting scheduled / held | V21: CTD acquisition or JV opportunity | W21: have new 18,000 sf facility just North of Denver Co. $3-4M to scale | X21: Term Sheets!17 | Y21: Advance diligence / proposal discussion | Z21: 5 | AA21: =IF(AC21="Archived",0,ROUND((IF(N21="Tier 1",35,IF(N21="Tier 2",20,8))+IF(C21="Financial Investor",15,IF(C21="Intermediary / Banker",12,8))+IF(L21="Term Sheet / Proposal",25,IF(L21="Engaged",20,IF(L21="Meeting Requested",18,IF(L21="Meeting Held",14,IF(L21="Follow Up",10,5)))))+MIN(Q21,30)+IF(S21="DUE",15,IF(S21="Next 3 Days",8,0))),0)) | AB21: =IF(AND(AC21="Active",OR(N21="Tier 1",N21="Tier 2"),OR(S21="DUE",S21="Next 3 Days")),"YES","") | AC21: =IF(L21="Passed","Archived","Active")
A22: EXOS-0021 | B22: John - Investor Contacts | C22: Financial Investor | D22: Crossroads Capital | E22: Andrew J. Buchholtz and David Ford | G22: andy@abuchholtz.com | H22: rphillips@crossroadscapitaldc.com; df@silverpeakib.com | K22: John Quinn | L22: Engaged | M22: Space / Defense / Aerospace / Advanced Manufacturing | N22: Tier 1 | O22: 45846 | P22: 46038 | Q22: =IF(P22="","",TODAY()-P22) | R22: =IF(OR(L22="Passed",Z22=""),"",P22+Z22) | S22: =IF(OR(R22="",L22="Passed"),"",IF(R22<=TODAY(),"DUE",IF(R22<=TODAY()+3,"Next 3 Days","Later"))) | T22: Meeting scheduled / held | U22: Richard Phillips | V22: CTD acquisition or JV opportunity | W22: Sent you the ELA draft this morning — let me if you didn’t receive or if you have any questions. We can schedule another call if you’d like to review together. | have new 18,000 sf facility just North of Denver Co. $3-4M to scale | had a call, sent deck | X22: John - Investor Contacts!4 | John - Investor Contacts!358 | Y22: Advance diligence / proposal discussion | Z22: 5 | AA22: =IF(AC22="Archived",0,ROUND((IF(N22="Tier 1",35,IF(N22="Tier 2",20,8))+IF(C22="Financial Investor",15,IF(C22="Intermediary / Banker",12,8))+IF(L22="Term Sheet / Proposal",25,IF(L22="Engaged",20,IF(L22="Meeting Requested",18,IF(L22="Meeting Held",14,IF(L22="Follow Up",10,5)))))+MIN(Q22,30)+IF(S22="DUE",15,IF(S22="Next 3 Days",8,0))),0)) | AB22: =IF(AND(AC22="Active",OR(N22="Tier 1",N22="Tier 2"),OR(S22="DUE",S22="Next 3 Days")),"YES","") | AC22: =IF(L22="Passed","Archived","Active")
A23: EXOS-0022 | B23: Term Sheets | C23: Financial Investor | D23: DC Finance | E23: Morris | K23: John Quinn | L23: Engaged | M23: Space / Defense / Aerospace / Advanced Manufacturing | N23: Tier 1 | Q23: =IF(P23="","",TODAY()-P23) | R23: =IF(OR(L23="Passed",Z23=""),"",P23+Z23) | S23: =IF(OR(R23="",L23="Passed"),"",IF(R23<=TODAY(),"DUE",IF(R23<=TODAY()+3,"Next 3 Days","Later"))) | T23: Meeting scheduled / held | V23: 10K or 30k to put you in a room with 12 Family offices | X23: Term Sheets!18 | Y23: Advance diligence / proposal discussion | Z23: 5 | AA23: =IF(AC23="Archived",0,ROUND((IF(N23="Tier 1",35,IF(N23="Tier 2",20,8))+IF(C23="Financial Investor",15,IF(C23="Intermediary / Banker",12,8))+IF(L23="Term Sheet / Proposal",25,IF(L23="Engaged",20,IF(L23="Meeting Requested",18,IF(L23="Meeting Held",14,IF(L23="Follow Up",10,5)))))+MIN(Q23,30)+IF(S23="DUE",15,IF(S23="Next 3 Days",8,0))),0)) | AB23: =IF(AND(AC23="Active",OR(N23="Tier 1",N23="Tier 2"),OR(S23="DUE",S23="Next 3 Days")),"YES","") | AC23: =IF(L23="Passed","Archived","Active")
A24: EXOS-0023 | B24: Term Sheets | C24: Financial Investor | D24: Digital Asset Management | E24: Juan Lorenzana | K24: John Quinn | L24: Engaged | M24: Space / Defense / Aerospace / Advanced Manufacturing | N24: Tier 1 | P24: 46059 | Q24: =IF(P24="","",TODAY()-P24) | R24: =IF(OR(L24="Passed",Z24=""),"",P24+Z24) | S24: =IF(OR(R24="",L24="Passed"),"",IF(R24<=TODAY(),"DUE",IF(R24<=TODAY()+3,"Next 3 Days","Later"))) | T24: Meeting scheduled / held | V24: no feedback on SEC filing AUM record | W24: $30K refundable. Fund with hedge of Gold metals real estate etc. | X24: Term Sheets!5 | Y24: Advance diligence / proposal discussion | Z24: 5 | AA24: =IF(AC24="Archived",0,ROUND((IF(N24="Tier 1",35,IF(N24="Tier 2",20,8))+IF(C24="Financial Investor",15,IF(C24="Intermediary / Banker",12,8))+IF(L24="Term Sheet / Proposal",25,IF(L24="Engaged",20,IF(L24="Meeting Requested",18,IF(L24="Meeting Held",14,IF(L24="Follow Up",10,5)))))+MIN(Q24,30)+IF(S24="DUE",15,IF(S24="Next 3 Days",8,0))),0)) | AB24: =IF(AND(AC24="Active",OR(N24="Tier 1",N24="Tier 2"),OR(S24="DUE",S24="Next 3 Days")),"YES","") | AC24: =IF(L24="Passed","Archived","Active")
A25: EXOS-0024 | B25: Term Sheets | C25: Other / Review | D25: Green- costs | K25: John Quinn | L25: Engaged | M25: Needs qualification | N25: Tier 1 | Q25: =IF(P25="","",TODAY()-P25) | R25: =IF(OR(L25="Passed",Z25=""),"",P25+Z25) | S25: =IF(OR(R25="",L25="Passed"),"",IF(R25<=TODAY(),"DUE",IF(R25<=TODAY()+3,"Next 3 Days","Later"))) | T25: Meeting scheduled / held | X25: Term Sheets!27 | Y25: Advance diligence / proposal discussion | Z25: 5 | AA25: =IF(AC25="Archived",0,ROUND((IF(N25="Tier 1",35,IF(N25="Tier 2",20,8))+IF(C25="Financial Investor",15,IF(C25="Intermediary / Banker",12,8))+IF(L25="Term Sheet / Proposal",25,IF(L25="Engaged",20,IF(L25="Meeting Requested",18,IF(L25="Meeting Held",14,IF(L25="Follow Up",10,5)))))+MIN(Q25,30)+IF(S25="DUE",15,IF(S25="Next 3 Days",8,0))),0)) | AB25: =IF(AND(AC25="Active",OR(N25="Tier 1",N25="Tier 2"),OR(S25="DUE",S25="Next 3 Days")),"YES","") | AC25: =IF(L25="Passed","Archived","Active")
A26: EXOS-0025 | B26: Term Sheets | C26: Other / Review | D26: Ivy Asset Management | E26: Chris Roberts "Christopher Virginia Roberts" | G26: chrisr@ivyassetmngmt.com | K26: John Quinn | L26: Engaged | M26: Needs qualification | N26: Tier 1 | Q26: =IF(P26="","",TODAY()-P26) | R26: =IF(OR(L26="Passed",Z26=""),"",P26+Z26) | S26: =IF(OR(R26="",L26="Passed"),"",IF(R26<=TODAY(),"DUE",IF(R26<=TODAY()+3,"Next 3 Days","Later"))) | T26: Meeting scheduled / held | X26: Term Sheets!13 | Y26: Advance diligence / proposal discussion | Z26: 5 | AA26: =IF(AC26="Archived",0,ROUND((IF(N26="Tier 1",35,IF(N26="Tier 2",20,8))+IF(C26="Financial Investor",15,IF(C26="Intermediary / Banker",12,8))+IF(L26="Term Sheet / Proposal",25,IF(L26="Engaged",20,IF(L26="Meeting Requested",18,IF(L26="Meeting Held",14,IF(L26="Follow Up",10,5)))))+MIN(Q26,30)+IF(S26="DUE",15,IF(S26="Next 3 Days",8,0))),0)) | AB26: =IF(AND(AC26="Active",OR(N26="Tier 1",N26="Tier 2"),OR(S26="DUE",S26="Next 3 Days")),"YES","") | AC26: =IF(L26="Passed","Archived","Active")
A27: EXOS-0026 | B27: JQ Follow Up | Term Sheets | C27: Financial Investor | D27: Odeon Capital | E27: Eric Gomberg | G27: egomberg@odeoncap.com | K27: John Quinn | L27: Engaged | M27: Space / Defense / Aerospace / Advanced Manufacturing | N27: Tier 1 | P27: 46028 | Q27: =IF(P27="","",TODAY()-P27) | R27: =IF(OR(L27="Passed",Z27=""),"",P27+Z27) | S27: =IF(OR(R27="",L27="Passed"),"",IF(R27<=TODAY(),"DUE",IF(R27<=TODAY()+3,"Next 3 Days","Later"))) | T27: Meeting scheduled / held | V27: Capital Discussion | W27: MNDA + data room sent Dec 17. No response prior to year-end. Follow-up email sent today. | 01/15/2026 | 1. Reduced Retainer of $30,000 Upfront. 2. Success Fee of $400,000 at the back end. We will credit the $30K Retainer back at the end upon a successful completion. 3. Any reasonable travel authorized by the client in advance of any travel. Please let us know if this is okay, then we can proceed with the detailed proposal/engagement letter. Regards, Bill Bill Nicholson, MBA, M&AMI®, CM&AA® | X27: Term Sheets!7 | JQ Follow Up!8 | Y27: Advance diligence / proposal discussion | Z27: 5 | AA27: =IF(AC27="Archived",0,ROUND((IF(N27="Tier 1",35,IF(N27="Tier 2",20,8))+IF(C27="Financial Investor",15,IF(C27="Intermediary / Banker",12,8))+IF(L27="Term Sheet / Proposal",25,IF(L27="Engaged",20,IF(L27="Meeting Requested",18,IF(L27="Meeting Held",14,IF(L27="Follow Up",10,5)))))+MIN(Q27,30)+IF(S27="DUE",15,IF(S27="Next 3 Days",8,0))),0)) | AB27: =IF(AND(AC27="Active",OR(N27="Tier 1",N27="Tier 2"),OR(S27="DUE",S27="Next 3 Days")),"YES","") | AC27: =IF(L27="Passed","Archived","Active")
A28: EXOS-0027 | B28: Term Sheets | C28: Other / Review | D28: Red dropped | K28: John Quinn | L28: Engaged | M28: Needs qualification | N28: Tier 1 | Q28: =IF(P28="","",TODAY()-P28) | R28: =IF(OR(L28="Passed",Z28=""),"",P28+Z28) | S28: =IF(OR(R28="",L28="Passed"),"",IF(R28<=TODAY(),"DUE",IF(R28<=TODAY()+3,"Next 3 Days","Later"))) | T28: Meeting scheduled / held | X28: Term Sheets!26 | Y28: Advance diligence / proposal discussion | Z28: 5 | AA28: =IF(AC28="Archived",0,ROUND((IF(N28="Tier 1",35,IF(N28="Tier 2",20,8))+IF(C28="Financial Investor",15,IF(C28="Intermediary / Banker",12,8))+IF(L28="Term Sheet / Proposal",25,IF(L28="Engaged",20,IF(L28="Meeting Requested",18,IF(L28="Meeting Held",14,IF(L28="Follow Up",10,5)))))+MIN(Q28,30)+IF(S28="DUE",15,IF(S28="Next 3 Days",8,0))),0)) | AB28: =IF(AND(AC28="Active",OR(N28="Tier 1",N28="Tier 2"),OR(S28="DUE",S28="Next 3 Days")),"YES","") | AC28: =IF(L28="Passed","Archived","Active")
A29: EXOS-0028 | B29: Term Sheets | C29: Financial Investor | D29: Ricci Global Partners | E29: Riccardo Ricci | G29: riccardo@riccicapitalpartners.com | K29: John Quinn | L29: Engaged | M29: Space / Defense / Aerospace / Advanced Manufacturing | N29: Tier 1 | P29: 46028 | Q29: =IF(P29="","",TODAY()-P29) | R29: =IF(OR(L29="Passed",Z29=""),"",P29+Z29) | S29: =IF(OR(R29="",L29="Passed"),"",IF(R29<=TODAY(),"DUE",IF(R29<=TODAY()+3,"Next 3 Days","Later"))) | T29: Meeting scheduled / held | V29: Capital Partner (Equity / Strategic) | W29: MNDA executed and data room shared. Ricci requested finance working session and followed up again today to move forward | 01/15/2026 | 03/13/2026 | X29: Term Sheets!10 | Y29: Advance diligence / proposal discussion | Z29: 5 | AA29: =IF(AC29="Archived",0,ROUND((IF(N29="Tier 1",35,IF(N29="Tier 2",20,8))+IF(C29="Financial Investor",15,IF(C29="Intermediary / Banker",12,8))+IF(L29="Term Sheet / Proposal",25,IF(L29="Engaged",20,IF(L29="Meeting Requested",18,IF(L29="Meeting Held",14,IF(L29="Follow Up",10,5)))))+MIN(Q29,30)+IF(S29="DUE",15,IF(S29="Next 3 Days",8,0))),0)) | AB29: =IF(AND(AC29="Active",OR(N29="Tier 1",N29="Tier 2"),OR(S29="DUE",S29="Next 3 Days")),"YES","") | AC29: =IF(L29="Passed","Archived","Active")
A30: EXOS-0029 | B30: JQ Follow Up | C30: Financial Investor | D30: Ricci Global Partners | E30: Riccardo Ricci | G30: riccardo-ricci@ricciglobalpartners.com | K30: John Quinn | L30: Engaged | M30: Space / Defense / Aerospace / Advanced Manufacturing | N30: Tier 1 | P30: 46028 | Q30: =IF(P30="","",TODAY()-P30) | R30: =IF(OR(L30="Passed",Z30=""),"",P30+Z30) | S30: =IF(OR(R30="",L30="Passed"),"",IF(R30<=TODAY(),"DUE",IF(R30<=TODAY()+3,"Next 3 Days","Later"))) | T30: Meeting scheduled / held | U30: referred by Tom Wright | V30: Capital Partner (Equity / Strategic) | W30: MNDA executed and data room shared. Ricci requested finance working session and followed up again today to move forward | 01/15/2026 | 03/13/2026 | X30: JQ Follow Up!10 | Y30: Advance diligence / proposal discussion | Z30: 5 | AA30: =IF(AC30="Archived",0,ROUND((IF(N30="Tier 1",35,IF(N30="Tier 2",20,8))+IF(C30="Financial Investor",15,IF(C30="Intermediary / Banker",12,8))+IF(L30="Term Sheet / Proposal",25,IF(L30="Engaged",20,IF(L30="Meeting Requested",18,IF(L30="Meeting Held",14,IF(L30="Follow Up",10,5)))))+MIN(Q30,30)+IF(S30="DUE",15,IF(S30="Next 3 Days",8,0))),0)) | AB30: =IF(AND(AC30="Active",OR(N30="Tier 1",N30="Tier 2"),OR(S30="DUE",S30="Next 3 Days")),"YES","") | AC30: =IF(L30="Passed","Archived","Active")
A31: EXOS-0030 | B31: Term Sheets | C31: Other / Review | D31: Screen with Visual Conmpliance | K31: John Quinn | L31: Engaged | M31: Needs qualification | N31: Tier 1 | Q31: =IF(P31="","",TODAY()-P31) | R31: =IF(OR(L31="Passed",Z31=""),"",P31+Z31) | S31: =IF(OR(R31="",L31="Passed"),"",IF(R31<=TODAY(),"DUE",IF(R31<=TODAY()+3,"Next 3 Days","Later"))) | T31: Meeting scheduled / held | X31: Term Sheets!30 | Y31: Advance diligence / proposal discussion | Z31: 5 | AA31: =IF(AC31="Archived",0,ROUND((IF(N31="Tier 1",35,IF(N31="Tier 2",20,8))+IF(C31="Financial Investor",15,IF(C31="Intermediary / Banker",12,8))+IF(L31="Term Sheet / Proposal",25,IF(L31="Engaged",20,IF(L31="Meeting Requested",18,IF(L31="Meeting Held",14,IF(L31="Follow Up",10,5)))))+MIN(Q31,30)+IF(S31="DUE",15,IF(S31="Next 3 Days",8,0))),0)) | AB31: =IF(AND(AC31="Active",OR(N31="Tier 1",N31="Tier 2"),OR(S31="DUE",S31="Next 3 Days")),"YES","") | AC31: =IF(L31="Passed","Archived","Active")
A32: EXOS-0031 | B32: Term Sheets | C32: Other / Review | D32: The Unity Group | E32: Alex Durie via Tahmina K | G32: alex@unity-group.com | H32: shorgan05@gmail.com; harry.young@theacquisitionrudis.com; jeremy@unity-group.com; victor.tan@unity-group.com | K32: John Quinn | L32: Engaged | M32: Needs qualification | N32: Tier 1 | Q32: =IF(P32="","",TODAY()-P32) | R32: =IF(OR(L32="Passed",Z32=""),"",P32+Z32) | S32: =IF(OR(R32="",L32="Passed"),"",IF(R32<=TODAY(),"DUE",IF(R32<=TODAY()+3,"Next 3 Days","Later"))) | T32: Meeting scheduled / held | X32: Term Sheets!8 | Y32: Advance diligence / proposal discussion | Z32: 5 | AA32: =IF(AC32="Archived",0,ROUND((IF(N32="Tier 1",35,IF(N32="Tier 2",20,8))+IF(C32="Financial Investor",15,IF(C32="Intermediary / Banker",12,8))+IF(L32="Term Sheet / Proposal",25,IF(L32="Engaged",20,IF(L32="Meeting Requested",18,IF(L32="Meeting Held",14,IF(L32="Follow Up",10,5)))))+MIN(Q32,30)+IF(S32="DUE",15,IF(S32="Next 3 Days",8,0))),0)) | AB32: =IF(AND(AC32="Active",OR(N32="Tier 1",N32="Tier 2"),OR(S32="DUE",S32="Next 3 Days")),"YES","") | AC32: =IF(L32="Passed","Archived","Active")
A33: EXOS-0032 | B33: Derek Contacts | JQ Follow Up | Term Sheets | C33: Intermediary / Banker | D33: Tristate Capital | E33: Sulaiman Sulaimani | G33: sulaiman@tristatecap.com | I33: 11/17 meeting held and follow up sent | K33: John Quinn | L33: Engaged | M33: Capital raise support / placement | N33: Tier 1 | P33: 46054 | Q33: =IF(P33="","",TODAY()-P33) | R33: =IF(OR(L33="Passed",Z33=""),"",P33+Z33) | S33: =IF(OR(R33="",L33="Passed"),"",IF(R33<=TODAY(),"DUE",IF(R33<=TODAY()+3,"Next 3 Days","Later"))) | T33: Meeting scheduled / held | U33: referred by Dereck | V33: Capital Introduction (Success Fee + Equity) Cost of finance under Tristate: 2.0% cash + 1.0% non-voting equity Only on Tristate-sourced, closed capital | W33: https://www.irongatevc.com/ Contracted with Sulaiman Sulaimani ​John Quinn​ ​Neil Milburn​ John, I'm scheduled to speak with our strategic partner Ty McCoy tomorrow. He just emailed me a company now that appears to be a close contact of his as there is someone on their team that is former CIA. I think we found the right partner for you and your team. Please give me sometime as I work on this for you and your team. I'll be back in touch. Thanks for the call yesterday. I enjoyed speaking with you. I was able to connect with our strategic partner Ty McCoy with IronGate. He is available to speak with us next week at 12 pm CST on 2/10. I was also able to circle up with our clients from ETL. Hanshin Lee emailed me that he is interested in Exos Aerospace and speaking with us next week at 8 am CST on 2/10. If you can please send me calendar invites for both calls on 2/10 8 am CST with ETL, and 12 pm CST with IronGate. Once I receive both invites, I'll be sure to pass them along. | 01/15/2026 | 2/10 – Calls Held: | etl dean rx? match with portfolio co | X33: Term Sheets!3 | JQ Follow Up!7 | Derek Contacts!55 | Y33: Advance diligence / proposal discussion | Z33: 5 | AA33: =IF(AC33="Archived",0,ROUND((IF(N33="Tier 1",35,IF(N33="Tier 2",20,8))+IF(C33="Financial Investor",15,IF(C33="Intermediary / Banker",12,8))+IF(L33="Term Sheet / Proposal",25,IF(L33="Engaged",20,IF(L33="Meeting Requested",18,IF(L33="Meeting Held",14,IF(L33="Follow Up",10,5)))))+MIN(Q33,30)+IF(S33="DUE",15,IF(S33="Next 3 Days",8,0))),0)) | AB33: =IF(AND(AC33="Active",OR(N33="Tier 1",N33="Tier 2"),OR(S33="DUE",S33="Next 3 Days")),"YES","") | AC33: =IF(L33="Passed","Archived","Active")
A34: EXOS-0033 | B34: Term Sheets | C34: Other / Review | D34: Viking Mergers & Acquisitions | E34: A. Rehwinkel | G34: arehwinkel@vikingmergers.com | K34: John Quinn | L34: Engaged | M34: Needs qualification | N34: Tier 1 | Q34: =IF(P34="","",TODAY()-P34) | R34: =IF(OR(L34="Passed",Z34=""),"",P34+Z34) | S34: =IF(OR(R34="",L34="Passed"),"",IF(R34<=TODAY(),"DUE",IF(R34<=TODAY()+3,"Next 3 Days","Later"))) | T34: Meeting scheduled / held | W34: Initial engagement underway; reviewing materials in data room. | X34: Term Sheets!12 | Y34: Advance diligence / proposal discussion | Z34: 5 | AA34: =IF(AC34="Archived",0,ROUND((IF(N34="Tier 1",35,IF(N34="Tier 2",20,8))+IF(C34="Financial Investor",15,IF(C34="Intermediary / Banker",12,8))+IF(L34="Term Sheet / Proposal",25,IF(L34="Engaged",20,IF(L34="Meeting Requested",18,IF(L34="Meeting Held",14,IF(L34="Follow Up",10,5)))))+MIN(Q34,30)+IF(S34="DUE",15,IF(S34="Next 3 Days",8,0))),0)) | AB34: =IF(AND(AC34="Active",OR(N34="Tier 1",N34="Tier 2"),OR(S34="DUE",S34="Next 3 Days")),"YES","") | AC34: =IF(L34="Passed","Archived","Active")
A35: EXOS-0034 | B35: John - Investor Contacts | C35: Financial Investor | D35: Collective Equity | E35: Mike Royston | G35: mike@collectiveequity.com | K35: John Quinn | L35: Meeting Requested | M35: Space / Defense / Aerospace / Advanced Manufacturing | N35: Tier 1 | Q35: =IF(P35="","",TODAY()-P35) | R35: =IF(OR(L35="Passed",Z35=""),"",P35+Z35) | S35: =IF(OR(R35="",L35="Passed"),"",IF(R35<=TODAY(),"DUE",IF(R35<=TODAY()+3,"Next 3 Days","Later"))) | T35: Meeting scheduled / held | W35: | | meeting on 6/25 / follow up meeting in the works / ziyi@collectiveequity.com | X35: John - Investor Contacts!249 | Y35: Book call and send agenda/deck | Z35: 2 | AA35: =IF(AC35="Archived",0,ROUND((IF(N35="Tier 1",35,IF(N35="Tier 2",20,8))+IF(C35="Financial Investor",15,IF(C35="Intermediary / Banker",12,8))+IF(L35="Term Sheet / Proposal",25,IF(L35="Engaged",20,IF(L35="Meeting Requested",18,IF(L35="Meeting Held",14,IF(L35="Follow Up",10,5)))))+MIN(Q35,30)+IF(S35="DUE",15,IF(S35="Next 3 Days",8,0))),0)) | AB35: =IF(AND(AC35="Active",OR(N35="Tier 1",N35="Tier 2"),OR(S35="DUE",S35="Next 3 Days")),"YES","") | AC35: =IF(L35="Passed","Archived","Active")
A36: EXOS-0035 | B36: Tank Contacts | C36: Strategic / Corporate | D36: Gravitics | E36: Scott Macklin | G36: smacklin@gravitics.com | H36: scottjmacklin@gmail.com | J36: https://www.linkedin.com/in/scmacklin/ | K36: John Quinn | L36: Meeting Requested | M36: Strategic space / aerospace alignment | N36: Tier 1 | O36: 45744 | P36: 45744 | Q36: =IF(P36="","",TODAY()-P36) | R36: =IF(OR(L36="Passed",Z36=""),"",P36+Z36) | S36: =IF(OR(R36="",L36="Passed"),"",IF(R36<=TODAY(),"DUE",IF(R36<=TODAY()+3,"Next 3 Days","Later"))) | T36: Meeting scheduled / held | W36: meeting set for 4/3 | X36: Tank Contacts!12 | Y36: Book call and send agenda/deck | Z36: 2 | AA36: =IF(AC36="Archived",0,ROUND((IF(N36="Tier 1",35,IF(N36="Tier 2",20,8))+IF(C36="Financial Investor",15,IF(C36="Intermediary / Banker",12,8))+IF(L36="Term Sheet / Proposal",25,IF(L36="Engaged",20,IF(L36="Meeting Requested",18,IF(L36="Meeting Held",14,IF(L36="Follow Up",10,5)))))+MIN(Q36,30)+IF(S36="DUE",15,IF(S36="Next 3 Days",8,0))),0)) | AB36: =IF(AND(AC36="Active",OR(N36="Tier 1",N36="Tier 2"),OR(S36="DUE",S36="Next 3 Days")),"YES","") | AC36: =IF(L36="Passed","Archived","Active")
A37: EXOS-0036 | B37: JQ Follow Up | John - Investor Contacts | C37: Financial Investor | D37: Investor Ready Capital | E37: Samuel Levitz | G37: samuel@investorreadycapital.com | I37: last email exchange I see is 11/23 and it looked promising - notes on what happened here? Looks like we need to follow up? | K37: John Quinn | L37: Meeting Requested | M37: Space / Defense / Aerospace / Advanced Manufacturing | N37: Tier 1 | Q37: =IF(P37="","",TODAY()-P37) | R37: =IF(OR(L37="Passed",Z37=""),"",P37+Z37) | S37: =IF(OR(R37="",L37="Passed"),"",IF(R37<=TODAY(),"DUE",IF(R37<=TODAY()+3,"Next 3 Days","Later"))) | T37: Meeting scheduled / held | W37: meeting held on 6/24 / follow up meeting on 6/27- Question replied to and followed up on 7-11 | X37: JQ Follow Up!23 | John - Investor Contacts!250 | Y37: Book call and send agenda/deck | Z37: 2 | AA37: =IF(AC37="Archived",0,ROUND((IF(N37="Tier 1",35,IF(N37="Tier 2",20,8))+IF(C37="Financial Investor",15,IF(C37="Intermediary / Banker",12,8))+IF(L37="Term Sheet / Proposal",25,IF(L37="Engaged",20,IF(L37="Meeting Requested",18,IF(L37="Meeting Held",14,IF(L37="Follow Up",10,5)))))+MIN(Q37,30)+IF(S37="DUE",15,IF(S37="Next 3 Days",8,0))),0)) | AB37: =IF(AND(AC37="Active",OR(N37="Tier 1",N37="Tier 2"),OR(S37="DUE",S37="Next 3 Days")),"YES","") | AC37: =IF(L37="Passed","Archived","Active")
A38: EXOS-0037 | B38: JQ Follow Up | John - Investor Contacts | OSC | C38: Financial Investor | D38: One Bow River | E38: Stowe Faircloth | G38: shane.sherman@onebowriver.com | H38: stowe.faircloth@onebowriver.com | I38: 720.910.9483 | J38: https://www.linkedin.com/in/shane-sherman/ | K38: John Quinn | L38: Meeting Requested | M38: Space / Defense / Aerospace / Advanced Manufacturing | N38: Tier 1 | O38: 45814 | P38: 45922 | Q38: =IF(P38="","",TODAY()-P38) | R38: =IF(OR(L38="Passed",Z38=""),"",P38+Z38) | S38: =IF(OR(R38="",L38="Passed"),"",IF(R38<=TODAY(),"DUE",IF(R38<=TODAY()+3,"Next 3 Days","Later"))) | T38: Meeting scheduled / held | U38: https://www.linkedin.com/in/shane-sherman/ | W38: 08/12/2025 | Stowe Faircloth <Stowe.faircloth@onebowriver.com>replied requesting a meeting on 9/22 | X38: JQ Follow Up!14 | John - Investor Contacts!144 | OSC!11 | Y38: Book call and send agenda/deck | Z38: 2 | AA38: =IF(AC38="Archived",0,ROUND((IF(N38="Tier 1",35,IF(N38="Tier 2",20,8))+IF(C38="Financial Investor",15,IF(C38="Intermediary / Banker",12,8))+IF(L38="Term Sheet / Proposal",25,IF(L38="Engaged",20,IF(L38="Meeting Requested",18,IF(L38="Meeting Held",14,IF(L38="Follow Up",10,5)))))+MIN(Q38,30)+IF(S38="DUE",15,IF(S38="Next 3 Days",8,0))),0)) | AB38: =IF(AND(AC38="Active",OR(N38="Tier 1",N38="Tier 2"),OR(S38="DUE",S38="Next 3 Days")),"YES","") | AC38: =IF(L38="Passed","Archived","Active")
A39: EXOS-0038 | B39: JQ Follow Up | John - Investor Contacts | C39: Financial Investor | D39: TEL Venture Capital | E39: Sergey Fedotov | G39: sergey.fedotov@tel.com | I39: 650.360.8669 | J39: https://www.linkedin.com/in/sergey-a-fedotov/ | K39: John Quinn | L39: Meeting Requested | M39: Space / Defense / Aerospace / Advanced Manufacturing | N39: Tier 1 | O39: 45912 | P39: 45912 | Q39: =IF(P39="","",TODAY()-P39) | R39: =IF(OR(L39="Passed",Z39=""),"",P39+Z39) | S39: =IF(OR(R39="",L39="Passed"),"",IF(R39<=TODAY(),"DUE",IF(R39<=TODAY()+3,"Next 3 Days","Later"))) | T39: Meeting scheduled / held | U39: https://www.linkedin.com/in/sergey-a-fedotov/ | W39: 9/24 - meeting set for 10/2 | X39: JQ Follow Up!13 | John - Investor Contacts!681 | Y39: Book call and send agenda/deck | Z39: 2 | AA39: =IF(AC39="Archived",0,ROUND((IF(N39="Tier 1",35,IF(N39="Tier 2",20,8))+IF(C39="Financial Investor",15,IF(C39="Intermediary / Banker",12,8))+IF(L39="Term Sheet / Proposal",25,IF(L39="Engaged",20,IF(L39="Meeting Requested",18,IF(L39="Meeting Held",14,IF(L39="Follow Up",10,5)))))+MIN(Q39,30)+IF(S39="DUE",15,IF(S39="Next 3 Days",8,0))),0)) | AB39: =IF(AND(AC39="Active",OR(N39="Tier 1",N39="Tier 2"),OR(S39="DUE",S39="Next 3 Days")),"YES","") | AC39: =IF(L39="Passed","Archived","Active")
A40: EXOS-0039 | B40: John - Investor Contacts | C40: Financial Investor | D40: referred by andy@abucholtz.com | E40: Richard Phillips | K40: John Quinn | L40: Meeting Requested | M40: Space / Defense / Aerospace / Advanced Manufacturing | N40: Tier 1 | O40: 45903 | P40: 45903 | Q40: =IF(P40="","",TODAY()-P40) | R40: =IF(OR(L40="Passed",Z40=""),"",P40+Z40) | S40: =IF(OR(R40="",L40="Passed"),"",IF(R40<=TODAY(),"DUE",IF(R40<=TODAY()+3,"Next 3 Days","Later"))) | T40: Meeting scheduled / held | U40: phillips@crossroadscapitaldc.com | W40: | meeting set 9/8/ NDA 9/12 | | X40: John - Investor Contacts!610 | Y40: Book call and send agenda/deck | Z40: 2 | AA40: =IF(AC40="Archived",0,ROUND((IF(N40="Tier 1",35,IF(N40="Tier 2",20,8))+IF(C40="Financial Investor",15,IF(C40="Intermediary / Banker",12,8))+IF(L40="Term Sheet / Proposal",25,IF(L40="Engaged",20,IF(L40="Meeting Requested",18,IF(L40="Meeting Held",14,IF(L40="Follow Up",10,5)))))+MIN(Q40,30)+IF(S40="DUE",15,IF(S40="Next 3 Days",8,0))),0)) | AB40: =IF(AND(AC40="Active",OR(N40="Tier 1",N40="Tier 2"),OR(S40="DUE",S40="Next 3 Days")),"YES","") | AC40: =IF(L40="Passed","Archived","Active")
...

Sheet Firm_Summary
A1: Company | B1: Category | C1: Best Stage | D1: Best Tier | E1: Contact Count | F1: Key Contacts | G1: Emails | H1: Last Touch | I1: Next Touch | J1: Due? | K1: Warm Intro | L1: Offer / Structure | M1: Notes
A2: AxisCades | B2: Financial Investor | C2: Term Sheet / Proposal | D2: Tier 1 | E2: 1 | F2: Suresh Babu Suryadevara | G2: suresh.s@axiscades.in | H2: 46055 | I2: =IF(OR(C2="Passed",H2="",ISBLANK(H2)),"",H2+2) | J2: =IF(I2="","",IF(I2<=TODAY(),"DUE",IF(I2<=TODAY()+3,"Next 3 Days","Later"))) | L2: Strategic Partnership- Equity deal | M2: Missed call toady at 08:30 - Follow-up framework shared outlining a phased, ITAR/EAR-compliant strategic partnership. Proposal includes AxisCades acquiring 51% of SSLC for $10M (phased capital), international sales support with commission structure, and long-term India-based manufacturing under TAA/MLA approvals. Discussions ongoing to confirm alignment on structure, valuation, and next steps. | toured SSLC on 2/16 | met in person at EXOS on 12/19, follow up set for onsite visit 1/19
A3: Bancroft Capital (Bancroft4Vets) | B3: Intermediary / Banker | C3: Term Sheet / Proposal | D3: Tier 1 | E3: 1 | F3: Jason Diamond | G3: jdiamond@bancroft4vets.com | I3: =IF(OR(C3="Passed",H3="",ISBLANK(H3)),"",H3+2) | J3: =IF(I3="","",IF(I3<=TODAY(),"DUE",IF(I3<=TODAY()+3,"Next 3 Days","Later"))) | L3: Investment Banking / Capital Raise | M3: Introduced via Kipton Cariaga. Terms/presentation shared. Defense- and veteran-focused investment bank. Logged for tracking and follow-up; no term sheet yet. Engaging BTIG 2-26-26 | 01/16/2026 | At their request, sent forward-ready cover email with high-level company overview and $10M raise summary, along with attached presentations. Materials prepared for direct circulation to IB partners and investor network (Jason forwarding internally). Awaiting feedback and/or investor introductions.
A4: Cerberus Capital Management | B4: Financial Investor | C4: Term Sheet / Proposal | D4: Tier 1 | E4: 3 | F4: Dan Quayle; Frank Bruno; Kent (Cerberus Ops) | G4: dquayle@cerberus.com; fbruno@cerberus.com; consult-klietzau@cerberusoperations.com | H4: 46023 | I4: =IF(OR(C4="Passed",H4="",ISBLANK(H4)),"",H4+2) | J4: =IF(I4="","",IF(I4<=TODAY(),"DUE",IF(I4<=TODAY()+3,"Next 3 Days","Later"))) | L4: Strategic Partner / Growth Capital | M4: 01/14/2026 | Introductory conversation held; John sent story deck, finance-focused deck, and one-pager today. Framed as strategic partner aligned with Scorpius acquisition, revenue expansion, and hypersonics / Golden Dome support. Added as potential strategic partner for board consideration. Awaiting response.
A5: Cloris Capital Group LLC | B5: Financial Investor | C5: Term Sheet / Proposal | D5: Tier 1 | E5: 1 | F5: Tahmina Khan | G5: tahmina.investing@gmail.com | I5: =IF(OR(C5="Passed",H5="",ISBLANK(H5)),"",H5+2) | J5: =IF(I5="","",IF(I5<=TODAY(),"DUE",IF(I5<=TODAY()+3,"Next 3 Days","Later"))) | K5: referred by Dereck | L5: Capital Partner (Equity / Strategic) 2% of transaction | M5: Completed discussions with both ETL and IronGate. No follow-up correspondence received to date. Awaiting next steps or investor feedback. | Investor requested documentation showing revenue for the past three years and indicated interest if trailing 12-month revenue reflects ~$1M. Financial documents sent by John. Awaiting response/feedback. | 11/24 call and materials sent
A6: Craft Capital | B6: Financial Investor | C6: Term Sheet / Proposal | D6: Tier 1 | E6: 1 | F6: Brandon Golenda | G6: bgolenda@craftcm.com | H6: 46020 | I6: =IF(OR(C6="Passed",H6="",ISBLANK(H6)),"",H6+2) | J6: =IF(I6="","",IF(I6<=TODAY(),"DUE",IF(I6<=TODAY()+3,"Next 3 Days","Later"))) | K6: referred by Dereck | L6: Advisory (Paid) Cost of finance: $30k fixed + 4–8% cash + 8% equity/warrants (if they introduce the capital) How to exclude other funding: The agreement already limits fees to Craft-introduced investors only, but You should formalize exclusions in writing immediately to avoid disputes. | M6: Advisory offer contingent on $30K fee. We chose not to proceed; parked. | $30K Investment bank enagement $10k/mo for 3 months advisor only. no funds.
