Workbook

Sheet Assumptions
A1: EXOS Aerospace / SSLC Option B Acquisition — Assumptions
A2: Prepared: 2026-10-07 | DRAFT — NEGOTIATING TERMS | INTERNAL — Exo/CEO only
A4: Assumption | B4: Value | C4: Source / Notes
A5: DEAL STRUCTURE — Option B
A6: Agreement date (Asset Acquisition Agreement) | B6: 2025-05-13 | C6: Executed — Jon Quinn & Jim Wertz
A7: §3 exclusivity trigger: financing agreement | B7: Ainigma/FNEX executed mandate | C7: FNEX advisory agreement; strengthen with investor/sponsor use-of-proceeds letter
A8: Exclusivity period (days) | B8: 90 | C8: §3 of the 2025 Agreement
A9: Deal price — total commitment ($) | B9: 3360000 | C9: §3 / §1: $2.51M cash + $60K costs + $790K stake credit
A10: Cash at close ($) | B10: 2510000 | C10: Stated deal price — cash component
A11: SSLC closing costs ($) | B11: 60000 | C11: Seller's costs; included in total
A12: Exos existing-stake credit ($) | B12: 790000 | C12: 18% equity at 2021 basis (~$4.39M total × 18%)
A13: Escrowed holdback (§7) — 5% for 12 months ($) | B13: =B9*0.05 | C13: §7; released at 12-month anniversary
A14: SSLC debts assumed at face ($) | B14: 500000 | C14: MANAGEMENT ASSUMPTION — UNVERIFIED. To verify in SSLC QB (session expired 10/7). Microcosm loan + Wertz notes + AP. Wertz/Microcosm debt paid at face = path to yes.
A15: Exos loan to SSLC — waived as license consideration ($) | B15: 38000 | C15: Jon decision 10/2; not re-proposed
A16: Working capital bridge needed (mid-point) ($) | B16: 500000 | C16: SSLC needs $0.3–0.7M to finish paid-for work (FY27 Q1 cash $198K; prepaid $984K; gap). Mid=$500K.
A17: Series A raise — first close ($) | B17: 10000000 | C17: D1 of record, 2026-08-13
A18: Pre-money valuation (Eqvista 409A) ($) | B18: 169700000 | C18: Eqvista 03/31/26; $8.66/sh; DLOM 36.51%
A19: RTO minimum enterprise value ($) | B19: 250000000 | C19: FNEX/Ainigma term — $250M min MEV
A20: Pre-RTO note size ($) | B20: 15000000 | C20: FNEX/Ainigma convertible note
A22: EARN-OUT PARAMETERS
A23: Earn-out i — IM tank revenue % (low) | B23: 0.03 | C23: Management assumption — unverified
A24: Earn-out i — IM tank revenue % (base) | B24: 0.05 | C24: Management assumption — unverified
A25: Earn-out i — IM tank revenue % (high) | B25: 0.07 | C25: Management assumption — unverified
A26: Earn-out i — annual cap ($) | B26: 300000 | C26: Management assumption — unverified
A27: Earn-out i — duration (years) | B27: 3 | C27: Management assumption — unverified
A28: Earn-out ii — Exos stock % of FD shares (low) | B28: 0.003 | C28: Management assumption — unverified
A29: Earn-out ii — Exos stock % of FD shares (base) | B29: 0.005 | C29: Management assumption — unverified
A30: Earn-out ii — Exos stock % of FD shares (high) | B30: 0.007 | C30: Management assumption — unverified
A31: Earn-out ii — assumed listing price (low) ($) | B31: 200000000 | C31: FNEX RTO min $250M MEV; low scenario
A32: Earn-out ii — assumed listing price (base) ($) | B32: 250000000 | C32: FNEX RTO minimum MEV
A33: Earn-out ii — assumed listing price (high) ($) | B33: 300000000 | C33: Management assumption — unverified
A34: Earn-out ii — lockup period (months) | B34: 12 | C34: Standard post-listing lockup
A36: SSLC HISTORICAL & PROJECTED FINANCIALS
A37: SSLC FY26 actual revenue ($) | B37: 1925000 | C37: SSLC QB FY26 actuals (Jon 10/2 QB pull)
A38: SSLC FY26 operating loss ($) | B38: -416000 | C38: SSLC QB FY26 actuals
A39: SSLC FY26 net income ($) | B39: -78000 | C39: Net of one-time $287K ERC credit
A40: SSLC FY27 Q1 actual revenue ($) | B40: 713000 | C40: SSLC QB FY27 Q1 (Sep not yet closed, Jon 10/2)
A41: SSLC FY27 billed-ahead + deposits ($) | B41: 984000 | C41: FY27 Q1 QB: $864K billed-ahead + $120K deposits
A42: SSLC cash at QB date ($) | B42: 198000 | C42: SSLC QB FY27 Q1 (10/2/2026)
A43: Exos % of SSLC revenue (FY26) | B43: 0.236 | C43: 23.6% per Jon 10/2 board meeting
...

Sheet Deal Structure
A1: SSLC Option B — Deal Structure, Sources & Uses, Earn-Out Analysis
A2: Option B: invoke §3 exclusivity at $3.36M base + earn-out (IM tank revenue and/or Exos stock post-listing). SSLC debts paid at face. DRAFT — negotiation-stage terms.
A4: SOURCES & USES AT CLOSE
A5: Line Item | B5: Amount ($) | E5: Notes
A6: USES
A7: Cash to SSLC sellers at close | B7: =Assumptions!B10 | E7: §3 deal price — cash component
A8: SSLC closing costs (sellers) | B8: =Assumptions!B11 | E8: Per §3 deal price
A9: SSLC debts assumed at face | B9: =Assumptions!B14 | E9: Microcosm/Wertz notes + AP — TO VERIFY IN SSLC QB
A10: Working capital bridge (mid-point) | B10: =Assumptions!B16 | E10: SSLC needs $0.3–0.7M to finish paid-for work
A11: Less: Exos stake credit (18%) | B11: =-Assumptions!B12 | E11: 18% equity at 2021 basis — reduces net cash
A12: 5% escrow holdback (§7, 12 mo.) | B12: =Assumptions!B13 | E12: Released at 12-month anniversary
A13: TOTAL USES | B13: =SUM(B7:B12) | E13: Net cash out-of-pocket at close + escrow
A15: SOURCES
A16: Series A first close (allocated to SSLC) | B16: =Assumptions!B10+Assumptions!B16 | E16: SSLC acquisition + WC bridge from Series A
A17: Exos stake credit (non-cash) | B17: =Assumptions!B12 | E17: Existing 18% stake reduces cash required
A18: TOTAL SOURCES | B18: =B16+B17
A19: Check (Sources − Uses) | B19: =B18-B13 | E19: Should = 0; debt payoff from SSLC operating cash
A21: EARN-OUT MECHANICS (two variants shown side by side; combined option in Col D)
A22: Metric | B22: Earn-Out i: IM Tank Revenue % | C22: Earn-Out ii: Exos Stock post-RTO | D22: Combined (i + ii) | E22: Notes
A23: Structure | B23: % of SSLC IM tank revenue, annual cap, 3-year term | C23: Exos common stock at listing (% of FD shares); 12-mo lockup | D23: Both i + ii | E23: Gives SSLC sellers upside from IM growth AND Exos growth
A24: Low scenario | B24: =MIN(Assumptions!B23*Assumptions!B44,Assumptions!B26)*Assumptions!B27 | C24: =Assumptions!B28*Assumptions!B31 | D24: =D24+C24 | E24: Low: 3% tank rev (cap $300K) × 3yr + 0.3% of $200M listing
A25: Base scenario | B25: =MIN(Assumptions!B24*Assumptions!B44,Assumptions!B26)*Assumptions!B27 | C25: =Assumptions!B29*Assumptions!B32 | D25: =B25+C25 | E25: Base: 5% × $5M firm + 0.5% of $250M listing
A26: High scenario | B26: =MIN(Assumptions!B25*Assumptions!B44,Assumptions!B26)*Assumptions!B27 | C26: =Assumptions!B30*Assumptions!B33 | D26: =B26+C26 | E26: High: 7% × $5M + 0.7% of $300M listing
A27: Exos dilution (stock, base) | B27: n/a | C27: =Assumptions!B29 | D27: =Assumptions!B29 | E27: 0.5% of FD shares; non-material at Series A scale
A28: Lockup / vesting | B28: Annual payments, 3 years | C28: 12-month lockup post-listing | D28: Each tranche per its own schedule
A30: TOTAL CONSIDERATION SUMMARY (Base price + earn-out)
A31: Component | B31: Low | C31: Base | D31: High | E31: Notes
A32: Base acquisition price | B32: =Assumptions!B9 | C32: =Assumptions!B9 | D32: =Assumptions!B9 | E32: §3 deal price; incl. stake credit
A33: SSLC debts assumed (TBV) | B33: =Assumptions!B14 | C33: =Assumptions!B14 | D33: =Assumptions!B14 | E33: To verify in SSLC QB
A34: Earn-out (combined) | B34: =D24 | C34: =D25 | D34: =D26 | E34: Earn-out i + ii combined
A35: TOTAL CONSIDERATION | B35: =B32+B33+B34 | C35: =C32+C33+C34 | D35: =D32+D33+D34 | E35: All-in for 82% of SSLC
A36: Implied 100% SSLC value | B36: =B35/0.82 | C36: =C35/0.82 | D36: =D35/0.82 | E36: At 82% acquisition; Exos holds 18%
A37: Payback (yrs at base EBITDA) | B37: =B35/1240000 | C37: =C35/1240000 | D37: =D35/1240000 | E37: FY27 SSLC EBITDA est. $1.24M

Sheet PL and Cash Flow
A1: EXOS + SSLC Consolidated P&L and Cash Flow — Option B Acquisition
A2: Assumes acquisition closes ~Q1 FY27. All figures in USD. SSLC consolidated from close date. Formulas link to Assumptions sheet.
A4: FY27 QUARTERLY — Exos+SSLC Consolidated (acquisition assumed closed Q1)
A5: Line Item | B5: FY27 Q1 | C5: FY27 Q2 | D5: FY27 Q3 | E5: FY27 Q4 | F5: FY27 Total | H5: Notes
A6: SSLC Revenue (post-consolidation) | B6: 713000 | C6: 1387000 | D6: 1400000 | E6: 2000000 | F6: =SUM(B6:E6) | H6: Q1 actual; Q2-Q4 management assumption distributing $5.5M FY27 total
A7: Exos Standalone Revenue | B7: 550000 | C7: 700000 | D7: 700000 | E7: 650000 | F7: =SUM(B7:E7) | H7: Management assumption; $2.6M FY27 total (v15 baseline excl. SSLC commission)
A8: Less: Intercompany Eliminations | B8: -125000 | C8: -125000 | D8: -125000 | E8: -125000 | F8: =SUM(B8:E8) | H8: Exos purchases from SSLC; $500K/yr eliminated
A9: NET CONSOLIDATED REVENUE | B9: =B6+B7+B8 | C9: =C6+C7+C8 | D9: =D6+D7+D8 | E9: =E6+E7+E8 | F9: =SUM(B9:E9)
A11: COST OF GOODS SOLD
A12: SSLC COGS (52% of SSLC rev) | B12: =B6*Assumptions!B45 | C12: =C6*Assumptions!B45 | D12: =D6*Assumptions!B45 | E12: =E6*Assumptions!B45 | F12: =SUM(B12:E12) | H12: 52% management assumption; derived from FY26
A13: Exos COGS (45% of Exos rev) | B13: =B7*0.45 | C13: =C7*0.45 | D13: =D7*0.45 | E13: =E7*0.45 | F13: =SUM(B13:E13) | H13: 45% management assumption (launch vehicle hardware-heavy)
A14: TOTAL COGS | B14: =B12+B13 | C14: =C12+C13 | D14: =D12+D13 | E14: =E12+E13 | F14: =SUM(B14:E14)
A15: GROSS PROFIT | B15: =B9-B14 | C15: =C9-C14 | D15: =D9-D14 | E15: =E9-E14 | F15: =SUM(B15:E15)
A16: Gross Margin % | B16: =IF(B9<>0,B15/B9,0) | C16: =IF(C9<>0,C15/C9,0) | D16: =IF(D9<>0,D15/D9,0) | E16: =IF(E9<>0,E15/E9,0) | F16: =SUM(B16:E16)
A18: OPERATING EXPENSES (combined)
A19: SSLC OpEx | B19: 350000 | C19: 350000 | D19: 350000 | E19: 350000 | F19: =SUM(B19:E19) | H19: FY27 $1.4M / 4 quarters
A20: Exos OpEx (excl. R&D) | B20: 650000 | C20: 650000 | D20: 650000 | E20: 650000 | F20: =SUM(B20:E20) | H20: Exos G&A / payroll (management assumption)
A21: Exos R&D / BLK3 dev | B21: 500000 | C21: 500000 | D21: 500000 | E21: 500000 | F21: =SUM(B21:E21) | H21: BLK3 development; ramps down post-flight
A22: TOTAL OPEX | B22: =SUM(B19:B21) | C22: =SUM(C19:C21) | D22: =SUM(D19:D21) | E22: =SUM(E19:E21) | F22: =SUM(B22:E22)
A24: EBITDA | B24: =B15-B22 | C24: =C15-C22 | D24: =D15-D22 | E24: =E15-E22 | F24: =SUM(B24:E24)
A25: EBITDA Margin % | B25: =IF(B9<>0,B24/B9,0) | C25: =IF(C9<>0,C24/C9,0) | D25: =IF(D9<>0,D24/D9,0) | E25: =IF(E9<>0,E24/E9,0) | F25: =SUM(B25:E25)
A26: D&A (est.) | B26: -40000 | C26: -40000 | D26: -40000 | E26: -40000 | F26: =SUM(B26:E26) | H26: $160K FY27 SSLC + Exos combined; management assumption
A27: EBIT | B27: =B24+B26 | C27: =C24+C26 | D27: =D24+D26 | E27: =E24+E26 | F27: =SUM(B27:E27)
A28: Interest / one-time | B28: 0 | C28: 0 | D28: 0 | E28: 0 | F28: =SUM(B28:E28) | H28: Acquisition-related one-time costs in Q1 (separate line)
A29: Pre-Tax Income | B29: =B27+B28 | C29: =C27+C28 | D29: =D27+D28 | E29: =E27+E28 | F29: =SUM(B29:E29)
A31: FY27 QUARTERLY — CASH FLOW (simplified)
A32: Beginning Cash (Exos + SSLC at close) | B32: 198000 | C32: =E32+E33+E34 | D32: =E33+E34+E35 | E32: =E34+E35+E36 | H32: SSLC cash $198K at QB date
A33: SSLC acquisition cash out | B33: -2510000 | C33: 0 | D33: 0 | E33: 0 | H33: Deal cash at close (Q1)
A34: Working capital injection | B34: -500000 | C34: 0 | D34: 0 | E34: 0 | H34: SSLC bridge; Q1
A35: Operating cash (EBITDA proxy) | B35: =B24 | C35: =C24 | D35: =D24 | E35: =E24 | H35: EBITDA proxy; ± WC changes not modeled
A36: Series A proceeds allocated | B36: 3010000 | C36: 0 | D36: 0 | E36: 0 | H36: Acquisition ($2.51M) + WC bridge ($0.5M) from first close
A37: ENDING CASH | B37: =SUM(B32:B36) | C37: =C32+C33+C34+C35+C36 | D37: =D32+D33+D34+D35+D36 | E37: =E32+E33+E34+E35+E36 | F37: =E37
A40: 5-YEAR ANNUAL P&L — FY27–FY31 (Exos+SSLC Consolidated)
A41: Line Item | B41: FY27 | C41: FY28 | D41: FY29 | E41: FY30 | F41: FY31 | G41: FY27-31 CAGR | H41: Notes
A42: SSLC Revenue | B42: =Assumptions!B37+Assumptions!B44 | C42: =Assumptions!B48 | D42: =Assumptions!B49 | E42: =Assumptions!B50 | F42: =Assumptions!B51 | H42: SSLC actual + IM firm FY27; projections FY28+
A43: Exos Standalone Revenue | B43: =Assumptions!B56 | C43: =Assumptions!B57 | D43: =Assumptions!B58 | E43: =Assumptions!B59 | F43: =Assumptions!B60 | H43: v15 baseline excl. SSLC commission
A44: Less: Intercompany | B44: -500000 | C44: -575000 | D44: -661000 | E44: -760000 | F44: -874000 | H44: Exos tank purchases from SSLC; interco elim.
A45: NET CONSOLIDATED REVENUE | B45: =B42+B43+B44 | C45: =C42+C43+C44 | D45: =D42+D43+D44 | E45: =E42+E43+E44 | F45: =F42+F43+F44 | G45: =IFERROR((F45/B45)^(1/4)-1,0)
A46: GROSS PROFIT
A47: SSLC Gross Profit (48%) | B47: =B42*(1-Assumptions!B45) | C47: =C42*(1-Assumptions!B45) | D47: =D42*(1-Assumptions!B45) | E47: =E42*(1-Assumptions!B45) | F47: =F42*(1-Assumptions!B45)
...

Sheet Returns and Dilution
A1: SSLC Option B — Returns, Dilution & Benchmark Comparison
A3: Metric | B3: Low | C3: Base | D3: High | E3: v15 Benchmark | F3: Notes
A4: FY27 SSLC revenue (Option B) | B4: ='PL and Cash Flow'!B42 | C4: ='PL and Cash Flow'!B42 | D4: ='PL and Cash Flow'!B42 | E4: =Assumptions!B52
A5: FY31 SSLC revenue (Option B) | B5: ='PL and Cash Flow'!F42 | C5: ='PL and Cash Flow'!F42 | D5: ='PL and Cash Flow'!F42 | E5: =Assumptions!B53
A6: FY27 SSLC rev vs benchmark ($+) | B6: =B4-D4 | C6: =C4-D4 | D6: =D4-E4 | E6: — | F6: Positive = Option B exceeds old model
A7: FY31 SSLC rev vs benchmark ($+) | B7: =B5-E4 | C7: =C5-E4 | D7: =D5-E5 | E7: — | F7: Substantial delta; IM tank confirmation changes picture
A9: Total consideration (all-in) | B9: ='Deal Structure'!B35 | C9: ='Deal Structure'!C35 | D9: ='Deal Structure'!D35 | E9: n/a | F9: Base price + earn-out + assumed debt
A10: Implied 100% SSLC value | B10: ='Deal Structure'!B36 | C10: ='Deal Structure'!C36 | D10: ='Deal Structure'!D36 | E10: n/a
A11: Exos FY31 SSLC EBITDA | B11: ='PL and Cash Flow'!B52 | C11: ='PL and Cash Flow'!B52 | D11: ='PL and Cash Flow'!F52 | E11: n/a | F11: SSLC standalone EBITDA contribution
A12: SSLC FY31 EBITDA × 10x (value) | B12: =B11*10 | C12: =C11*10 | D12: =D11*10 | E12: n/a | F12: Indicative exit value at 10× EBITDA
A13: Acquisition ROI (FY31 val/cost) | B13: =B12/B9 | C13: =C12/C9 | D13: =D12/D9 | E13: n/a | F13: Illustrative; not a guarantee
A14: EARN-OUT DILUTION ANALYSIS
A15: Earn-out ii: Exos stock (low) | B15: =Assumptions!B28 | F15: % of FD shares issued for earn-out
A16: Earn-out ii: Exos stock (base) | C16: =Assumptions!B29
A17: Earn-out ii: Exos stock (high) | D17: =Assumptions!B30
A18: Earn-out stock dilution | B18: =B15 | C18: =C16 | D18: =D17 | E18: n/a | F18: Non-material; well within Series A dilution
A19: CASH DEPLOYMENT SUMMARY
A20: FY27 net cash deployment | B20: =Assumptions!B10+Assumptions!B16 | C20: =Assumptions!B10+Assumptions!B16 | D20: =Assumptions!B10+Assumptions!B16 | E20: n/a | F20: Acquisition + WC bridge; from Series A
A21: Series A first close | B21: =Assumptions!B17 | C21: =Assumptions!B17 | D21: =Assumptions!B17 | E21: n/a | F21: $10M; well covers acquisition+bridge
A22: Remaining for Exos ops post-acq | B22: =B21-B20 | C22: =C21-C20 | D22: =D21-D20 | E22: n/a | F22: Available for BLK3, R&D, G&A after SSLC

Sheet Funding
A1: SSLC Option B — Funding Structure & Risks
A3: FUNDING OVERVIEW
A4: Acquisition is funded from Exos-only post-RTO proceeds | B4: Investor requirement | C4: SSLC stays OUT of RTO perimeter (Jon 10/2 remarks to SSLC board)
A5: Series A first close ($) | B5: =Assumptions!B17 | C5: D1 of record; $10M
A6: Allocated to SSLC acquisition | B6: =Assumptions!B10 | C6: Cash deal price
A7: Allocated to SSLC WC bridge | B7: =Assumptions!B16 | C7: $0.3–0.7M; mid=$500K
A8: Remaining for Exos operations | B8: =B5-B6-B7
A9: Pre-RTO convertible note ($) | B9: =Assumptions!B20 | C9: FNEX/Ainigma; primary Exos development capital
A10: TOTAL FINANCING AT CLOSE | B10: =B5 | C10: Series A covers acquisition + WC bridge
A12: §3 FINANCING TRIGGER GAP (CRITICAL RISK)
A13: FNEX/Ainigma role | B13: Advisor / broker-dealer | C13: FNEX is NOT itself the 'investor or lender' under §3
A14: Risk: SSLC counsel (Danny) challenges trigger | B14: HIGH | C14: §3 requires 'investor or lender capable of financing'; advisory mandate may not qualify
A15: Mitigation required | B15: Attach FNEX countersigned agreement + investor/sponsor use-of-proceeds letter naming SSLC asset purchase | C15: [Confirm FNEX agreement countersigned per D-7281974 10/6]
A16: §3 extension right | B16: SSLC shall not unreasonably withhold | C16: 90-day window from exclusivity grant; request extension proactively while good-faith progress shown
A17: Timing: 90-day exclusivity ends | B17: ~Jan 6, 2027 | C17: From ~Oct 8 grant; RTO is 4-5 months; need extension
A19: RELATED-PARTY DISCLOSURES
A20: Jon sits on BOTH boards | B20: Conflict of interest | C20: Jon must RECUSE from SSLC vote; send as Exos CEO only
A21: Fairness opinion | B21: Required (Eqvista engaged) | C21: Eqvista engaged for 409A + fairness opinion per D1-D4 of record
A22: Disinterested director approval | B22: Required (SSLC side) | C22: Markus Rufer and Bob as disinterested directors approve; Jon abstains
A23: Legal review | B23: Deferred (Jon 10/7) | C23: Negotiation stage; no legal review until Jon calls it
A25: HE-TANK DISPUTE RISK
A26: Rev3 tank leaks at boss post-Hysol | B26: RISK | C26: 10/1 hydro fail; Morey questions as flight article. Plan B: qualified COPV ≤$250K (MC #3056, D-7281994)
A27: Impact on acquisition | B27: SSLC demonstrably can't deliver BLK3 flight article | C27: Customer-hat PO default (due 9/24/2025) kept in reserve; resolves post-acquisition
A29: SSLC CASH RISK
A30: SSLC cash at close (est.) | B30: =Assumptions!B42+Assumptions!B41-Assumptions!B16 | C30: FY27 Q1 cash + billed-ahead minus WC need
A31: Risk: SSLC runs out of cash before close | B31: MEDIUM | C31: Cash $198K + collections on $984K prepaid; needs $0.3-0.7M to finish work
A32: Mitigation: Option C pre-cliff bridge | B32: Secured prepaid BLK3 tank PO $300-700K | C32: Use only disclosed SSLC numbers; Option C held for follow-up
A34: DATA NOT VERIFIED IN SSLC QB (CRITICAL GAPS)
A35: SSLC total liabilities / AP | B35: ~$500K est. — TO VERIFY IN SSLC QB | C35: QB session expired 10/7; cannot confirm Microcosm/Wertz note amounts. Must verify before signing.
A36: SSLC total debt assumed at face | B36: TO VERIFY IN SSLC QB | C36: Critical for Bob/Jim: personal path to yes depends on debt payoff amount
A37: Exos loan to SSLC status in QB | B37: ~$38K — cancelled per Jon 10/2 | C37: Verify cancellation documented in QB
