Workbook

Sheet Index
B3: Date: | C3: =TODAY() -> 46171
A5: 1 | B5: Instructions
A6: =A5+1 -> 2 | B6: Dashboard
A7: =A6+1 -> 3 | B7: Controls
A8: =A7+1 -> 4 | B8: Revenue Asumptions
A9: =A8+1 -> 5 | B9: Expense Assumptions
A10: =A9+1 -> 6 | B10: Payroll Assumptions
A11: =A10+1 -> 7 | B11: Fixed Asset Schedules
A12: =A11+1 -> 8 | B12: Monthly P&L
A13: =A12+1 -> 9 | B13: Annual P&L
A14: =A13+1 -> 10 | B14: Monthly CFS
A15: =A14+1 -> 11 | B15: Annual CFS
A16: =A15+1 -> 12 | B16: Balance Sheet
A17: =A16+1 -> 13 | B17: Annual Balance Sheet
A18: =A16+1 -> 13 | B18: Funding Ask
A19: =A18+1 -> 14 | B19: Valuation

Sheet Instructions
A4: How this Model works
A6: A. | B6: Financial models are an attempt to present a "big picture" view of future financial performance. Many simplifying assumptions are made, and the model does not attempt to capture all financial details & nuances. Most simplifying assumptions will not have a material impact on the big picture - for example, the cash flow differences between leasing or purchasing a vehicle probably won't affect the big picture unless the company operates a massive fleet of vehicles. The model may also simplify issues such as the expensing vs. amortizing of startup expenses.
A7: B. | B7: The quality of any forecast is dependent on the quality of the assumptions and the quality of the cause-and-effect relationships incorporated into the model. The focus must be on the quality of the assumptions taken; and its cause-and-effect relationships.
A9: Colour Coding
C11: The Control Tab is the Input Tab for Assumptions.
C13: The tabs in Light Blue reflect the different of Assumptions taken in the model. These values are controlled by the values input in the Control Tab.
C15: Tabs in Light Green are output tabs, which display the information from the input tabs. Do not modify anything on the green tabs.
B17: 0 | C17: ONLY the BLUE cells containing texts in BLUE are Hard Coded and can be adjusted by the user without compromising the excel formulas.
B19: 0 | C19: Cells shaded Grey-Blue contain a dropdown list, and take values from the dropdown list only. Any other value inputed, will go on to show the user an error.
C21: Cells shaded Yellow contain instructions & explanations for the user to better understand the model, and the asumptions taken by the model

Sheet Dashboard
A1: Back To Index
B3: Overview | C3: 1 | D3: =+C3+1 -> 2 | E3: =+D3+1 -> 3 | F3: =+E3+1 -> 4 | G3: =+F3+1 -> 5
B5: Total Revenue | C5: ='Annual P&L'!B14/10^6 -> 8.86754 | D5: ='Annual P&L'!C14/10^6 -> 21.108525 | E5: ='Annual P&L'!D14/10^6 -> 43.092777 | F5: ='Annual P&L'!E14/10^6 -> 95.919145 | G5: ='Annual P&L'!F14/10^6 -> 179.18554
B6: Y.O.Y Growth % | D6: ='Annual P&L'!C15 -> 1.3804263 | E6: ='Annual P&L'!D15 -> 1.0414869 | F6: ='Annual P&L'!E15 -> 1.2258753 | G6: ='Annual P&L'!F15 -> 0.86808943
B8: Gross Profit | C8: ='Annual P&L'!B19/10^6 -> #N/A | D8: ='Annual P&L'!C19/10^6 -> #N/A | E8: ='Annual P&L'!D19/10^6 -> #N/A | F8: ='Annual P&L'!E19/10^6 -> #N/A | G8: ='Annual P&L'!F19/10^6 -> #N/A
B9: Gross Margins % | C9: ='Annual P&L'!B20 -> #N/A | D9: ='Annual P&L'!C20 -> #N/A | E9: ='Annual P&L'!D20 -> #N/A | F9: ='Annual P&L'!E20 -> #N/A | G9: ='Annual P&L'!F20 -> #N/A
B11: EBITDA | C11: ='Annual P&L'!B39/10^6 -> #N/A | D11: ='Annual P&L'!C39/10^6 -> #N/A | E11: ='Annual P&L'!D39/10^6 -> #N/A | F11: ='Annual P&L'!E39/10^6 -> #N/A | G11: ='Annual P&L'!F39/10^6 -> #N/A
B12: EBITDA Margin % | C12: ='Annual P&L'!B40 -> #N/A | D12: ='Annual P&L'!C40 -> #N/A | E12: ='Annual P&L'!D40 -> #N/A | F12: ='Annual P&L'!E40 -> #N/A | G12: ='Annual P&L'!F40 -> #N/A
B14: PAT | C14: ='Annual P&L'!B50/10^6 -> #N/A | D14: ='Annual P&L'!C50/10^6 -> #N/A | E14: ='Annual P&L'!D50/10^6 -> #N/A | F14: ='Annual P&L'!E50/10^6 -> #N/A | G14: ='Annual P&L'!F50/10^6 -> #N/A
B15: PAT Margin % | C15: ='Annual P&L'!B51 -> #N/A | D15: ='Annual P&L'!C51 -> #N/A | E15: ='Annual P&L'!D51 -> #N/A | F15: ='Annual P&L'!E51 -> #N/A | G15: ='Annual P&L'!F51 -> #N/A
S43: Product Devlopment | T43: 0.6
S44: Marketing | T44: 0.3
S45: Opex | T45: 0.1

Sheet Controls
A1: EXOS Aerospace | B1: Beginning Month: | C1: July | E1: NOTE: Month 1 = July 2025. Updated May 29, 2026. Includes entX LSA ($840K) + Second BLK3 Flight ($750K) + NASA Flight Opportunities IDIQ ($8M/yr steady state from Q3 2027). Exos is ONLY US FAA-licensed co. actively selling suborbital reusable payload services. Campaign model: 2 NASA + 1 commercial flight per quarter. Dual listing: Euronext Dublin + TXSE.
A2: Controls Sheet
A3: Amounts in USD | B3: Note: All the figures and assumptions are taken monthly
A4: Back To Index
A5: Assumptions for the Annual Period | B5: 1 | C5: =+B5+1 -> 2 | D5: =+C5+1 -> 3 | E5: =+D5+1 -> 4 | F5: =+E5+1 -> 5
A7: REVENUE ASSUMPTIONS
A9: BLK4 360kg LAUNCHER
A11: BLK4 360kg - Cost to Customer - Wet Lease (Commercial Flights) | B11: 3753756.3 | C11: 3753756.3 | D11: 3753756.3 | E11: 3753756.3 | F11: 3753756.3
A13: BLK4 360kg - Vehicle Launch | B13: 6000000 | C13: 6000000 | D13: 6000000 | E13: 6000000 | F13: 6000000
A15: PROPULSION SYSTEM SALES 5K 20K DESIGNS WITH TRIFDYNE PRESS.
A17: Propulsion System Cost to Customer | B17: 250000 | C17: 250000 | D17: 250000 | E17: 250000 | F17: 250000
A19: EXOS US BLK4 Wet Lease Launches
A21: Initial Outfit per Vessel | B21: 1
A23: EXOS US BLK4 Wet Lease Launches Cost to Customer | B23: 6000000 | C23: 6000000 | D23: 6000000 | E23: 6000000 | F23: 6000000
A25: Second Stage Sales
A27: Second Stage Price Per Unit | B27: 350000 | C27: 350000 | D27: 350000 | E27: 350000 | F27: 350000
A29: Scorpius Space Corp Tank Manufacture
A31: Linerless Carbon Fiber Composite Tanks | B31: 183000 | C31: =B31*(1+C32) -> 274500 | D31: =C31*(1+D32) -> 343125 | E31: =D31*(1+E32) -> 428906.25 | F31: =E31*(1+F32) -> 536132.81
A32: Annual Change % | C32: 0.5 | D32: 0.25 | E32: 0.25 | F32: 0.25
A34: Sarge Technology and Hardware Sales
A36: Contract Value | B36: 500000 | C36: =B36*(1+C37) -> 1000000 | D36: =C36*(1+D37) -> 1200000 | E36: =D36*(1+E37) -> 1440000 | F36: =E36*(1+F37) -> 1800000
A37: Annual Change % | C37: 1 | D37: 0.2 | E37: 0.2 | F37: 0.25
A40: OPEX
A42: COGS
A44: BLK4 360kg LAUNCHER - COGS - Wet Lease | B44: 3003005.1 | C44: 3003005.1 | D44: 3003005.1 | E44: 3003005.1 | F44: 3003005.1
A46: BLK4 360kg LAUNCHER - COGS - Vehicle Launch | B46: 4525325.6 | C46: 4525325.6 | D46: 4525325.6 | E46: 4525325.6 | F46: 2909137.9
A48: PROPULSION SYSTEM SALES 5K 20K DESIGNS WITH TRIFDYNE PRESS - COGS | B48: 0.5 | C48: 0.5 | D48: 0.5 | E48: 0.5 | F48: 0.5
A50: EXOS US BLK4 Wet Lease Launches - COGS | B50: 0.5 | C50: 0.5 | D50: 0.5 | E50: 0.5 | F50: 0.5
A52: Second Stage Sales - COGS | B52: 0.5 | C52: 0.5 | D52: 0.5 | E52: 0.5 | F52: 0.5
A54: Scorpius Space Corp Tank Manufacture - COGS | B54: 0.35 | C54: 0.35 | D54: 0.35 | E54: 0.3 | F54: 0.3
A56: Sarge Technology and Hardware Sales - COGS | B56: 0.5 | C56: 0.5 | D56: 0.5 | E56: 0.5 | F56: 0.5
A59: OPEX
A61: Internet and Phone | B61: ='Oper, Cap, Other Assum'!L15 -> 750 | C61: ='Oper, Cap, Other Assum'!G16 -> 772.5 | D61: ='Oper, Cap, Other Assum'!G17 -> 795.675 | E61: ='Oper, Cap, Other Assum'!G18 -> 1639.0905 | F61: ='Oper, Cap, Other Assum'!G19 -> 1688.2632
A63: Insurance | B63: ='Oper, Cap, Other Assum'!L22 -> 3000 | C63: ='Oper, Cap, Other Assum'!G23 -> 6180 | D63: ='Oper, Cap, Other Assum'!G24 -> 12180 | E63: ='Oper, Cap, Other Assum'!G25 -> 37930 | F63: ='Oper, Cap, Other Assum'!G26 -> 140180
A65: Professional Fees | B65: ='Oper, Cap, Other Assum'!L29 -> 3500 | C65: ='Oper, Cap, Other Assum'!G30 -> 3605 | D65: ='Oper, Cap, Other Assum'!G31 -> 3713.15 | E65: ='Oper, Cap, Other Assum'!G32 -> 3824.5445 | F65: ='Oper, Cap, Other Assum'!G33 -> 3939.2808
A67: Rent and Utility | B67: ='Oper, Cap, Other Assum'!M36 -> 40000 | C67: ='Oper, Cap, Other Assum'!G37 -> 41600 | D67: ='Oper, Cap, Other Assum'!G38 -> 43264 | E67: ='Oper, Cap, Other Assum'!G39 -> 89989.12 | F67: ='Oper, Cap, Other Assum'!G40 -> 93588.685
A69: Office and Other Expenses (per employee) | B69: 5000 | C69: =B69*(1+C70) -> 5150 | D69: =C69*(1+D70) -> 5304.5 | E69: =D69*(1+E70) -> 5463.635 | F69: =E69*(1+F70) -> 5627.5441
A70: Annual Change % | C70: 0.03 | D70: 0.03 | E70: 0.03 | F70: 0.03
A72: Marketing | B72: ='Oper, Cap, Other Assum'!G58 -> 15000 | C72: ='Oper, Cap, Other Assum'!G59 -> 16500 | D72: ='Oper, Cap, Other Assum'!G60 -> 18150 | E72: ='Oper, Cap, Other Assum'!G61 -> 19965 | F72: ='Oper, Cap, Other Assum'!G62 -> 21961.5
A74: Travel Expenses | B74: ='Oper, Cap, Other Assum'!G65 -> 20000 | C74: ='Oper, Cap, Other Assum'!G66 -> 20600 | D74: ='Oper, Cap, Other Assum'!G67 -> 21218 | E74: ='Oper, Cap, Other Assum'!G68 -> 21854.54 | F74: ='Oper, Cap, Other Assum'!G69 -> 22510.176
...

Sheet Revenue Asumptions
A1: EXOS Aerospace
A2: Revenue Assumptions Sheet | B2: =Controls!C1 -> July | C2: =TEXT(DATE(2000, MATCH(B2, {"January","February","March","April","May","June","July","August","September","October","November","December"}, 0) + 1, 1), "mmmm") -> August | D2: =TEXT(DATE(2000, MATCH(C2, {"January","February","March","April","May","June","July","August","September","October","November","December"}, 0) + 1, 1), "mmmm") -> September | E2: =TEXT(DATE(2000, MATCH(D2, {"January","February","March","April","May","June","July","August","September","October","November","December"}, 0) + 1, 1), "mmmm") -> October | F2: =TEXT(DATE(2000, MATCH(E2, {"January","February","March","April","May","June","July","August","September","October","November","December"}, 0) + 1, 1), "mmmm") -> November | G2: =TEXT(DATE(2000, MATCH(F2, {"January","February","March","April","May","June","July","August","September","October","November","December"}, 0) + 1, 1), "mmmm") -> December | H2: =TEXT(DATE(2000, MATCH(G2, {"January","February","March","April","May","June","July","August","September","October","November","December"}, 0) + 1, 1), "mmmm") -> January | I2: =TEXT(DATE(2000, MATCH(H2, {"January","February","March","April","May","June","July","August","September","October","November","December"}, 0) + 1, 1), "mmmm") -> February | J2: =TEXT(DATE(2000, MATCH(I2, {"January","February","March","April","May","June","July","August","September","October","November","December"}, 0) + 1, 1), "mmmm") -> March | ... BI2: =TEXT(DATE(2000, MATCH(BH2, {"January","February","March","April","May","June","July","August","September","October","November","December"}, 0) + 1, 1), "mmmm") -> June
A3: Amounts in USD | B3: 1 | C3: =IF(MOD(B4,B5) = 0,B3+1,B3) -> 1 | D3: =IF(MOD(C4,C5) = 0,C3+1,C3) -> 1 | E3: =IF(MOD(D4,D5) = 0,D3+1,D3) -> 1 | F3: =IF(MOD(E4,E5) = 0,E3+1,E3) -> 1 | G3: =IF(MOD(F4,F5) = 0,F3+1,F3) -> 1 | H3: =IF(MOD(G4,G5) = 0,G3+1,G3) -> 1 | I3: =IF(MOD(H4,H5) = 0,H3+1,H3) -> 1 | J3: =IF(MOD(I4,I5) = 0,I3+1,I3) -> 1 | ... BI3: =IF(MOD(BH4,BH5) = 0,BH3+1,BH3) -> 5
A4: Back To Index | B4: 1 | C4: =B4+1 -> 2 | D4: =C4+1 -> 3 | E4: =D4+1 -> 4 | F4: =E4+1 -> 5 | G4: =F4+1 -> 6 | H4: =G4+1 -> 7 | I4: =H4+1 -> 8 | J4: =I4+1 -> 9 | ... BI4: =BH4+1 -> 60
A5: Assumptions for the Monthly Period | B5: 12 | C5: 12 | D5: 12 | E5: 12 | F5: 12 | G5: 12 | H5: 12 | I5: 12 | J5: 12 | K5: 12 | L5: 12 | M5: 12 | N5: 12 | O5: 12 | P5: 12 | Q5: 12 | R5: 12 | S5: 12 | T5: 12 | U5: 12 | V5: 12 | W5: 12 | X5: 12 | Y5: 12 | Z5: 12 | AA5: 12 | AB5: 12 | AC5: 12 | AD5: 12 | AE5: 12 | AF5: 12 | AG5: 12 | AH5: 12 | AI5: 12 | AJ5: 12 | AK5: 12 | AL5: 12 | AM5: 12 | AN5: 12 | AO5: 12 | AP5: 12 | AQ5: 12 | AR5: 12 | AS5: 12 | AT5: 12 | AU5: 12 | AV5: 12 | AW5: 12 | AX5: 12 | AY5: 12 | AZ5: 12 | BA5: 12 | BB5: 12 | BC5: 12 | BD5: 12 | BE5: 12 | BF5: 12 | BG5: 12 | BH5: 12 | BI5: 12
A7: BLK4 360kg launcher
A9: Wet Leases | B9: 0 | C9: 0 | D9: 0 | E9: 0 | F9: 0 | G9: 0 | H9: 0 | I9: 0 | J9: 0 | K9: 0 | L9: 0 | M9: 0 | N9: 0 | O9: 0 | P9: 0 | Q9: 0 | R9: 0 | S9: 0 | T9: 0 | U9: 0 | V9: 0 | W9: 0 | X9: 0 | Y9: 0 | Z9: 0 | AA9: 0 | AB9: 0 | AC9: 0 | AD9: 0 | AE9: 0 | AF9: 0 | AG9: 0 | AH9: 0 | AI9: 0 | AJ9: 0 | AK9: 0 | AL9: 0 | AM9: 0 | AN9: 0 | AO9: 0 | AP9: 0 | AQ9: 0 | AR9: 0 | AS9: 0 | AT9: 0 | AU9: 0 | AV9: 0 | AW9: 0 | AX9: 0 | AY9: 0 | AZ9: 0 | BA9: 0 | BB9: 0 | BC9: 0 | BD9: 0 | BE9: 0 | BF9: 0 | BG9: 0 | BH9: 0 | BI9: 0
A11: Vehicle Launches | B11: 0 | C11: 0 | D11: 0 | E11: 0 | F11: 0 | G11: 0 | H11: 0 | I11: 0 | J11: 0 | K11: 0 | L11: 0 | M11: 0 | N11: 0 | O11: 0 | P11: 0 | Q11: 0 | R11: 0 | S11: 0 | T11: 0 | U11: 0 | V11: 0 | W11: 0 | X11: 0 | Y11: 0 | Z11: 0 | AA11: 0 | AB11: 0 | AC11: 0 | AD11: 0 | AE11: 0 | AF11: 0 | AG11: 0 | AH11: 0 | AI11: 0 | AJ11: 0 | AK11: 0 | AL11: 0 | AM11: 0 | AN11: 0 | AO11: 0 | AP11: 0 | AQ11: 0 | AR11: 0 | AS11: 0 | AT11: 0 | AU11: 0 | AV11: 0 | AW11: 0 | AX11: 0 | AY11: 0 | AZ11: 0 | BA11: 0 | BB11: 0 | BC11: 0 | BD11: 0 | BE11: 0 | BF11: 0 | BG11: 0 | BH11: 0 | BI11: 0 | BJ11: 0 | BK11: 0 | BL11: 1 | BM11: 0 | BN11: 2 | BO11: 0 | BP11: 3 | BQ11: 0 | BR11: 4 | BS11: 0 | BT11: 4 | BU11: 0 | BV11: 4 | BW11: 0 | BX11: 4 | BY11: 0 | BZ11: 5 | CA11: 0 | CB11: 5 | CC11: 0 | CD11: 0 | CE11: 6 | CF11: 0 | CG11: 6 | CH11: 0 | CI11: 0 | CJ11: 6 | CK11: 0 | CL11: 6
A13: Revenue
A15: BLK4 360kg - Cost to Customer - Wet Lease (Commercial Flights) | B15: =((HLOOKUP(B$3,Controls!$A$5:$F$178,MATCH($A15,Controls!$A$5:$A$178,0),0))*B9)+(SUM(B17:B22)) -> 0 | C15: =((HLOOKUP(C$3,Controls!$A$5:$F$178,MATCH($A15,Controls!$A$5:$A$178,0),0))*C9)+(SUM(C17:C22)) -> 0 | D15: =((HLOOKUP(D$3,Controls!$A$5:$F$178,MATCH($A15,Controls!$A$5:$A$178,0),0))*D9)+(SUM(D17:D22)) -> 0 | E15: =((HLOOKUP(E$3,Controls!$A$5:$F$178,MATCH($A15,Controls!$A$5:$A$178,0),0))*E9)+(SUM(E17:E22)) -> 0 | F15: =((HLOOKUP(F$3,Controls!$A$5:$F$178,MATCH($A15,Controls!$A$5:$A$178,0),0))*F9)+(SUM(F17:F22)) -> 0 | G15: =((HLOOKUP(G$3,Controls!$A$5:$F$178,MATCH($A15,Controls!$A$5:$A$178,0),0))*G9)+(SUM(G17:G22)) -> 0 | H15: =((HLOOKUP(H$3,Controls!$A$5:$F$178,MATCH($A15,Controls!$A$5:$A$178,0),0))*H9)+(SUM(H17:H22)) -> 0 | I15: =((HLOOKUP(I$3,Controls!$A$5:$F$178,MATCH($A15,Controls!$A$5:$A$178,0),0))*I9)+(SUM(I17:I22)) -> 0 | ... BI15: =((HLOOKUP(BI$3,Controls!$A$5:$F$178,MATCH($A15,Controls!$A$5:$A$178,0),0))*BI9)+(SUM(BI17:BI22)) -> 6833332.8
A17: BLK4 360kg — Commercial Flight Revenue (Vehicle Sales & Wet Lease) | B17: 0 | C17: 0 | D17: 0 | E17: 0 | F17: 0 | G17: 0 | H17: 0 | I17: 0 | J17: 0 | K17: 0 | L17: 0 | M17: 0 | N17: 0 | O17: 0 | P17: 0 | Q17: 0 | R17: 0 | S17: 0 | T17: 0 | U17: 0 | V17: 0 | W17: 0 | X17: 0 | Y17: 0 | Z17: 0 | AA17: 0 | AB17: 0 | AC17: 0 | AD17: 0 | AE17: 0 | AF17: 0 | AG17: 0 | AH17: 0 | AI17: 1092592.3 | AJ17: 1092592.3 | AK17: 1092592.3 | AL17: 1092592.3 | AM17: 1092592.3 | AN17: 1092592.3 | AO17: 1092592.3 | AP17: 1092592.3 | AQ17: 1092592.3 | AR17: 2583333 | AS17: 2583333 | AT17: 2583333 | AU17: 2583333 | AV17: 2583333 | AW17: 2583333 | AX17: 2583333 | AY17: 2583333 | AZ17: 2583333 | BA17: 2583333 | BB17: 2583333 | BC17: 2583333 | BD17: 6833332.8 | BE17: 6833332.8 | BF17: 6833332.8 | BG17: 6833332.8 | BH17: 6833332.8 | BI17: 6833332.8
A18: Additional Revenue/Contract | B18: 0 | C18: 0 | D18: 0 | E18: 0 | F18: 0 | G18: 0 | H18: 0 | I18: 0 | J18: 0 | K18: 0 | L18: 0 | M18: 0 | N18: 0 | O18: 0 | P18: 0 | Q18: 0 | R18: 0 | S18: 0 | T18: 0 | U18: 0 | V18: 0 | W18: 0 | X18: 0 | Y18: 0 | Z18: 0 | AA18: 0 | AB18: 0 | AC18: 0 | AD18: 0 | AE18: 0 | AF18: 0 | AG18: 0 | AH18: 0 | AI18: 0 | AJ18: 0 | AK18: 0 | AL18: 0 | AM18: 0 | AN18: 0 | AO18: 0 | AP18: 0 | AQ18: 0 | AR18: 0 | AS18: 0 | AT18: 0 | AU18: 0 | AV18: 0 | AW18: 0 | AX18: 0 | AY18: 0 | AZ18: 0 | BA18: 0 | BB18: 0 | BC18: 0 | BD18: 0 | BE18: 0 | BF18: 0 | BG18: 0 | BH18: 0 | BI18: 0
A19: Additional Revenue/Contract | B19: 0 | C19: 0 | D19: 0 | E19: 0 | F19: 0 | G19: 0 | H19: 0 | I19: 0 | J19: 0 | K19: 0 | L19: 0 | M19: 0 | N19: 0 | O19: 0 | P19: 0 | Q19: 0 | R19: 0 | S19: 0 | T19: 0 | U19: 0 | V19: 0 | W19: 0 | X19: 0 | Y19: 0 | Z19: 0 | AA19: 0 | AB19: 0 | AC19: 0 | AD19: 0 | AE19: 0 | AF19: 0 | AG19: 0 | AH19: 0 | AI19: 0 | AJ19: 0 | AK19: 0 | AL19: 0 | AM19: 0 | AN19: 0 | AO19: 0 | AP19: 0 | AQ19: 0 | AR19: 0 | AS19: 0 | AT19: 0 | AU19: 0 | AV19: 0 | AW19: 0 | AX19: 0 | AY19: 0 | AZ19: 0 | BA19: 0 | BB19: 0 | BC19: 0 | BD19: 0 | BE19: 0 | BF19: 0 | BG19: 0 | BH19: 0 | BI19: 0
A20: Additional Revenue/Contract | B20: 0 | C20: 0 | D20: 0 | E20: 0 | F20: 0 | G20: 0 | H20: 0 | I20: 0 | J20: 0 | K20: 0 | L20: 0 | M20: 0 | N20: 0 | O20: 0 | P20: 0 | Q20: 0 | R20: 0 | S20: 0 | T20: 0 | U20: 0 | V20: 0 | W20: 0 | X20: 0 | Y20: 0 | Z20: 0 | AA20: 0 | AB20: 0 | AC20: 0 | AD20: 0 | AE20: 0 | AF20: 0 | AG20: 0 | AH20: 0 | AI20: 0 | AJ20: 0 | AK20: 0 | AL20: 0 | AM20: 0 | AN20: 0 | AO20: 0 | AP20: 0 | AQ20: 0 | AR20: 0 | AS20: 0 | AT20: 0 | AU20: 0 | AV20: 0 | AW20: 0 | AX20: 0 | AY20: 0 | AZ20: 0 | BA20: 0 | BB20: 0 | BC20: 0 | BD20: 0 | BE20: 0 | BF20: 0 | BG20: 0 | BH20: 0 | BI20: 0
A21: Additional Revenue/Contract | B21: 0 | C21: 0 | D21: 0 | E21: 0 | F21: 0 | G21: 0 | H21: 0 | I21: 0 | J21: 0 | K21: 0 | L21: 0 | M21: 0 | N21: 0 | O21: 0 | P21: 0 | Q21: 0 | R21: 0 | S21: 0 | T21: 0 | U21: 0 | V21: 0 | W21: 0 | X21: 0 | Y21: 0 | Z21: 0 | AA21: 0 | AB21: 0 | AC21: 0 | AD21: 0 | AE21: 0 | AF21: 0 | AG21: 0 | AH21: 0 | AI21: 0 | AJ21: 0 | AK21: 0 | AL21: 0 | AM21: 0 | AN21: 0 | AO21: 0 | AP21: 0 | AQ21: 0 | AR21: 0 | AS21: 0 | AT21: 0 | AU21: 0 | AV21: 0 | AW21: 0 | AX21: 0 | AY21: 0 | AZ21: 0 | BA21: 0 | BB21: 0 | BC21: 0 | BD21: 0 | BE21: 0 | BF21: 0 | BG21: 0 | BH21: 0 | BI21: 0
A22: Additional Revenue/Contract | B22: 0 | C22: 0 | D22: 0 | E22: 0 | F22: 0 | G22: 0 | H22: 0 | I22: 0 | J22: 0 | K22: 0 | L22: 0 | M22: 0 | N22: 0 | O22: 0 | P22: 0 | Q22: 0 | R22: 0 | S22: 0 | T22: 0 | U22: 0 | V22: 0 | W22: 0 | X22: 0 | Y22: 0 | Z22: 0 | AA22: 0 | AB22: 0 | AC22: 0 | AD22: 0 | AE22: 0 | AF22: 0 | AG22: 0 | AH22: 0 | AI22: 0 | AJ22: 0 | AK22: 0 | AL22: 0 | AM22: 0 | AN22: 0 | AO22: 0 | AP22: 0 | AQ22: 0 | AR22: 0 | AS22: 0 | AT22: 0 | AU22: 0 | AV22: 0 | AW22: 0 | AX22: 0 | AY22: 0 | AZ22: 0 | BA22: 0 | BB22: 0 | BC22: 0 | BD22: 0 | BE22: 0 | BF22: 0 | BG22: 0 | BH22: 0 | BI22: 0
A24: BLK4 360kg - Vehicle Launch | B24: =((HLOOKUP(B$3,Controls!$A$5:$F$217,MATCH($A24,Controls!$A$5:$A$217,0),0)*B11)+(SUM(B26:B31))) -> 0 | C24: =((HLOOKUP(C$3,Controls!$A$5:$F$217,MATCH($A24,Controls!$A$5:$A$217,0),0)*C11)+(SUM(C26:C31))) -> 0 | D24: =((HLOOKUP(D$3,Controls!$A$5:$F$217,MATCH($A24,Controls!$A$5:$A$217,0),0)*D11)+(SUM(D26:D31))) -> 0 | E24: =((HLOOKUP(E$3,Controls!$A$5:$F$217,MATCH($A24,Controls!$A$5:$A$217,0),0)*E11)+(SUM(E26:E31))) -> 0 | F24: =((HLOOKUP(F$3,Controls!$A$5:$F$217,MATCH($A24,Controls!$A$5:$A$217,0),0)*F11)+(SUM(F26:F31))) -> 0 | G24: =((HLOOKUP(G$3,Controls!$A$5:$F$217,MATCH($A24,Controls!$A$5:$A$217,0),0)*G11)+(SUM(G26:G31))) -> 0 | H24: =((HLOOKUP(H$3,Controls!$A$5:$F$217,MATCH($A24,Controls!$A$5:$A$217,0),0)*H11)+(SUM(H26:H31))) -> 0 | I24: =((HLOOKUP(I$3,Controls!$A$5:$F$217,MATCH($A24,Controls!$A$5:$A$217,0),0)*I11)+(SUM(I26:I31))) -> 0 | ... BI24: =((HLOOKUP(BI$3,Controls!$A$5:$F$217,MATCH($A24,Controls!$A$5:$A$217,0),0)*BI11)+(SUM(BI26:BI31))) -> 0
A26: Additional Revenue/Contract | B26: 0 | C26: 0 | D26: 0 | E26: 0 | F26: 0 | G26: 0 | H26: 0 | I26: 0 | J26: 0 | K26: 0 | L26: 0 | M26: 0 | N26: 0 | O26: 0 | P26: 0 | Q26: 0 | R26: 0 | S26: 0 | T26: 0 | U26: 0 | V26: 0 | W26: 0 | X26: 0 | Y26: 0 | Z26: 0 | AA26: 0 | AB26: 0 | AC26: 0 | AD26: 0 | AE26: 0 | AF26: 0 | AG26: 0 | AH26: 0 | AI26: 0 | AJ26: 0 | AK26: 0 | AL26: 0 | AM26: 0 | AN26: 0 | AO26: 0 | AP26: 0 | AQ26: 0 | AR26: 0 | AS26: 0 | AT26: 0 | AU26: 0 | AV26: 0 | AW26: 0 | AX26: 0 | AY26: 0 | AZ26: 0 | BA26: 0 | BB26: 0 | BC26: 0 | BD26: 0 | BE26: 0 | BF26: 0 | BG26: 0 | BH26: 0 | BI26: 0
A27: Additional Revenue/Contract | B27: 0 | C27: 0 | D27: 0 | E27: 0 | F27: 0 | G27: 0 | H27: 0 | I27: 0 | J27: 0 | K27: 0 | L27: 0 | M27: 0 | N27: 0 | O27: 0 | P27: 0 | Q27: 0 | R27: 0 | S27: 0 | T27: 0 | U27: 0 | V27: 0 | W27: 0 | X27: 0 | Y27: 0 | Z27: 0 | AA27: 0 | AB27: 0 | AC27: 0 | AD27: 0 | AE27: 0 | AF27: 0 | AG27: 0 | AH27: 0 | AI27: 0 | AJ27: 0 | AK27: 0 | AL27: 0 | AM27: 0 | AN27: 0 | AO27: 0 | AP27: 0 | AQ27: 0 | AR27: 0 | AS27: 0 | AT27: 0 | AU27: 0 | AV27: 0 | AW27: 0 | AX27: 0 | AY27: 0 | AZ27: 0 | BA27: 0 | BB27: 0 | BC27: 0 | BD27: 0 | BE27: 0 | BF27: 0 | BG27: 0 | BH27: 0 | BI27: 0
A28: Additional Revenue/Contract | B28: 0 | C28: 0 | D28: 0 | E28: 0 | F28: 0 | G28: 0 | H28: 0 | I28: 0 | J28: 0 | K28: 0 | L28: 0 | M28: 0 | N28: 0 | O28: 0 | P28: 0 | Q28: 0 | R28: 0 | S28: 0 | T28: 0 | U28: 0 | V28: 0 | W28: 0 | X28: 0 | Y28: 0 | Z28: 0 | AA28: 0 | AB28: 0 | AC28: 0 | AD28: 0 | AE28: 0 | AF28: 0 | AG28: 0 | AH28: 0 | AI28: 0 | AJ28: 0 | AK28: 0 | AL28: 0 | AM28: 0 | AN28: 0 | AO28: 0 | AP28: 0 | AQ28: 0 | AR28: 0 | AS28: 0 | AT28: 0 | AU28: 0 | AV28: 0 | AW28: 0 | AX28: 0 | AY28: 0 | AZ28: 0 | BA28: 0 | BB28: 0 | BC28: 0 | BD28: 0 | BE28: 0 | BF28: 0 | BG28: 0 | BH28: 0 | BI28: 0
A29: Additional Revenue/Contract | B29: 0 | C29: 0 | D29: 0 | E29: 0 | F29: 0 | G29: 0 | H29: 0 | I29: 0 | J29: 0 | K29: 0 | L29: 0 | M29: 0 | N29: 0 | O29: 0 | P29: 0 | Q29: 0 | R29: 0 | S29: 0 | T29: 0 | U29: 0 | V29: 0 | W29: 0 | X29: 0 | Y29: 0 | Z29: 0 | AA29: 0 | AB29: 0 | AC29: 0 | AD29: 0 | AE29: 0 | AF29: 0 | AG29: 0 | AH29: 0 | AI29: 0 | AJ29: 0 | AK29: 0 | AL29: 0 | AM29: 0 | AN29: 0 | AO29: 0 | AP29: 0 | AQ29: 0 | AR29: 0 | AS29: 0 | AT29: 0 | AU29: 0 | AV29: 0 | AW29: 0 | AX29: 0 | AY29: 0 | AZ29: 0 | BA29: 0 | BB29: 0 | BC29: 0 | BD29: 0 | BE29: 0 | BF29: 0 | BG29: 0 | BH29: 0 | BI29: 0
A30: Additional Revenue/Contract | B30: 0 | C30: 0 | D30: 0 | E30: 0 | F30: 0 | G30: 0 | H30: 0 | I30: 0 | J30: 0 | K30: 0 | L30: 0 | M30: 0 | N30: 0 | O30: 0 | P30: 0 | Q30: 0 | R30: 0 | S30: 0 | T30: 0 | U30: 0 | V30: 0 | W30: 0 | X30: 0 | Y30: 0 | Z30: 0 | AA30: 0 | AB30: 0 | AC30: 0 | AD30: 0 | AE30: 0 | AF30: 0 | AG30: 0 | AH30: 0 | AI30: 0 | AJ30: 0 | AK30: 0 | AL30: 0 | AM30: 0 | AN30: 0 | AO30: 0 | AP30: 0 | AQ30: 0 | AR30: 0 | AS30: 0 | AT30: 0 | AU30: 0 | AV30: 0 | AW30: 0 | AX30: 0 | AY30: 0 | AZ30: 0 | BA30: 0 | BB30: 0 | BC30: 0 | BD30: 0 | BE30: 0 | BF30: 0 | BG30: 0 | BH30: 0 | BI30: 0
A31: Additional Revenue/Contract | B31: 0 | C31: 0 | D31: 0 | E31: 0 | F31: 0 | G31: 0 | H31: 0 | I31: 0 | J31: 0 | K31: 0 | L31: 0 | M31: 0 | N31: 0 | O31: 0 | P31: 0 | Q31: 0 | R31: 0 | S31: 0 | T31: 0 | U31: 0 | V31: 0 | W31: 0 | X31: 0 | Y31: 0 | Z31: 0 | AA31: 0 | AB31: 0 | AC31: 0 | AD31: 0 | AE31: 0 | AF31: 0 | AG31: 0 | AH31: 0 | AI31: 0 | AJ31: 0 | AK31: 0 | AL31: 0 | AM31: 0 | AN31: 0 | AO31: 0 | AP31: 0 | AQ31: 0 | AR31: 0 | AS31: 0 | AT31: 0 | AU31: 0 | AV31: 0 | AW31: 0 | AX31: 0 | AY31: 0 | AZ31: 0 | BA31: 0 | BB31: 0 | BC31: 0 | BD31: 0 | BE31: 0 | BF31: 0 | BG31: 0 | BH31: 0 | BI31: 0
A33: Revenue from BLK4 360kg Launcher | B33: =B15+B24 -> 0 | C33: =C15+C24 -> 0 | D33: =D15+D24 -> 0 | E33: =E15+E24 -> 0 | F33: =F15+F24 -> 0 | G33: =G15+G24 -> 0 | H33: =H15+H24 -> 0 | I33: =I15+I24 -> 0 | ... BI33: =BI15+BI24 -> 6833332.8
A35: SYSTEMS SALES - CONTRACTING -
A37: Propulsion System Sales | B37: 0 | C37: 0 | D37: 0 | E37: 0 | F37: 0 | G37: 0 | H37: 0 | I37: 0 | J37: 0 | K37: 0 | L37: 0 | M37: 0 | N37: 0 | O37: 0 | P37: 0 | Q37: 0 | R37: 0 | S37: 0 | T37: 0 | U37: 0 | V37: 1 | W37: 0 | X37: 0 | Y37: 1 | Z37: 0 | AA37: 0 | AB37: 1 | AC37: 0 | AD37: 0 | AE37: 0 | AF37: 0 | AG37: 0 | AH37: 0 | AI37: 0 | AJ37: 0 | AK37: 1 | AL37: 0 | AM37: 1 | AN37: 0 | AO37: 1 | AP37: 0 | AQ37: 0 | AR37: 1 | AS37: 0 | AT37: 0 | AU37: 1 | AV37: 0 | AW37: 0 | AX37: 1 | AY37: 0 | AZ37: 0 | BA37: 1 | BB37: 0 | BC37: 0 | BD37: 1 | BE37: 0 | BF37: 0 | BG37: 1 | BH37: 0 | BI37: 1
A39: Suborbital Hover Vehicle-Reusable Rocket- DoD /DoW | B39: 0 | C39: 0 | D39: 250000 | E39: 100000 | F39: 250000 | G39: 250000 | H39: 250000 | I39: 250000 | J39: 150000 | K39: 150000 | L39: 150000 | M39: 100000 | N39: 0 | O39: 0 | P39: 0 | Q39: 0 | R39: 0 | S39: 0 | T39: 0 | U39: 0 | V39: 0 | W39: 0 | X39: 0 | Y39: 0 | Z39: 0 | AA39: 0 | AB39: 0 | AC39: 0 | AD39: 0 | AE39: 0 | AF39: 0 | AG39: 0 | AH39: 0 | AI39: 0 | AJ39: 0 | AK39: 0 | AL39: 0 | AM39: 0 | AN39: 0 | AO39: 0 | AP39: 0 | AQ39: 0 | AR39: 0 | AS39: 0 | AT39: 0 | AU39: 0 | AV39: 0 | AW39: 0 | AX39: 0 | AY39: 0 | AZ39: 0 | BA39: 0 | BB39: 0 | BC39: 0 | BD39: 0 | BE39: 0 | BF39: 0 | BG39: 0 | BH39: 0 | BI39: 0
A40: Scorpius Space Corp — Tank Manufacturing & Related Sales (Calendar Year) | B40: 0 | C40: 0 | D40: 0 | E40: 0 | F40: 0 | G40: 0 | H40: 150000 | I40: 150000 | J40: 150000 | K40: 150000 | L40: 150000 | M40: 150000 | N40: 291666.67 | O40: 291666.67 | P40: 291666.67 | Q40: 291666.67 | R40: 291666.67 | S40: 291666.67 | T40: 291666.67 | U40: 291666.67 | V40: 291666.67 | W40: 291666.67 | X40: 291666.67 | Y40: 291666.67 | Z40: 291666.67 | AA40: 291666.67 | AB40: 291666.67 | AC40: 291666.67 | AD40: 291666.67 | AE40: 291666.67 | AF40: 583333.33 | AG40: 583333.33 | AH40: 583333.33 | AI40: 583333.33 | AJ40: 583333.33 | AK40: 583333.33 | AL40: 583333.33 | AM40: 583333.33 | AN40: 583333.33 | AO40: 583333.33 | AP40: 583333.33 | AQ40: 583333.33 | AR40: 1166666.7 | AS40: 1166666.7 | AT40: 1166666.7 | AU40: 1166666.7 | AV40: 1166666.7 | AW40: 1166666.7 | AX40: 1166666.7 | AY40: 1166666.7 | AZ40: 1166666.7 | BA40: 1166666.7 | BB40: 1166666.7 | BC40: 1166666.7 | BD40: 2333333.3 | BE40: 2333333.3 | BF40: 2333333.3 | BG40: 2333333.3 | BH40: 2333333.3 | BI40: 2333333.3
A41: entX LSA — Project Lazarus RHU Flight Demo (BLK3.1) | B41: 0 | C41: 0 | D41: 0 | E41: 0 | F41: 0 | G41: 250000 | H41: 0 | I41: 0 | J41: 0 | K41: 0 | L41: 82000 | M41: 328000 | N41: 143000 | O41: 143000 | P41: 144000 | Q41: 0 | R41: 0 | S41: 0 | T41: 0 | U41: 0 | V41: 0 | W41: 0 | X41: 0 | Y41: 0 | Z41: 0 | AA41: 0 | AB41: 0 | AC41: 0 | AD41: 0 | AE41: 0 | AF41: 0 | AG41: 0 | AH41: 0 | AI41: 0 | AJ41: 0 | AK41: 0 | AL41: 0 | AM41: 0 | AN41: 0 | AO41: 0 | AP41: 0 | AQ41: 0 | AR41: 0 | AS41: 0 | AT41: 0 | AU41: 0 | AV41: 0 | AW41: 0 | AX41: 0 | AY41: 0 | AZ41: 0 | BA41: 0 | BB41: 0 | BC41: 0 | BD41: 0 | BE41: 0 | BF41: 0 | BG41: 0 | BH41: 0 | BI41: 0
A42: TACFI — RDRE Development Program ($2M DoD + $2M Match) | B42: 0 | C42: 0 | D42: 0 | E42: 0 | F42: 0 | G42: 0 | H42: 0 | I42: 0 | J42: 0 | K42: 0 | L42: 0 | M42: 0 | N42: 0 | O42: 0 | P42: 0 | Q42: 222222.22 | R42: 222222.22 | S42: 222222.22 | T42: 222222.22 | U42: 222222.22 | V42: 222222.22 | W42: 222222.22 | X42: 222222.22 | Y42: 222222.22 | Z42: 222222.22 | AA42: 222222.22 | AB42: 222222.22 | AC42: 222222.22 | AD42: 222222.22 | AE42: 222222.22 | AF42: 222222.22 | AG42: 222222.22 | AH42: 222222.22 | AI42: 0 | AJ42: 0 | AK42: 0 | AL42: 0 | AM42: 0 | AN42: 0 | AO42: 0 | AP42: 0 | AQ42: 0 | AR42: 0 | AS42: 0 | AT42: 0 | AU42: 0 | AV42: 0 | AW42: 0 | AX42: 0 | AY42: 0 | AZ42: 0 | BA42: 0 | BB42: 0 | BC42: 0 | BD42: 0 | BE42: 0 | BF42: 0 | BG42: 0 | BH42: 0 | BI42: 0
A43: STRATFI — RDRE Operational Engine Program ($30M over 36 months) | B43: 0 | C43: 0 | D43: 0 | E43: 0 | F43: 0 | G43: 0 | H43: 0 | I43: 0 | J43: 0 | K43: 0 | L43: 0 | M43: 0 | N43: 0 | O43: 0 | P43: 0 | Q43: 0 | R43: 0 | S43: 0 | T43: 0 | U43: 0 | V43: 0 | W43: 0 | X43: 0 | Y43: 0 | Z43: 0 | AA43: 0 | AB43: 0 | AC43: 0 | AD43: 0 | AE43: 0 | AF43: 0 | AG43: 0 | AH43: 0 | AI43: 833333.33 | AJ43: 833333.33 | AK43: 833333.33 | AL43: 833333.33 | AM43: 833333.33 | AN43: 833333.33 | AO43: 833333.33 | AP43: 833333.33 | AQ43: 833333.33 | AR43: 833333.33 | AS43: 833333.33 | AT43: 833333.33 | AU43: 833333.33 | AV43: 833333.33 | AW43: 833333.33 | AX43: 833333.33 | AY43: 833333.33 | AZ43: 833333.33 | BA43: 833333.33 | BB43: 833333.33 | BC43: 833333.33 | BD43: 833333.33 | BE43: 833333.33 | BF43: 833333.33 | BG43: 833333.33 | BH43: 833333.33 | BI43: 833333.33
A44: Note: STRATFI remaining 9 months ($7.5M) in FY2031 not shown | B44: 0 | C44: 0 | D44: 0 | E44: 0 | F44: 0 | G44: 0 | H44: 0 | I44: 0 | J44: 0 | K44: 0 | L44: 0 | M44: 0 | N44: 0 | O44: 0 | P44: 0 | Q44: 0 | R44: 0 | S44: 0 | T44: 0 | U44: 0 | V44: 0 | W44: 0 | X44: 0 | Y44: 0 | Z44: 0 | AA44: 0 | AB44: 0 | AC44: 0 | AD44: 0 | AE44: 0 | AF44: 0 | AG44: 0 | AH44: 0 | AI44: 0 | AJ44: 0 | AK44: 0 | AL44: 0 | AM44: 0 | AN44: 0 | AO44: 0 | AP44: 0 | AQ44: 0 | AR44: 0 | AS44: 0 | AT44: 0 | AU44: 0 | AV44: 0 | AW44: 0 | AX44: 0 | AY44: 0 | AZ44: 0 | BA44: 0 | BB44: 0 | BC44: 0 | BD44: 0 | BE44: 0 | BF44: 0 | BG44: 0 | BH44: 0 | BI44: 0
A46: Revenue from Propulsion System Sales | B46: =((HLOOKUP(B$3,Controls!$A$5:$F$217,MATCH(Controls!$A17,Controls!$A$5:$A$217,0),0)*B37))+(SUM(B39:B44)) -> 0 | C46: =((HLOOKUP(C$3,Controls!$A$5:$F$217,MATCH(Controls!$A17,Controls!$A$5:$A$217,0),0)*C37))+(SUM(C39:C44)) -> 0 | D46: =((HLOOKUP(D$3,Controls!$A$5:$F$217,MATCH(Controls!$A17,Controls!$A$5:$A$217,0),0)*D37))+(SUM(D39:D44)) -> 250000 | E46: =((HLOOKUP(E$3,Controls!$A$5:$F$217,MATCH(Controls!$A17,Controls!$A$5:$A$217,0),0)*E37))+(SUM(E39:E44)) -> 100000 | F46: =((HLOOKUP(F$3,Controls!$A$5:$F$217,MATCH(Controls!$A17,Controls!$A$5:$A$217,0),0)*F37))+(SUM(F39:F44)) -> 250000 | G46: =((HLOOKUP(G$3,Controls!$A$5:$F$217,MATCH(Controls!$A17,Controls!$A$5:$A$217,0),0)*G37))+(SUM(G39:G44)) -> 500000 | H46: =((HLOOKUP(H$3,Controls!$A$5:$F$217,MATCH(Controls!$A17,Controls!$A$5:$A$217,0),0)*H37))+(SUM(H39:H44)) -> 400000 | I46: =((HLOOKUP(I$3,Controls!$A$5:$F$217,MATCH(Controls!$A17,Controls!$A$5:$A$217,0),0)*I37))+(SUM(I39:I44)) -> 400000 | ... BI46: =((HLOOKUP(BI$3,Controls!$A$5:$F$217,MATCH(Controls!$A17,Controls!$A$5:$A$217,0),0)*BI37))+(SUM(BI39:BI44)) -> 3416666.7
A48: EXOS US BLK4 Wet Lease Launches
A50: EXOS US BLK4 Wet Lease Launches | B50: 0 | C50: 0 | D50: 0 | E50: 0 | F50: 0 | G50: 0 | H50: 0 | I50: 0 | J50: 0 | K50: 0 | L50: 0 | M50: 0 | N50: 0 | O50: 0 | P50: 0 | Q50: 0 | R50: 0 | S50: 0 | T50: 0 | U50: 0 | V50: 0 | W50: 0 | X50: 0 | Y50: 0 | Z50: 0 | AA50: 0 | AB50: 0 | AC50: 0 | AD50: 0 | AE50: 0 | AF50: 0 | AG50: 0 | AH50: 0 | AI50: 0 | AJ50: 0 | AK50: 0 | AL50: 0 | AM50: 0 | AN50: 0 | AO50: 0 | AP50: 0 | AQ50: 0 | AR50: 0 | AS50: 0 | AT50: 0 | AU50: 0 | AV50: 0 | AW50: 0 | AX50: 0 | AY50: 0 | AZ50: 0 | BA50: 0 | BB50: 0 | BC50: 0 | BD50: 0 | BE50: 0 | BF50: 0 | BG50: 0 | BH50: 0 | BI50: 0
A52: Recurring Orders | B52: 0 | C52: 0 | D52: 0 | E52: 0 | F52: 0 | G52: 0 | H52: 0 | I52: 0 | J52: 0 | K52: 0 | L52: 0 | M52: 0 | N52: 0 | O52: 0 | P52: 0 | Q52: 0 | R52: 0 | S52: 0 | T52: 0 | U52: 0 | V52: 0 | W52: 0 | X52: 0 | Y52: 0 | Z52: 0 | AA52: 0 | AB52: 0 | AC52: 0 | AD52: 0 | AE52: 0 | AF52: 0 | AG52: 0 | AH52: 0 | AI52: 0 | AJ52: 0 | AK52: 0 | AL52: 0 | AM52: 0.2 | AN52: 0 | AO52: 0 | AP52: 0 | AQ52: 0 | AR52: 0 | AS52: 0 | AT52: 0 | AU52: 0 | AV52: 0 | AW52: 0 | AX52: 0 | AY52: 0 | AZ52: 0.125 | BA52: 0 | BB52: 0.125 | BC52: 0 | BD52: 0.25 | BE52: 0 | BF52: 0 | BG52: 0 | BH52: 0.3 | BI52: 0
A54: NASA Flight Opportunities IDIQ — Suborbital Research Services ($1M/flight × 2 flights/qtr) | B54: 0 | C54: 0 | D54: 0 | E54: 0 | F54: 0 | G54: 0 | H54: 0 | I54: 0 | J54: 0 | K54: 0 | L54: 0 | M54: 0 | N54: 0 | O54: 0 | P54: 0 | Q54: 0 | R54: 0 | S54: 0 | T54: 0 | U54: 0 | V54: 0 | W54: 0 | X54: 0 | Y54: 0 | Z54: 0 | AA54: 0 | AB54: 0 | AC54: 0 | AD54: 0 | AE54: 0 | AF54: 0 | AG54: 0 | AH54: 0 | AI54: 0 | AJ54: 0 | AK54: 0 | AL54: 0 | AM54: 0 | AN54: 0 | AO54: 0 | AP54: 0 | AQ54: 0 | AR54: 0 | AS54: 0 | AT54: 0 | AU54: 0 | AV54: 0 | AW54: 0 | AX54: 0 | AY54: 0 | AZ54: 0 | BA54: 0 | BB54: 0 | BC54: 0 | BD54: 0 | BE54: 0 | BF54: 0 | BG54: 0 | BH54: 0 | BI54: 0
A55: Second BLK3 Flight — Commercial Payload Revenue ($750K) | B55: 0 | C55: 0 | D55: 0 | E55: 0 | F55: 0 | G55: 0 | H55: 0 | I55: 0 | J55: 0 | K55: 0 | L55: 0 | M55: 0 | N55: 0 | O55: 0 | P55: 0 | Q55: 0 | R55: 0 | S55: 0 | T55: 0 | U55: 0 | V55: 0 | W55: 0 | X55: 0 | Y55: 0 | Z55: 375000 | AA55: 375000 | AB55: 0 | AC55: 0 | AD55: 0 | AE55: 0 | AF55: 0 | AG55: 0 | AH55: 0 | AI55: 0 | AJ55: 0 | AK55: 0 | AL55: 0 | AM55: 0 | AN55: 0 | AO55: 0 | AP55: 0 | AQ55: 0 | AR55: 0 | AS55: 0 | AT55: 0 | AU55: 0 | AV55: 0 | AW55: 0 | AX55: 0 | AY55: 0 | AZ55: 0 | BA55: 0 | BB55: 0 | BC55: 0 | BD55: 0 | BE55: 0 | BF55: 0 | BG55: 0 | BH55: 0 | BI55: 0
A56: ANNUAL REVENUE TRAJECTORY — Projections start March 2026, scaling to $120M by CY2030 | B56: 0 | C56: 0 | D56: 0 | E56: 0 | F56: 0 | G56: 0 | H56: 0 | I56: 0 | J56: 0 | K56: 0 | L56: 0 | M56: 0 | N56: 0 | O56: 0 | P56: 0 | Q56: 0 | R56: 0 | S56: 0 | T56: 0 | U56: 0 | V56: 0 | W56: 0 | X56: 0 | Y56: 0 | Z56: 0 | AA56: 0 | AB56: 0 | AC56: 0 | AD56: 0 | AE56: 0 | AF56: 0 | AG56: 0 | AH56: 0 | AI56: 0 | AJ56: 0 | AK56: 0 | AL56: 0 | AM56: 0 | AN56: 0 | AO56: 0 | AP56: 0 | AQ56: 0 | AR56: 0 | AS56: 0 | AT56: 0 | AU56: 0 | AV56: 0 | AW56: 0 | AX56: 0 | AY56: 0 | AZ56: 0 | BA56: 0 | BB56: 0 | BC56: 0 | BD56: 0 | BE56: 0 | BF56: 0 | BG56: 0 | BH56: 0 | BI56: 0
A57: CY2025 Actual: $1,550,000 (base year — 4 consecutive years of doubling) | B57: 0 | C57: 0 | D57: 0 | E57: 0 | F57: 0 | G57: 0 | H57: 0 | I57: 0 | J57: 0 | K57: 0 | L57: 0 | M57: 0 | N57: 0 | O57: 0 | P57: 0 | Q57: 0 | R57: 0 | S57: 0 | T57: 0 | U57: 0 | V57: 0 | W57: 0 | X57: 0 | Y57: 0 | Z57: 0 | AA57: 0 | AB57: 0 | AC57: 0 | AD57: 0 | AE57: 0 | AF57: 0 | AG57: 0 | AH57: 0 | AI57: 0 | AJ57: 0 | AK57: 0 | AL57: 0 | AM57: 0 | AN57: 0 | AO57: 0 | AP57: 0 | AQ57: 0 | AR57: 0 | AS57: 0 | AT57: 0 | AU57: 0 | AV57: 0 | AW57: 0 | AX57: 0 | AY57: 0 | AZ57: 0 | BA57: 0 | BB57: 0 | BC57: 0 | BD57: 0 | BE57: 0 | BF57: 0 | BG57: 0 | BH57: 0 | BI57: 0
...

Sheet Oper, Cap, Other Assum
B1: Series A Investment
B3: Assumptions | G3: M1 | H3: M2 | I3: M3 | J3: M4 | K3: M5 | L3: M6 | M3: M7 | N3: M8 | O3: M9 | P3: M10 | Q3: M11 | R3: M12 | S3: Annual
B5: General & Administrative Expenses
B7: Utilities | F7: Growth(y-o-y)
B8: Year 1 | F8: 0 | G8: 5000 | H8: 5000 | I8: 5000 | J8: 5000 | K8: 5000 | L8: 5000 | M8: 5000 | N8: 5000 | O8: 5000 | P8: 5000 | Q8: 5000 | R8: 5000 | S8: =SUM(G8:R8) -> 60000
B9: Year 2 | F9: 0.05 | G9: =R8+R8*F9 -> 5250 | H9: =G9 -> 5250 | I9: =H9 -> 5250 | J9: =I9 -> 5250 | K9: =J9 -> 5250 | L9: =K9 -> 5250 | M9: =L9 -> 5250 | N9: =M9 -> 5250 | O9: =N9 -> 5250 | ... R9: =Q9 -> 5250 | S9: =SUM(G9:R9) -> 63000
B10: Year 3 | F10: 0.05 | G10: =R9+R9*F10 -> 5512.5 | H10: =G10 -> 5512.5 | I10: =H10 -> 5512.5 | J10: =I10 -> 5512.5 | K10: =J10 -> 5512.5 | L10: =K10 -> 5512.5 | M10: =L10 -> 5512.5 | N10: =M10 -> 5512.5 | O10: =N10 -> 5512.5 | ... R10: =Q10 -> 5512.5 | S10: =SUM(G10:R10) -> 66150
B11: Year 4 | C11: Add manufacturing in Midland- Bldg by Midland EDC | F11: 0.05 | G11: =(R10+R10*F11)*4 -> 23152.5 | H11: =G11 -> 23152.5 | I11: =H11 -> 23152.5 | J11: =I11 -> 23152.5 | K11: =J11 -> 23152.5 | L11: =K11 -> 23152.5 | M11: =L11 -> 23152.5 | N11: =M11 -> 23152.5 | O11: =N11 -> 23152.5 | ... R11: =Q11 -> 23152.5 | S11: =SUM(G11:R11) -> 277830
B12: Year 5 | F12: 0.05 | G12: =R11+R11*F12 -> 24310.125 | H12: =G12 -> 24310.125 | I12: =H12 -> 24310.125 | J12: =I12 -> 24310.125 | K12: =J12 -> 24310.125 | L12: =K12 -> 24310.125 | M12: =L12 -> 24310.125 | N12: =M12 -> 24310.125 | O12: =N12 -> 24310.125 | ... R12: =Q12 -> 24310.125 | S12: =SUM(G12:R12) -> 291721.5
B14: Internet/Phone | F14: Growth(y-o-y)
B15: Year 1 | G15: 750 | H15: =G15 -> 750 | I15: =H15 -> 750 | J15: =I15 -> 750 | K15: =J15 -> 750 | L15: =K15 -> 750 | M15: =L15 -> 750 | N15: =M15 -> 750 | O15: =N15 -> 750 | ... R15: =Q15 -> 750 | S15: =SUM(G15:R15) -> 9000
B16: Year 2 | F16: 0.03 | G16: =R15*(1+$F16) -> 772.5 | H16: =G16 -> 772.5 | I16: =H16 -> 772.5 | J16: =I16 -> 772.5 | K16: =J16 -> 772.5 | L16: =K16 -> 772.5 | M16: =L16 -> 772.5 | N16: =M16 -> 772.5 | O16: =N16 -> 772.5 | ... R16: =Q16 -> 772.5 | S16: =SUM(G16:R16) -> 9270
B17: Year 3 | F17: 0.03 | G17: =R16*(1+$F17) -> 795.675 | H17: =G17 -> 795.675 | I17: =H17 -> 795.675 | J17: =I17 -> 795.675 | K17: =J17 -> 795.675 | L17: =K17 -> 795.675 | M17: =L17 -> 795.675 | N17: =M17 -> 795.675 | O17: =N17 -> 795.675 | ... R17: =Q17 -> 795.675 | S17: =SUM(G17:R17) -> 9548.1
B18: Year 4 | F18: 0.03 | G18: =(R17*(1+$F18))*2 -> 1639.0905 | H18: =G18 -> 1639.0905 | I18: =H18 -> 1639.0905 | J18: =I18 -> 1639.0905 | K18: =J18 -> 1639.0905 | L18: =K18 -> 1639.0905 | M18: =L18 -> 1639.0905 | N18: =M18 -> 1639.0905 | O18: =N18 -> 1639.0905 | ... R18: =Q18 -> 1639.0905 | S18: =SUM(G18:R18) -> 19669.086
B19: Year 5 | F19: 0.03 | G19: =R18*(1+$F19) -> 1688.2632 | H19: =G19 -> 1688.2632 | I19: =H19 -> 1688.2632 | J19: =I19 -> 1688.2632 | K19: =J19 -> 1688.2632 | L19: =K19 -> 1688.2632 | M19: =L19 -> 1688.2632 | N19: =M19 -> 1688.2632 | O19: =N19 -> 1688.2632 | ... R19: =Q19 -> 1688.2632 | S19: =SUM(G19:R19) -> 20259.159
B21: Insurance | F21: Growth(y-o-y)
B22: Year 1 | C22: Mission insurance accounted for as part of flight costs | G22: 3000 | H22: =G22 -> 3000 | I22: =H22 -> 3000 | J22: =I22 -> 3000 | K22: =J22 -> 3000 | L22: =K22 -> 3000 | M22: =L22 -> 3000 | N22: =M22 -> 3000 | O22: =N22*2 -> 6000 | P22: =O22 -> 6000 | Q22: =P22 -> 6000 | R22: =Q22 -> 6000 | S22: =SUM(G22:R22) -> 48000
B23: Year 2 | F23: 0.03 | G23: =R22*(1+$F23) -> 6180 | H23: 89430 | I23: 21000 | J23: 6000 | K23: 6000 | L23: 6000 | M23: 6000 | N23: 6000 | O23: 6000 | P23: 6000 | Q23: 6000 | R23: 6000 | S23: =SUM(G23:R23) -> 170610
B24: Year 3 | F24: 0.03 | G24: 12180 | H24: 194274 | I24: 31000 | J24: 6000 | K24: 6000 | L24: 6000 | M24: 6000 | N24: 6000 | O24: 6000 | P24: 6000 | Q24: 6000 | R24: 31000 | S24: =SUM(G24:R24) -> 316454
B25: Year 4 | F25: 0.03 | G25: 37930 | H25: 356947 | I25: 6000 | J25: 31000 | K25: 6000 | L25: 6000 | M25: 6000 | N25: 6000 | O25: 6000 | P25: 106000 | Q25: 6000 | R25: 106000 | S25: =SUM(G25:R25) -> 679877
B26: Year 5 | F26: 0.03 | G26: 140180 | H26: 706274 | I26: 6000 | J26: 106000 | K26: 6000 | L26: 6000 | M26: 6000 | N26: 6000 | O26: 6000 | P26: 106000 | Q26: 6000 | R26: 31000 | S26: =SUM(G26:R26) -> 1131454
B28: Professional Fees (consulting, legal, accounting, etc) | F28: Growth(y-o-y)
B29: Year 1 | G29: 3500 | H29: =G29 -> 3500 | I29: =H29 -> 3500 | J29: =I29 -> 3500 | K29: =J29 -> 3500 | L29: =K29 -> 3500 | M29: =L29 -> 3500 | N29: =M29 -> 3500 | O29: =N29 -> 3500 | ... R29: =Q29 -> 3500 | S29: =SUM(G29:R29) -> 42000
B30: Year 2 | F30: 0.03 | G30: =R29*(1+$F30) -> 3605 | H30: =G30 -> 3605 | I30: =H30 -> 3605 | J30: =I30 -> 3605 | K30: =J30 -> 3605 | L30: =K30 -> 3605 | M30: =L30 -> 3605 | N30: =M30 -> 3605 | O30: =N30 -> 3605 | ... R30: =Q30 -> 3605 | S30: =SUM(G30:R30) -> 43260
B31: Year 3 | F31: 0.03 | G31: =R30*(1+$F31) -> 3713.15 | H31: =G31 -> 3713.15 | I31: =H31 -> 3713.15 | J31: =I31 -> 3713.15 | K31: =J31 -> 3713.15 | L31: =K31 -> 3713.15 | M31: =L31 -> 3713.15 | N31: =M31 -> 3713.15 | O31: =N31 -> 3713.15 | ... R31: =Q31 -> 3713.15 | S31: =SUM(G31:R31) -> 44557.8
B32: Year 4 | F32: 0.03 | G32: =R31*(1+$F32) -> 3824.5445 | H32: =G32 -> 3824.5445 | I32: =H32 -> 3824.5445 | J32: =I32 -> 3824.5445 | K32: =J32 -> 3824.5445 | L32: =K32 -> 3824.5445 | M32: =L32 -> 3824.5445 | N32: =M32 -> 3824.5445 | O32: =N32 -> 3824.5445 | ... R32: =Q32 -> 3824.5445 | S32: =SUM(G32:R32) -> 45894.534
B33: Year 5 | F33: 0.03 | G33: =R32*(1+$F33) -> 3939.2808 | H33: =G33 -> 3939.2808 | I33: =H33 -> 3939.2808 | J33: =I33 -> 3939.2808 | K33: =J33 -> 3939.2808 | L33: =K33 -> 3939.2808 | M33: =L33 -> 3939.2808 | N33: =M33 -> 3939.2808 | O33: =N33 -> 3939.2808 | ... R33: =Q33 -> 3939.2808 | S33: =SUM(G33:R33) -> 47271.37 | T33: Torrence California Monthly lease Expense $33,000 plus personnel (included in Headcount)
F34: Buy 310 Wilmeth Basis | G34: 75000 sqft | H34: build out | I34: AC 75Ksf | J34: Insulation | K34: power | L34: Total for occ | M34: Credit | N34: Total | O34: Monthly rent NNN | P34: Monthly Taxes | Q34: Maintenance and power | R34: Total/month | T34: 75215.536
B35: Rent /Lease / Equipment/ Electricity | F35: Growth(y-o-y) | G35: office costs | H35: =20000*125 -> 2500000 | I35: =75000*8 -> 600000 | J35: =75000*3 -> 225000 | K35: 500000 | L35: =SUM(H35:K35) -> 3825000 | M35: =75000*8 -> 600000 | N35: =L35-M35 -> 3225000 | O35: =(7.75*75000)/12 -> 48437.5 | P35: =(3.25*75000)/12 -> 20312.5 | Q35: =((1*75000)/12)+6500 -> 12750 | R35: =SUM(O35:Q35) -> 81500
B36: Year 1 | G36: 40000 | H36: 40000 | I36: 40000 | J36: 40000 | K36: 40000 | L36: 40000 | M36: 40000 | N36: 40000 | O36: 40000 | P36: 40000 | Q36: 40000 | R36: 40000 | S36: =SUM(G36:R36) -> 480000
B37: Year 2 | F37: 0.04 | G37: =$R$36*(1+$F$37) -> 41600 | H37: =$R$36*(1+$F$37) -> 41600 | I37: =$R$36*(1+$F$37) -> 41600 | J37: =$R$36*(1+$F$37) -> 41600 | K37: =$R$36*(1+$F$37) -> 41600 | L37: =$R$36*(1+$F$37) -> 41600 | M37: =$R$36*(1+$F$37) -> 41600 | N37: =$R$36*(1+$F$37) -> 41600 | ... R37: =$R$36*(1+$F$37) -> 41600 | S37: =SUM(G37:R37) -> 499200
B38: Year 3 | F38: 0.04 | G38: =R37*(1+$F$37) -> 43264 | H38: =G38 -> 43264 | I38: =H38 -> 43264 | J38: =I38 -> 43264 | K38: =J38 -> 43264 | L38: =K38 -> 43264 | M38: =L38 -> 43264 | N38: =M38 -> 43264 | O38: =N38 -> 43264 | ... R38: =Q38 -> 43264 | S38: =SUM(G38:R38) -> 519168
B39: Year 4 | F39: 0.04 | G39: =R38*(1+$F$37)*2 -> 89989.12 | H39: =G39 -> 89989.12 | I39: =H39 -> 89989.12 | J39: =I39 -> 89989.12 | K39: =J39 -> 89989.12 | L39: =K39 -> 89989.12 | M39: =L39 -> 89989.12 | N39: =M39 -> 89989.12 | O39: =N39 -> 89989.12 | ... R39: =Q39 -> 89989.12 | S39: =SUM(G39:R39) -> 1079869.4
B40: Year 5 | F40: 0.04 | G40: =R39*(1+$F$37) -> 93588.685 | H40: =G40 -> 93588.685 | I40: =H40 -> 93588.685 | J40: =I40 -> 93588.685 | K40: =J40 -> 93588.685 | L40: =K40 -> 93588.685 | M40: =L40 -> 93588.685 | N40: =M40 -> 93588.685 | O40: =N40 -> 93588.685 | ... R40: =Q40 -> 93588.685 | S40: =SUM(G40:R40) -> 1123064.2
B42: Office Setup / Network / Computers / Software - Licensing | F42: Growth(y-o-y)
B43: Year 1 | G43: 5000 | H43: =G43 -> 5000 | I43: =H43 -> 5000 | J43: =I43 -> 5000 | K43: =J43 -> 5000 | L43: =K43 -> 5000 | M43: =L43 -> 5000 | N43: 10000 | O43: 10000 | P43: 5000 | Q43: 15000 | R43: 5000 | S43: =SUM(G43:R43) -> 80000
B44: Year 2 | F44: 0.03 | G44: 25000 | H44: 10000 | I44: 5000 | J44: 5000 | K44: 30000 | L44: 15000 | M44: 10000 | N44: 10000 | O44: 5000 | P44: 15000 | Q44: 5000 | R44: 30000 | S44: =SUM(G44:R44) -> 165000
B45: Year 3 | F45: 0.03 | G45: 30000 | H45: 35000 | I45: 0 | J45: 0 | K45: 0 | L45: 0 | M45: 5000 | N45: 5000 | O45: 5000 | P45: 5000 | Q45: 5000 | R45: 20000 | S45: =SUM(G45:R45) -> 110000
B46: Year 4 | F46: 0.03 | G46: 150000 | H46: 12640 | I46: 12640 | J46: 12640 | K46: 12640 | L46: 12640 | M46: 12640 | N46: 12640 | O46: 12640 | P46: 12640 | Q46: 12640 | R46: 12640 | S46: =SUM(G46:R46) -> 289040
B47: Year 5 | F47: 0.03 | G47: 15550 | H47: 15550 | I47: 15550 | J47: 15550 | K47: 15550 | L47: 15550 | M47: 15550 | N47: 15550 | O47: 15550 | P47: 15550 | Q47: 15550 | R47: 15550 | S47: =SUM(G47:R47) -> 186600
...

Sheet Expense Assumptions
A1: EXOS Aerospace
A2: Expense Assumptions Sheet | B2: =Controls!C1 -> July | C2: =TEXT(DATE(2000, MATCH(B2, {"January","February","March","April","May","June","July","August","September","October","November","December"}, 0) + 1, 1), "mmmm") -> August | D2: =TEXT(DATE(2000, MATCH(C2, {"January","February","March","April","May","June","July","August","September","October","November","December"}, 0) + 1, 1), "mmmm") -> September | E2: =TEXT(DATE(2000, MATCH(D2, {"January","February","March","April","May","June","July","August","September","October","November","December"}, 0) + 1, 1), "mmmm") -> October | F2: =TEXT(DATE(2000, MATCH(E2, {"January","February","March","April","May","June","July","August","September","October","November","December"}, 0) + 1, 1), "mmmm") -> November | G2: =TEXT(DATE(2000, MATCH(F2, {"January","February","March","April","May","June","July","August","September","October","November","December"}, 0) + 1, 1), "mmmm") -> December | H2: =TEXT(DATE(2000, MATCH(G2, {"January","February","March","April","May","June","July","August","September","October","November","December"}, 0) + 1, 1), "mmmm") -> January | I2: =TEXT(DATE(2000, MATCH(H2, {"January","February","March","April","May","June","July","August","September","October","November","December"}, 0) + 1, 1), "mmmm") -> February | J2: =TEXT(DATE(2000, MATCH(I2, {"January","February","March","April","May","June","July","August","September","October","November","December"}, 0) + 1, 1), "mmmm") -> March | ... BI2: =TEXT(DATE(2000, MATCH(BH2, {"January","February","March","April","May","June","July","August","September","October","November","December"}, 0) + 1, 1), "mmmm") -> June
A3: Amounts in USD | B3: 1 | C3: =IF(MOD(B4,B5) = 0,B3+1,B3) -> 1 | D3: =IF(MOD(C4,C5) = 0,C3+1,C3) -> 1 | E3: =IF(MOD(D4,D5) = 0,D3+1,D3) -> 1 | F3: =IF(MOD(E4,E5) = 0,E3+1,E3) -> 1 | G3: =IF(MOD(F4,F5) = 0,F3+1,F3) -> 1 | H3: =IF(MOD(G4,G5) = 0,G3+1,G3) -> 1 | I3: =IF(MOD(H4,H5) = 0,H3+1,H3) -> 1 | J3: =IF(MOD(I4,I5) = 0,I3+1,I3) -> 1 | ... BI3: =IF(MOD(BH4,BH5) = 0,BH3+1,BH3) -> 5
A4: Back To Index | B4: 1 | C4: =B4+1 -> 2 | D4: =C4+1 -> 3 | E4: =D4+1 -> 4 | F4: =E4+1 -> 5 | G4: =F4+1 -> 6 | H4: =G4+1 -> 7 | I4: =H4+1 -> 8 | J4: =I4+1 -> 9 | ... BI4: =BH4+1 -> 60
A5: Assumptions for the Monthly Period | B5: 12 | C5: 12 | D5: 12 | E5: 12 | F5: 12 | G5: 12 | H5: 12 | I5: 12 | J5: 12 | K5: 12 | L5: 12 | M5: 12 | N5: 12 | O5: 12 | P5: 12 | Q5: 12 | R5: 12 | S5: 12 | T5: 12 | U5: 12 | V5: 12 | W5: 12 | X5: 12 | Y5: 12 | Z5: 12 | AA5: 12 | AB5: 12 | AC5: 12 | AD5: 12 | AE5: 12 | AF5: 12 | AG5: 12 | AH5: 12 | AI5: 12 | AJ5: 12 | AK5: 12 | AL5: 12 | AM5: 12 | AN5: 12 | AO5: 12 | AP5: 12 | AQ5: 12 | AR5: 12 | AS5: 12 | AT5: 12 | AU5: 12 | AV5: 12 | AW5: 12 | AX5: 12 | AY5: 12 | AZ5: 12 | BA5: 12 | BB5: 12 | BC5: 12 | BD5: 12 | BE5: 12 | BF5: 12 | BG5: 12 | BH5: 12 | BI5: 12
A7: Cost of Sale (COS)
A9: BLK4 360kg LAUNCHER - COGS - Wet Lease | B9: =HLOOKUP(B$3,Controls!$A$5:$F$96,MATCH('Expense Assumptions'!$A9,Controls!$A$5:$A$96,0),0)*'Revenue Asumptions'!B9 -> 0 | C9: =HLOOKUP(C$3,Controls!$A$5:$F$96,MATCH('Expense Assumptions'!$A9,Controls!$A$5:$A$96,0),0)*'Revenue Asumptions'!C9 -> 0 | D9: =HLOOKUP(D$3,Controls!$A$5:$F$96,MATCH('Expense Assumptions'!$A9,Controls!$A$5:$A$96,0),0)*'Revenue Asumptions'!D9 -> 0 | E9: =HLOOKUP(E$3,Controls!$A$5:$F$96,MATCH('Expense Assumptions'!$A9,Controls!$A$5:$A$96,0),0)*'Revenue Asumptions'!E9 -> 0 | F9: =HLOOKUP(F$3,Controls!$A$5:$F$96,MATCH('Expense Assumptions'!$A9,Controls!$A$5:$A$96,0),0)*'Revenue Asumptions'!F9 -> 0 | G9: =HLOOKUP(G$3,Controls!$A$5:$F$96,MATCH('Expense Assumptions'!$A9,Controls!$A$5:$A$96,0),0)*'Revenue Asumptions'!G9 -> 0 | H9: =HLOOKUP(H$3,Controls!$A$5:$F$96,MATCH('Expense Assumptions'!$A9,Controls!$A$5:$A$96,0),0)*'Revenue Asumptions'!H9 -> 0 | I9: =HLOOKUP(I$3,Controls!$A$5:$F$96,MATCH('Expense Assumptions'!$A9,Controls!$A$5:$A$96,0),0)*'Revenue Asumptions'!I9 -> 0 | ... BI9: =HLOOKUP(BI$3,Controls!$A$5:$F$96,MATCH('Expense Assumptions'!$A9,Controls!$A$5:$A$96,0),0)*'Revenue Asumptions'!BI9 -> 0
A10: BLK4 360kg LAUNCHER - COGS - Vehicle Launch | B10: =HLOOKUP(B$3,Controls!$A$5:$F$96,MATCH('Expense Assumptions'!$A10,Controls!$A$5:$A$96,0),0)*'Revenue Asumptions'!B11 -> 0 | C10: =HLOOKUP(C$3,Controls!$A$5:$F$96,MATCH('Expense Assumptions'!$A10,Controls!$A$5:$A$96,0),0)*'Revenue Asumptions'!C11 -> 0 | D10: =HLOOKUP(D$3,Controls!$A$5:$F$96,MATCH('Expense Assumptions'!$A10,Controls!$A$5:$A$96,0),0)*'Revenue Asumptions'!D11 -> 0 | E10: =HLOOKUP(E$3,Controls!$A$5:$F$96,MATCH('Expense Assumptions'!$A10,Controls!$A$5:$A$96,0),0)*'Revenue Asumptions'!E11 -> 0 | F10: =HLOOKUP(F$3,Controls!$A$5:$F$96,MATCH('Expense Assumptions'!$A10,Controls!$A$5:$A$96,0),0)*'Revenue Asumptions'!F11 -> 0 | G10: =HLOOKUP(G$3,Controls!$A$5:$F$96,MATCH('Expense Assumptions'!$A10,Controls!$A$5:$A$96,0),0)*'Revenue Asumptions'!G11 -> 0 | H10: =HLOOKUP(H$3,Controls!$A$5:$F$96,MATCH('Expense Assumptions'!$A10,Controls!$A$5:$A$96,0),0)*'Revenue Asumptions'!H11 -> 0 | I10: =HLOOKUP(I$3,Controls!$A$5:$F$96,MATCH('Expense Assumptions'!$A10,Controls!$A$5:$A$96,0),0)*'Revenue Asumptions'!I11 -> 0 | ... BI10: =HLOOKUP(BI$3,Controls!$A$5:$F$96,MATCH('Expense Assumptions'!$A10,Controls!$A$5:$A$96,0),0)*'Revenue Asumptions'!BI11 -> 0
A11: PROPULSION SYSTEM SALES 5K 20K DESIGNS WITH TRIFDYNE PRESS - COGS | B11: =HLOOKUP(B$3,Controls!$A$5:$F$96,MATCH('Expense Assumptions'!$A11,Controls!$A$5:$A$96,0),0)*'Revenue Asumptions'!B46 -> 0 | C11: =HLOOKUP(C$3,Controls!$A$5:$F$96,MATCH('Expense Assumptions'!$A11,Controls!$A$5:$A$96,0),0)*'Revenue Asumptions'!C46 -> 0 | D11: =HLOOKUP(D$3,Controls!$A$5:$F$96,MATCH('Expense Assumptions'!$A11,Controls!$A$5:$A$96,0),0)*'Revenue Asumptions'!D46 -> 125000 | E11: =HLOOKUP(E$3,Controls!$A$5:$F$96,MATCH('Expense Assumptions'!$A11,Controls!$A$5:$A$96,0),0)*'Revenue Asumptions'!E46 -> 50000 | F11: =HLOOKUP(F$3,Controls!$A$5:$F$96,MATCH('Expense Assumptions'!$A11,Controls!$A$5:$A$96,0),0)*'Revenue Asumptions'!F46 -> 125000 | G11: =HLOOKUP(G$3,Controls!$A$5:$F$96,MATCH('Expense Assumptions'!$A11,Controls!$A$5:$A$96,0),0)*'Revenue Asumptions'!G46 -> 250000 | H11: =HLOOKUP(H$3,Controls!$A$5:$F$96,MATCH('Expense Assumptions'!$A11,Controls!$A$5:$A$96,0),0)*'Revenue Asumptions'!H46 -> 200000 | I11: =HLOOKUP(I$3,Controls!$A$5:$F$96,MATCH('Expense Assumptions'!$A11,Controls!$A$5:$A$96,0),0)*'Revenue Asumptions'!I46 -> 200000 | ... BI11: =HLOOKUP(BI$3,Controls!$A$5:$F$96,MATCH('Expense Assumptions'!$A11,Controls!$A$5:$A$96,0),0)*'Revenue Asumptions'!BI46 -> 1708333.3
A12: EXOS US BLK4 Wet Lease Launches - COGS | B12: =HLOOKUP(B$3,Controls!$A$5:$F$96,MATCH('Expense Assumptions'!$A12,Controls!$A$5:$A$96,0),0)*'Revenue Asumptions'!B61 -> 0 | C12: =HLOOKUP(C$3,Controls!$A$5:$F$96,MATCH('Expense Assumptions'!$A12,Controls!$A$5:$A$96,0),0)*'Revenue Asumptions'!C61 -> 0 | D12: =HLOOKUP(D$3,Controls!$A$5:$F$96,MATCH('Expense Assumptions'!$A12,Controls!$A$5:$A$96,0),0)*'Revenue Asumptions'!D61 -> 0 | E12: =HLOOKUP(E$3,Controls!$A$5:$F$96,MATCH('Expense Assumptions'!$A12,Controls!$A$5:$A$96,0),0)*'Revenue Asumptions'!E61 -> 0 | F12: =HLOOKUP(F$3,Controls!$A$5:$F$96,MATCH('Expense Assumptions'!$A12,Controls!$A$5:$A$96,0),0)*'Revenue Asumptions'!F61 -> 0 | G12: =HLOOKUP(G$3,Controls!$A$5:$F$96,MATCH('Expense Assumptions'!$A12,Controls!$A$5:$A$96,0),0)*'Revenue Asumptions'!G61 -> 0 | H12: =HLOOKUP(H$3,Controls!$A$5:$F$96,MATCH('Expense Assumptions'!$A12,Controls!$A$5:$A$96,0),0)*'Revenue Asumptions'!H61 -> 0 | I12: =HLOOKUP(I$3,Controls!$A$5:$F$96,MATCH('Expense Assumptions'!$A12,Controls!$A$5:$A$96,0),0)*'Revenue Asumptions'!I61 -> 0 | ... BI12: =HLOOKUP(BI$3,Controls!$A$5:$F$96,MATCH('Expense Assumptions'!$A12,Controls!$A$5:$A$96,0),0)*'Revenue Asumptions'!BI61 -> 0
A13: ='Revenue Asumptions'!A63 -> NOTE: $10M Series A enables this trajectory. Dual listing: Euronext Dublin (immediate) + TXSE (Year 2) | B13: =HLOOKUP(B$3,Controls!$A$5:$F$96,MATCH('Expense Assumptions'!$A13,Controls!$A$5:$A$96,0),0)*'Revenue Asumptions'!B76 -> #N/A | C13: =HLOOKUP(C$3,Controls!$A$5:$F$96,MATCH('Expense Assumptions'!$A13,Controls!$A$5:$A$96,0),0)*'Revenue Asumptions'!C76 -> #N/A | D13: =HLOOKUP(D$3,Controls!$A$5:$F$96,MATCH('Expense Assumptions'!$A13,Controls!$A$5:$A$96,0),0)*'Revenue Asumptions'!D76 -> #N/A | E13: =HLOOKUP(E$3,Controls!$A$5:$F$96,MATCH('Expense Assumptions'!$A13,Controls!$A$5:$A$96,0),0)*'Revenue Asumptions'!E76 -> #N/A | F13: =HLOOKUP(F$3,Controls!$A$5:$F$96,MATCH('Expense Assumptions'!$A13,Controls!$A$5:$A$96,0),0)*'Revenue Asumptions'!F76 -> #N/A | G13: =HLOOKUP(G$3,Controls!$A$5:$F$96,MATCH('Expense Assumptions'!$A13,Controls!$A$5:$A$96,0),0)*'Revenue Asumptions'!G76 -> #N/A | H13: =HLOOKUP(H$3,Controls!$A$5:$F$96,MATCH('Expense Assumptions'!$A13,Controls!$A$5:$A$96,0),0)*'Revenue Asumptions'!H76 -> #N/A | I13: =HLOOKUP(I$3,Controls!$A$5:$F$96,MATCH('Expense Assumptions'!$A13,Controls!$A$5:$A$96,0),0)*'Revenue Asumptions'!I76 -> #N/A | ... BI13: =HLOOKUP(BI$3,Controls!$A$5:$F$96,MATCH('Expense Assumptions'!$A13,Controls!$A$5:$A$96,0),0)*'Revenue Asumptions'!BI76 -> #N/A
A14: Scorpius Space Corp Tank Manufacture - COGS | B14: =HLOOKUP(B$3,Controls!$A$5:$F$96,MATCH('Expense Assumptions'!$A14,Controls!$A$5:$A$96,0),0)*('Revenue Asumptions'!B89) -> 92960 | C14: =HLOOKUP(C$3,Controls!$A$5:$F$96,MATCH('Expense Assumptions'!$A14,Controls!$A$5:$A$96,0),0)*('Revenue Asumptions'!C89) -> 47355 | D14: =HLOOKUP(D$3,Controls!$A$5:$F$96,MATCH('Expense Assumptions'!$A14,Controls!$A$5:$A$96,0),0)*('Revenue Asumptions'!D89) -> 75250 | E14: =HLOOKUP(E$3,Controls!$A$5:$F$96,MATCH('Expense Assumptions'!$A14,Controls!$A$5:$A$96,0),0)*('Revenue Asumptions'!E89) -> 189644 | F14: =HLOOKUP(F$3,Controls!$A$5:$F$96,MATCH('Expense Assumptions'!$A14,Controls!$A$5:$A$96,0),0)*('Revenue Asumptions'!F89) -> 202475 | G14: =HLOOKUP(G$3,Controls!$A$5:$F$96,MATCH('Expense Assumptions'!$A14,Controls!$A$5:$A$96,0),0)*('Revenue Asumptions'!G89) -> 192360 | H14: =HLOOKUP(H$3,Controls!$A$5:$F$96,MATCH('Expense Assumptions'!$A14,Controls!$A$5:$A$96,0),0)*('Revenue Asumptions'!H89) -> 113470 | I14: =HLOOKUP(I$3,Controls!$A$5:$F$96,MATCH('Expense Assumptions'!$A14,Controls!$A$5:$A$96,0),0)*('Revenue Asumptions'!I89) -> 188125 | ... BI14: =HLOOKUP(BI$3,Controls!$A$5:$F$96,MATCH('Expense Assumptions'!$A14,Controls!$A$5:$A$96,0),0)*('Revenue Asumptions'!BI89) -> 1447558.6
A15: Sarge Technology and Hardware Sales - COGS | B15: =HLOOKUP(B$3,Controls!$A$5:$F$96,MATCH('Expense Assumptions'!$A15,Controls!$A$5:$A$96,0),0)*('Revenue Asumptions'!B102) -> 0 | C15: =HLOOKUP(C$3,Controls!$A$5:$F$96,MATCH('Expense Assumptions'!$A15,Controls!$A$5:$A$96,0),0)*('Revenue Asumptions'!C102) -> 0 | D15: =HLOOKUP(D$3,Controls!$A$5:$F$96,MATCH('Expense Assumptions'!$A15,Controls!$A$5:$A$96,0),0)*('Revenue Asumptions'!D102) -> 0 | E15: =HLOOKUP(E$3,Controls!$A$5:$F$96,MATCH('Expense Assumptions'!$A15,Controls!$A$5:$A$96,0),0)*('Revenue Asumptions'!E102) -> 0 | F15: =HLOOKUP(F$3,Controls!$A$5:$F$96,MATCH('Expense Assumptions'!$A15,Controls!$A$5:$A$96,0),0)*('Revenue Asumptions'!F102) -> 0 | G15: =HLOOKUP(G$3,Controls!$A$5:$F$96,MATCH('Expense Assumptions'!$A15,Controls!$A$5:$A$96,0),0)*('Revenue Asumptions'!G102) -> 0 | H15: =HLOOKUP(H$3,Controls!$A$5:$F$96,MATCH('Expense Assumptions'!$A15,Controls!$A$5:$A$96,0),0)*('Revenue Asumptions'!H102) -> 0 | I15: =HLOOKUP(I$3,Controls!$A$5:$F$96,MATCH('Expense Assumptions'!$A15,Controls!$A$5:$A$96,0),0)*('Revenue Asumptions'!I102) -> 0 | ... BI15: =HLOOKUP(BI$3,Controls!$A$5:$F$96,MATCH('Expense Assumptions'!$A15,Controls!$A$5:$A$96,0),0)*('Revenue Asumptions'!BI102) -> 0
A16: TACFI/STRATFI RDRE Program COGS (est. 70% of revenue) | B16: 0 | C16: 0 | D16: 0 | E16: 0 | F16: 0 | G16: 0 | H16: 0 | I16: 0 | J16: 0 | K16: 0 | L16: 0 | M16: 0 | N16: 0 | O16: 0 | P16: 0 | Q16: 155555.55 | R16: 155555.55 | S16: 155555.55 | T16: 155555.55 | U16: 155555.55 | V16: 155555.55 | W16: 155555.55 | X16: 155555.55 | Y16: 155555.55 | Z16: 155555.55 | AA16: 155555.55 | AB16: 155555.55 | AC16: 155555.55 | AD16: 155555.55 | AE16: 155555.55 | AF16: 155555.55 | AG16: 155555.55 | AH16: 155555.55 | AI16: 583333.33 | AJ16: 583333.33 | AK16: 583333.33 | AL16: 583333.33 | AM16: 583333.33 | AN16: 583333.33 | AO16: 583333.33 | AP16: 583333.33 | AQ16: 583333.33 | AR16: 583333.33 | AS16: 583333.33 | AT16: 583333.33 | AU16: 583333.33 | AV16: 583333.33 | AW16: 583333.33 | AX16: 583333.33 | AY16: 583333.33 | AZ16: 583333.33 | BA16: 583333.33 | BB16: 583333.33 | BC16: 583333.33 | BD16: 583333.33 | BE16: 583333.33 | BF16: 583333.33 | BG16: 583333.33 | BH16: 583333.33 | BI16: 583333.33
A17: Scorpius Tank Manufacturing COGS (est. 55% of revenue) | T17: 137500 | U17: 137500 | V17: 137500 | W17: 137500 | X17: 137500 | Y17: 137500 | Z17: 137500 | AA17: 137500 | AB17: 137500 | AC17: 137500 | AD17: 137500 | AE17: 137500 | AF17: 229166.85 | AG17: 229166.85 | AH17: 229166.85 | AI17: 229166.85 | AJ17: 229166.85 | AK17: 229166.85 | AL17: 229166.85 | AM17: 229166.85 | AN17: 229166.85 | AO17: 229166.85 | AP17: 229166.85 | AQ17: 229166.85 | AR17: 366666.85 | AS17: 366666.85 | AT17: 366666.85 | AU17: 366666.85 | AV17: 366666.85 | AW17: 366666.85 | AX17: 366666.85 | AY17: 366666.85 | AZ17: 366666.85 | BA17: 366666.85 | BB17: 366666.85 | BC17: 366666.85 | BD17: 504166.85 | BE17: 504166.85 | BF17: 504166.85 | BG17: 504166.85 | BH17: 504166.85 | BI17: 504166.85
A18: Total Cost of Sale (COS) | B18: =SUM(B9:B16) -> #N/A | C18: =SUM(C9:C16) -> #N/A | D18: =SUM(D9:D16) -> #N/A | E18: =SUM(E9:E16) -> #N/A | F18: =SUM(F9:F16) -> #N/A | G18: =SUM(G9:G16) -> #N/A | H18: =SUM(H9:H16) -> #N/A | I18: =SUM(I9:I16) -> #N/A | ... BI18: =SUM(BI9:BI16) -> #N/A
A20: Operating Expenses (OPEX)
A22: Internet and Phone | B22: =HLOOKUP(B$3,Controls!$A$5:$F$96,MATCH('Expense Assumptions'!$A22,Controls!$A$5:$A$96,0),0) -> 750 | C22: =HLOOKUP(C$3,Controls!$A$5:$F$96,MATCH('Expense Assumptions'!$A22,Controls!$A$5:$A$96,0),0) -> 750 | D22: =HLOOKUP(D$3,Controls!$A$5:$F$96,MATCH('Expense Assumptions'!$A22,Controls!$A$5:$A$96,0),0) -> 750 | E22: =HLOOKUP(E$3,Controls!$A$5:$F$96,MATCH('Expense Assumptions'!$A22,Controls!$A$5:$A$96,0),0) -> 750 | F22: =HLOOKUP(F$3,Controls!$A$5:$F$96,MATCH('Expense Assumptions'!$A22,Controls!$A$5:$A$96,0),0) -> 750 | G22: =HLOOKUP(G$3,Controls!$A$5:$F$96,MATCH('Expense Assumptions'!$A22,Controls!$A$5:$A$96,0),0) -> 750 | H22: =HLOOKUP(H$3,Controls!$A$5:$F$96,MATCH('Expense Assumptions'!$A22,Controls!$A$5:$A$96,0),0) -> 750 | I22: =HLOOKUP(I$3,Controls!$A$5:$F$96,MATCH('Expense Assumptions'!$A22,Controls!$A$5:$A$96,0),0) -> 750 | ... BI22: =HLOOKUP(BI$3,Controls!$A$5:$F$96,MATCH('Expense Assumptions'!$A22,Controls!$A$5:$A$96,0),0) -> 1688.2632
A23: Insurance | B23: =HLOOKUP(B$3,Controls!$A$5:$F$96,MATCH('Expense Assumptions'!$A23,Controls!$A$5:$A$96,0),0) -> 3000 | C23: =HLOOKUP(C$3,Controls!$A$5:$F$96,MATCH('Expense Assumptions'!$A23,Controls!$A$5:$A$96,0),0) -> 3000 | D23: =HLOOKUP(D$3,Controls!$A$5:$F$96,MATCH('Expense Assumptions'!$A23,Controls!$A$5:$A$96,0),0) -> 3000 | E23: =HLOOKUP(E$3,Controls!$A$5:$F$96,MATCH('Expense Assumptions'!$A23,Controls!$A$5:$A$96,0),0) -> 3000 | F23: =HLOOKUP(F$3,Controls!$A$5:$F$96,MATCH('Expense Assumptions'!$A23,Controls!$A$5:$A$96,0),0) -> 3000 | G23: =HLOOKUP(G$3,Controls!$A$5:$F$96,MATCH('Expense Assumptions'!$A23,Controls!$A$5:$A$96,0),0) -> 3000 | H23: =HLOOKUP(H$3,Controls!$A$5:$F$96,MATCH('Expense Assumptions'!$A23,Controls!$A$5:$A$96,0),0) -> 3000 | I23: =HLOOKUP(I$3,Controls!$A$5:$F$96,MATCH('Expense Assumptions'!$A23,Controls!$A$5:$A$96,0),0) -> 3000 | ... BI23: =HLOOKUP(BI$3,Controls!$A$5:$F$96,MATCH('Expense Assumptions'!$A23,Controls!$A$5:$A$96,0),0) -> 140180
A24: Professional Fees | B24: =HLOOKUP(B$3,Controls!$A$5:$F$96,MATCH('Expense Assumptions'!$A24,Controls!$A$5:$A$96,0),0) -> 3500 | C24: =HLOOKUP(C$3,Controls!$A$5:$F$96,MATCH('Expense Assumptions'!$A24,Controls!$A$5:$A$96,0),0) -> 3500 | D24: =HLOOKUP(D$3,Controls!$A$5:$F$96,MATCH('Expense Assumptions'!$A24,Controls!$A$5:$A$96,0),0) -> 3500 | E24: =HLOOKUP(E$3,Controls!$A$5:$F$96,MATCH('Expense Assumptions'!$A24,Controls!$A$5:$A$96,0),0) -> 3500 | F24: =HLOOKUP(F$3,Controls!$A$5:$F$96,MATCH('Expense Assumptions'!$A24,Controls!$A$5:$A$96,0),0) -> 3500 | G24: =HLOOKUP(G$3,Controls!$A$5:$F$96,MATCH('Expense Assumptions'!$A24,Controls!$A$5:$A$96,0),0) -> 3500 | H24: =HLOOKUP(H$3,Controls!$A$5:$F$96,MATCH('Expense Assumptions'!$A24,Controls!$A$5:$A$96,0),0) -> 3500 | I24: =HLOOKUP(I$3,Controls!$A$5:$F$96,MATCH('Expense Assumptions'!$A24,Controls!$A$5:$A$96,0),0) -> 3500 | ... BI24: =HLOOKUP(BI$3,Controls!$A$5:$F$96,MATCH('Expense Assumptions'!$A24,Controls!$A$5:$A$96,0),0) -> 3939.2808
