Workbook

Sheet Master Launch Schedule
A1: Exos Aerospace Master Launch Schedule | G1: Today's Date--> | H1: =TODAY() -> 43977
A2: Scheduled Launch Date: | D2: 44058.458 | E2: Scheduled Launch Time: | F2: =D2 -> 44058.458 | G2: Days to launch--> | H2: =D2-H1 -> 81.458333
A3: Pre-Launch and Regulatory Milestones
A4: Item # | B4: # of days before Launch | C4: Action Date | D4: Description | E4: Point of Contact | F4: Phone Number | G4: Email Address | H4: Notes:
A5: 1 | B5: 67 | C5: =$D$2-B5 -> 43991.458 | D5: Initial Hold Down Testing | E5: Internal
A6: 2 | B6: 65 | C6: =$D$2-B6 -> 43993.458 | D6: Spaceport Scheduling | E6: Bill Gutman | F6: 575-520-5433 | G6: bill.gutman@spaceportamerica.com
A7: 3 | B7: 60 | C7: =$D$2-B7 -> 43998.458 | D7: Send 60 Day Notification Including Payload Manifest. (Click for Contact List) | E7: Sherman Council/Henry Lampazzi | F7: 202-570-5819 | G7: sherman.council@faa.gov; Henry.Lampazzi@faa.gov; AST-400@faa.gov; annette.parks@faa.gov | H7: Notification by Email | I7: 60 Day Launch Notification, Click for requirements.
A8: 4 | B8: 45 | C8: =$D$2-B8 -> 44013.458 | D8: Request Launch Insurance Coverage, Send Certificates to AST when complete. | E8: Dana or Jason at Gallegher | F8: Dana Cell: 713-828-7319 | G8: dana.smith@ajg.com; Jason.Hendrix@ajg.com | H8: Request by Email, Follow up by Phone
A9: 5 | B9: 45 | C9: =$D$2-B9 -> 44013.458 | D9: Place Reservation for Crew Van with Enterprise Van Rental Specialties | E9: Sean Spradling | F9: 972-519-9697 | G9: sean.j.spradling@erac.com | H9: Request Chevy Express 15 Passenger Van by Phone, Follow up by Email. Do Not Rent the Ford Transit!
A10: 6 | B10: 45 | C10: =$D$2-B10 -> 44013.458 | D10: Place Reservation for Hotel in Las Cruces | E10: Fairfield Inn by Marriott | G10: (Needs Contact Info)
A11: 7 | B11: 30 | C11: =$D$2-B11 -> 44028.458 | D11: Send Insurance Certificates to AST | E11: AST-400, Sherman Council | G11: AST-400@faa.gov
A12: 8 | B12: 30 | C12: =$D$2-B12 -> 44028.458 | D12: Request Travel Insurance | E12: Roanoak Trade, Tom Moran | F12: 847-969-8232 | G12: Tom.Moran@roanokegroup.com | H12: Request by Email, Follow up by Phone
A13: 9 | B13: 30 | C13: =$D$2-B13 -> 44028.458 | D13: File Cross Waivers with AST, Send Final Payload Manifest. | E13: Ken Wong, AST-200 | F13: (202) 267-8465 | G13: Ken.Wong@faa.gov; henry.lampazzi@faa.gov; sherman.council@faa.gov; AST-400@faa.gov; | H13: Notify by email, Send original signature copies by US Mail
A14: 10 | B14: 21 | C14: =$D$2-B14 -> 44037.458 | D14: Complete System Integration test | E14: Internal
A15: 11 | B15: 15 | C15: =$D$2-B15 -> 44043.458 | D15: 15 Day Notification, Make the 10 Day Notification at the same time and include all of the required information. | E15: Sherman Council/Henry Lampazzi | F15: 202-570-5819 | G15: sherman.council@faa.gov; Henry.Lampazzi@faa.gov; AST-400@faa.gov; annette.parks@faa.gov | H15: Notification by Email | I15: 15 Day Noification to AST, Click for Requirements.
A16: 12 | B16: 10 | C16: =$D$2-B16 -> 44048.458 | D16: 10 Day notice to ARTCC and ZAB | E16: Tim McHale/ZAB 530 | G16: 9-asw-zab530@faa.gov; 9-AWA-AJR-SPCE.OPS@faa.gov; spaceops@spaceportamerica.com; Melanie.Ramos@faa.gov; beth.e.adams@faa.gov | H16: Notification done by Email at the 15 day mark | I16: 10 Day Notification to ZAB, Click for requirements.
A17: 13 | B17: 5 | C17: =$D$2-B17 -> 44053.458 | D17: Crane Truck Depart for Spaceport | E17: Jessica Harrell/Brian Mott | F17: 214-557-5536 | G17: Also Verify Van rental pickup | H17: The van should be brought to the shop and prepared for travel.
A18: 14 | B18: 3 | C18: =$D$2-B18 -> 44055.458 | D18: Crew depart for Spaceport | E18: Internal
A19: 15 | B19: 2 | C19: =$D$2-B19 -> 44056.458 | D19: 1st day of Setup | E19: Internal
A20: 16 | B20: 2 | C20: =$D$2-B20 -> 44056.458 | D20: Payload Integration Begins | E20: Brad Clouser | G20: Brad to oversee Payload readiness and integration timing | H20: To Be Done at the Spaceport Provided Facility.
A21: 17 | B21: 2 | C21: =$D$2-B21 -> 44056.458 | D21: Vehile Dry Run approximately 1:00 PM
A22: 18 | B22: 1 | C22: =$D$2-B22 -> 44057.458 | D22: 2nd Day of Setup | E22: Internal
A23: 19 | B23: 1 | C23: =$D$2-B23 -> 44057.458 | D23: Mission Readiness Review | E23: All Attendees
A24: 20 | B24: 0 | C24: =$D$2-B24 -> 44058.458 | D24: Launch Day | E24: Everyone
A25: 21 | B25: 0 | C25: =$D$2-B25 -> 44058.458 | D25: Post Flight Briefing

Sheet Day 1 Setup
A1: Day 1 Launch Setup | G1: Return to Master
A2: Item # | B2: Time to Launch | C2: Action Time | D2: Description | E2: Participants | F2: Estimated Time | G2: Notes:
A3: 1 | B3: ="T - "&'Master Launch Schedule'!D2-'Master Launch Schedule'!C20&" days" -> T - 2 days | C3: 0.29166667 | D3: Depart from the Hotel | E3: All Crew
A4: 2 | D4: Unpack Trailer and Truck | E4: All Crew
A5: 3 | D5: Prep Rocket for Combined Systems Test | E5: All Crew
A6: 4 | C6: 0.41666667 | D6: Combined Systems Test | E6: 3 or 4 people
A7: 5 | C7: 0.4375 | D7: Full Dry Run | E7: All Crew
A8: 6 | D8: Launch Pad Setup | E8: Joseph and 2 helpers
A9: 7 | C9: 1200.5 | D9: Break For Lunch | E9: All Crew
A10: 8 | D10: Set Up Helium 6 Packs for Pressuization | E10: =$E$13 -> Joseph and 1 helper
A11: 9 | D11: Set up Recovery system | E11: Phil and Lee
A12: 10 | D12: Set Up Exos Wifi | E12: Russ
A13: 11 | D13: Set Up Truck for Pad ops (Start) | E13: Joseph and 1 helper
A14: 12 | C14: 0.66666667 | D14: Get Everything back into the trailer. | E14: All Crew
A15: 13 | C15: 0.70833333 | D15: Depart Launch Site | E15: All Crew
A16: 14
A17: 15
A18: 16
A19: 17
A20: 18
A21: 19

Sheet Day 2 Setup
A1: Day 2 Launch Setup | G1: Return to Master
A2: Item # | B2: Time to Launch | C2: Action Time | D2: Description | E2: Participants | F2: Estimated Time | G2: Notes:
A3: 1 | B3: ="T - "&'Master Launch Schedule'!$D$2-'Master Launch Schedule'!$C$23&" days" -> T - 1 days | C3: 0.29166667 | D3: Depart from the Hotel | E3: All Crew | F3: 75 minutes
A4: 2 | C4: 0.34375 | D4: Unpack Trailer | E4: All Crew | F4: 30 minutes
A5: 3 | D5: Tightness Check and Reassembly | E5: 3 people | F5: 2 to 3 hours
A6: 4 | D6: Start Pressurization on Press Section | E6: Joseph | F6: All Day
A7: 5 | D7: Finish Pad Ops Prep on Crane Truck | E7: Joseph | F7: 2 hours concurrent to Pressurization.
C8: 0.41666667 | D8: Walk Through with John and Guests | E8: John Quinn | F8: 1 hour+ | G8: John will escort visitors around the Launch Control Area and discuss the stations they see as well as the rocket in process.
A9: 6 | C9: 0.5 | D9: Lunch Break | E9: All Crew
A10: 7 | C10: 0.54166667 | D10: Role Assignment and Training | E10: Tiffany Long and Teresa Quinn | F10: 1 to 2 hours | G10: All Contractors filling Roles MUST be onsite no later than 1:00PM!
A11: 8 | D11: LOX Transfill | E11: 1 or 2 people
A12: 9 | D12: Final Assembly of the Recovery system | E12: 2 people | F12: 2 hours
A13: 10 | D13: Finalize Checklist and Print | E13: Russ | F13: 2 hours
A14: 11 | D14: Collect and File Subassembly Checklists | E14: Haley or Russ or Logistics Coordinator | F14: 30 minutes | G14: Ne a list of Subassembly Checklists. Must be filed in Vehicle Log Folder.
A15: 12 | C15: 0.66666667 | D15: Repack for the night, Fuel Generators and Gator | E15: 2 People | F15: 30 to 60 minutes
A16: 13 | C16: 0.70833333 | D16: Attend MRR | E16: All Crew and Day Of Launch Attendees | F16: 1 hour
A17: 14 | D17: Depart Spaceport
A18: 15
A19: 16
A20: 17
A21: 18
A22: 19

Sheet Launch Day
A1: Launch Day | G1: Return to Master
A2: Item # | B2: Time to Launch | C2: Action Time | D2: Description | E2: Participants | F2: Estimated Time | G2: Notes:
A3: 1 | B3: ='Master Launch Schedule'!$F$2-C3 -> 44058.25 | C3: 0.20833333 | D3: Depart from the Hotel | E3: All Crew
A4: 2 | B4: ='Master Launch Schedule'!$F$2-C4 -> 44058.208 | C4: 0.25 | D4: Unpack Trailer | E4: All Crew
A5: 3 | B5: ='Master Launch Schedule'!$F$2-C5 -> 44058.167 | C5: 0.29166667 | D5: Check Press Section, bump press if needed. | E5: Joseph and Helper
A6: 4 | B6: ='Master Launch Schedule'!$F$2-C6 -> 44058.125 | C6: 0.33333333 | D6: Start Rocket Assembly | E6: All Crew | G6: Payload must be complete with Can going on at this time!
A7: 5 | B7: ='Master Launch Schedule'!$F$2-C7 -> 44058.104 | C7: 0.35416667 | D7: Final Installation of Payload Section | E7: All Crew | F7: 15 minutes
A8: 6 | B8: ='Master Launch Schedule'!$F$2-C8 -> 44058.094 | C8: 0.36458333 | D8: Final Installation of Recovery Section | E8: All Crew | F8: 15 minutes
A9: 7 | B9: ='Master Launch Schedule'!$F$2-C9 -> 44058.083 | C9: 0.375 | D9: Turn on Rocket verify connections good. | E9: All Crew
A10: 8 | C10: 0.38541667 | D10: Roll to Pad | E10: All Crew
A11: 9 | B11: ='Master Launch Schedule'!$F$2-C11 -> 44058.056 | C11: 0.40277778 | D11: Photo Opportunity on Pad | E11: All Attendees
A12: 10 | B12: ='Master Launch Schedule'!$F$2-C12 -> 44058.042 | C12: 0.41666667 | D12: All Nonessential Personnel return to Spaceport viewing area
A13: 11 | B13: ='Master Launch Schedule'!$F$2-C13 -> 44058.042 | C13: 0.41666667 | D13: Start Launch Procedure | E13: All Crew
A14: 12 | B14: =ABS('Master Launch Schedule'!$F$2-C14) -> 44058.026 | C14: 0.43194444 | D14: Start Hazardous Ops | E14: All Crew
A15: 13 | B15: =ABS('Master Launch Schedule'!$F$2-C15) -> 44058 | C15: 0.45833333 | D15: Planned Launch Time | E15: All Eyes
A16: 14 | B16: =ABS('Master Launch Schedule'!$F$2-C16) -> 44057.997 | C16: 0.46111111 | D16: Apogee | E16: All Eyes
A17: 15 | B17: =ABS('Master Launch Schedule'!$F$2-C17) -> 44057.994 | C17: 0.46458333 | D17: Main Deployment | E17: All Eyes
A18: 16 | B18: =ABS('Master Launch Schedule'!$F$2-C18) -> 44057.986 | C18: 0.47222222 | D18: Rocket Lands under Main | E18: All Eyes | G18: Nose lands about the same time. Check with Spotters for Location Confirmation.
A19: 17 | D19: Retrieval team to Rocket | E19: 4 to 6 people
A20: 18 | D20: Retrieval team to Nose location | E20: 2 to 4 people
A21: 19 | D21: Pack Trailer and Truck | E21: 2 or 3 people | G21: Concurrent Operation with Nose Retrieval
A22: 20 | D22: Post Mission Briefing | E22: John, Neil, Phil, Russ | G22: May or may not happen depending on AST Schedule.
A23: 21 | D23: Leave Launch Site | E23: All Crew

Sheet 60 Day Notification Contacts
A1: Email Contacts:
A2: sherman.council@faa.gov;
A3: Henry.Lampazzi@faa.gov;
A4: AST-400@faa.gov;
A5: annette.parks@faa.gov;
A7: jquinn@exosaero.com;
A8: nmilburn@exosaero.com;
A9: smillard@exosaero.com;
A10: peaton@exosaero.com
A11: tlong@exosaero.com;

Sheet Schedule for 15day Notification
A1: Days Before Launch Date | B1: Hours Before Launch Time | C1: Travel | D1: Launch Schedule, ALL TIMES ARE APPROXIMATE | E1: MDT is GMT-6 | F1: 6.25 | G1: Summer, Fall
A2: 4 | B2: 3 | C2: ='Master Launch Schedule'!$D$2-('Schedule for 15day Notification'!A2+(0.0416*B2)) -> 44054.334 | D2: Crane and Rocket Depart to New Mexico - Overnight in Van Horn for crane truck | E2: MST is GMT-7 | F2: 7.2916667 | G2: Winter, Spring
A3: 3 | B3: 23 | C3: ='Master Launch Schedule'!$D$2-('Schedule for 15day Notification'!A3+(0.04166*B3)) -> 44054.5 | D3: Exos Team pickup and pack Rental Van
A4: 3 | B4: 3 | C4: ='Master Launch Schedule'!$D$2-('Schedule for 15day Notification'!A4+(0.04166*B4)) -> 44055.333 | D4: Exos Team departs for Las Cruces | G4: Email Contacts:
A5: 3 | B5: 1 | C5: ='Master Launch Schedule'!$D$2-('Schedule for 15day Notification'!A5+(0.04166*B5)) -> 44055.417 | D5: Crane and Rocket trailer continue to site at Spaceport NM | G5: 15 Day Notification Contacts | I5: sherman.council@faa.gov;
A6: 2 | B6: 23 | C6: ='Master Launch Schedule'!$D$2-('Schedule for 15day Notification'!A6+(0.04166*B6)) -> 44055.5 | D6: Crane and Rocket trailer arrive at Spaceport NM | I6: Henry.Lampazzi@faa.gov;
A7: 2 | B7: 19 | C7: ='Master Launch Schedule'!$D$2-('Schedule for 15day Notification'!A7+(0.04166*B7)) -> 44055.667 | D7: Crane and Rocket trailer team arrives at Las Cruces hotel | I7: AST-400@faa.gov;
A8: 2 | B8: 15 | C8: ='Master Launch Schedule'!$D$2-('Schedule for 15day Notification'!A8+(0.04166*B8)) -> 44055.833 | D8: Exos Team arrives at Las Cruces hotel | I8: annette.parks@faa.gov;
A9: 2 | C9: ='Master Launch Schedule'!$D$2-'Schedule for 15day Notification'!A9 -> 44056.458 | D9: Set Up Day 1
C10: 0.29166667 | D10: Depart from the Hotel | I10: jquinn@exosaero.com;
D11: Unpack Trailer and Truck, Prep Rocket for Combined Systems Test | I11: nmilburn@exosaero.com;
C12: 0.41666667 | D12: Combined Systems Test | I12: smillard@exosaero.com;
C13: 0.4375 | D13: Full Dry Run | I13: peaton@exosaero.com
D14: Launch Pad Setup | I14: tlong@exosaero.com;
C15: 0.5 | D15: Break For Lunch
D16: Set up recovery system, Set Up Exos Wifi | G16: 10 day notification contacts. See next tab for data requirement. | I16: 9-asw-zab530@faa.gov;
C17: 0.66666667 | D17: Get Everything back into the trailer. | I17: 9-AWA-AJR-SPACE.OPS@faa.gov;
C18: 0.70833333 | D18: Depart Launch Site | I18: spaceops@spaceportamerica.com;
A19: 1 | C19: ='Master Launch Schedule'!$D$2-'Schedule for 15day Notification'!A19 -> 44057.458 | D19: Set Up Day 2 | I19: Craig.Brenden@faa.gov
C20: 0.29166667 | D20: Depart from Hotel | I20: beth.e.adams@faa.gov;
C21: 0.33333333 | D21: Unpack trailer, Tightness Check and Reassembly
D22: Start Pressurization on Press Section, Finish Crane Truck Prep for Pad Ops
D23: Payload customers arrive and prepare payloads
C24: 0.5 | D24: Lunch Break
C25: 0.54166667 | D25: Role Assignment and Training
C26: 0.70833333 | D26: Mission Readiness Review
A27: 0 | C27: ='Master Launch Schedule'!$D$2-'Schedule for 15day Notification'!A27 -> 44058.458 | D27: Launch Day
C28: 0.20833333 | D28: Depart from the Hotel
C29: 0.25 | D29: Unpack Trailer
C30: 0.29166667 | D30: Check Press Section, bump press if needed.
C31: 0.33333333 | D31: Start Rocket Assembly
C32: 0.35416667 | D32: Final Installation of Payload Section
C33: 0.36458333 | D33: Final Installation of Recovery Section
C34: 0.375 | D34: Turn on Rocket verify connections good.
C35: 0.38541667 | D35: Roll to Pad
C36: 0.40277778 | D36: Photo Opportunity on Pad
C37: 0.41666667 | D37: All Nonessential Personnel return to Spaceport viewing area
C38: 0.41666667 | D38: Start Launch Procedure
C39: 0.43194444 | D39: Start Hazardous Ops | E39: GMT Summer/fall | F39: GMT Winter/Spring
C40: ='Master Launch Schedule'!F2 -> 44058.458 | D40: Planned Launch Time | E40: =C27+F1 -> 44064.708 | F40: =C27+F2 -> 44065.75
...

Sheet 10 Day Notification Content
A1: 10 Day Notification Requirements | C1: Return to Master
A2: Date and Time of Launch | B2: October 26th 2019, 16:00-18:30 GMT (or 10:00-12:30 MDT) Alternate date, October 27th with the same times.
A3: Radius of the Hazard area | B3: 7KM from (32.943694, –106.922361)
A4: Expected Altitude | B4: Expected 90KM, Maximum 105KM
A5: Verify Coordination with White Sands Missile Range | B5: Noted from AST Meeting, verify with Bill Gutman at SPAM
A7: 10 Day Notification Email Contacts:
A8: ='Schedule for 15day Notification'!I16 -> 9-asw-zab530@faa.gov;
A9: ='Schedule for 15day Notification'!I17 -> 9-AWA-AJR-SPACE.OPS@faa.gov;
A10: ='Schedule for 15day Notification'!I18 -> spaceops@spaceportamerica.com;
A11: ='Schedule for 15day Notification'!I19 -> Craig.Brenden@faa.gov
A12: ='Schedule for 15day Notification'!I20 -> beth.e.adams@faa.gov;
A15: (c) Notify ZAB Airspace & Procedures Office and ATCSCC Space Operations ten (10) business days in advance of their scheduled launch. If the request is made within ten (10) business days, it will be approved at the discretion of the ZAB Support Manager for Airspace and Procedures. 1. The notification must include:
A16: a. Dates and time of mission, back-up times
A17: b. Radius of Hazard Area
A18: c. Altitude
A19: d. Confirmation that coordination has been accomplished with White Sands Missile Range, if R5107B, R5111A/B/C/D will be affected.

Sheet Final Assembly Checklist
A1: Final Vehicle Assembly Checklist
A2: Item # | B2: Description | C2: Check 1 | D2: Check 2
A3: 1 | B3: Fin Can On and Connected
A4: 2 | B4: Press Section On and Connected
A5: 3 | B5: Main Flight Computer On and Connected
A6: 4 | B6: Payload Section On and Connected
A7: 5 | B7: Recovery Section On and Connected
A8: 6 | B8: Rocket On, All Connections Verified Ready for Flight
A9: Date:

Sheet Recovery Section Checklist
A1: Recovery Section Checklist
A2: Flight Number:____Flight Location:____________________________
B3: Pressurize nose tank to 1100 psi.
B4: Charge nose tracker battery
B5: Ensure yellow pin is installed
B6: Verify GPS Landing Coordinates are programmed into the AGU
B7: Install Main Parachute
B8: Connect the pull cord to the AGU flight switch
B9: Connect the Right and Left control lines to the AGU
B10: Verify the control lines go straight down the spool and not over the top
B11: Verify length of control line on AGU spools
B12: Ensure the recovery system bolts are tight and sealed
B13: Connect the Drogue link to the Kevlar strap leading through the cutters
B14: Ensure cut sensor wire goes through both cutters.
... B22: Install the recovery section on the rocket
A24: Completed By __________________ Date ______________

Sheet CPU Pressure Check
A1: CPU Pressure Check | C1: Date | D1: ________________
G2: Completed By | H2: Checked By
A3: 1 | B3: Assemble CPU and payload with appropriate seals - Execute CPU to Payload Assembly Checklist
A4: 2 | B4: Verify all bolts on pressure sides in place
A5: 3 | B5: Turn on CPU using either debug power and RF cables or connected to vehicle
A6: 4 | B6: Run ITOS and start CPU press plot
A7: 5 | B7: Add 10psi to current CPU pressure using compressed air
A8: 6 | B8: Let CPU rest for 2 minutes
A9: 7 | B9: Measure initial CPU pressure | C9: Initial pressure
A10: 8 | B10: Wait 10 minutes, measure final CPU pressure | C10: Final pressure
A11: 9 | B11: Pass < 5psi loss in 10 minutes | C11: Pass/Fail
A12: 10 | B12: Proceed to assembling CPU to Press Section

Sheet CPU to Payload Assembly
A1: CPU to Payload Assembly Checklist | G1: Date | H1: ______________
G3: Completed By | H3: Checked By
A4: 1 | B4: Clean payload o-ring grove
A5: 2 | B5: Krytox o-ring and groove
A6: 3 | B6: Install o-ring
A7: 4 | B7: Connect Main CPU connector
A8: 5 | B8: Connect ACS connector
A9: 6 | B9: Connect GPS connector and torque
A10: 7 | B10: Connect AGU connector and torque
A11: 8 | B11: Allign Z- and attach payload to CPU
A12: 9 | B12: Secure with 60 10-32 5/16" 100CSK

Sheet CPU to Press Section Assembly
A1: CPU to Press Section Assembly | G1: Date | H1: ______________
G3: Completed By | H3: Checked By
A4: 1 | B4: Align the computer section with the pressure section in the correct orientation for flight.
A5: 2 | B5: Connect the appropriate AN-10 upper ACS gas feed line to the CPU bulkhead connection using an Aluminum seal. Ensure hose orientation lays smoothly and the hose is connected in such a manner as it will not loosen when the CPU section is attached to the pressure section
A6: 3 | B6: Connect the sensors, actuators and Lower ACS D connections (3 Cannon Plugs)
A7: 4 | B7: Connect the Antennae cables (at least 3) 2 Comms and 1 AGU
A8: 5 | B8: Visually inspect to ensure no wires or gas lines will be kinked caught or scraped while sliding the CPU section onto the Pressure section
A9: 6 | B9: Secure CPU bulkhead to the pressure section with screws match Z- orientation

Sheet Recovery Glow Plug Test
A1: Recovery Glow Plug Check | Q1: Date | R1: _____________
Q3: Completed By | R3: Checked By
A4: 1 | B4: Disconnect glow plugs, both cutters
M6: Lamp Resistance
A7: 2 | B7: Measure impedance between each the two plug leads on each side, should be 2-2.5 ohms | M7: Left | O7: Right
A9: 3 | B9: Connect leads to glow plugs
M11: Plug impedance
A12: 4 | B12: Measure resistance between power wires at the power supply, must be 0.6 - 1.0 ohms | M12: Left | O12: Right
A14: 5 | B14: Pass / Fail | D14: lamp impedance is not required to pass | M14: Left | O14: Right

Sheet Recovery to Payload Assembly
A1: Recovery to Payload Assembly | G1: Date | H1: ________________
G3: Completed By | H3: Checked By
A4: 1 | B4: Connect main CPU connector
A5: 2 | B5: Connect GPS cable and torque
A6: 3 | B6: Connect AGU cable and torque
A7: 4 | B7: Align Z- and set recovery into payload section
A8: 5 | B8: Secure with 60 10-32 5/16" 100CSK bolts

Sheet Preflight Press Section
B1: SARGE: Preflight pressurization section Field Operations Checklist
B2: The purpose of this checklist is to ensure safe remote pressurization of the high pressure tank used for onboard pressure in the SARGE vehicle.
B3: INITIAL SETUP
A4: 1 | B4: Place vehicle pressure section on it's handling cart in a safe location out of the way of work areas and foot traffic
A5: 2 | B5: Set Haskel pump transport box adjacent to Press section
A6: 3 | B6: Set a FULL Helium 6 pack a few feet from Press section, this is the pressurization supply and control area
A7: 4 | B7: Set High Volume High Pressure (HVHP) Helium tanks in same location
A8: 5 | B8: Install shade over press section
A9: 6 | B9: Unpack the pump box and place the pump on top of the box
A10: 7 | B10: Co-locate the Gas powered compressor within easy reach and where the operator is able to easily see the pressure gage on the compressor
A11: 8 | B11: Make sure the Haskel pump operating valve is closed
A12: 9 | B12: Connect the Compressor air line to the Haskel Pump
A13: 10 | B13: Check the oil and start the compressor to make sure it operates, bring it up to full pressure and shut it off
A14: 11 | B14: Setup work table, tools and hardware.
A15: 12 | B15: Install 6K psi CONCOA regulator on the helium 6 pack.
... A19: 16 | B19: Hang the gage in a safe location to make sure it does not fall
B20: COOLING and MONITORING Setup
A21: 17 | B21: Place the air conditioning unit on the cart under the pressure section and level with a 3/4 to 1 inch shim
A22: 18 | B22: Install the cooling plenum on the bottom end of the pressure section with the fill line passing through the notch on the plenum
A23: 19 | B23: Connect Air conditioner to generator power and turn on to begin cooling Receiving tank. Verify that the AC is set to cool and the fan is on high.
A24: 20 | B24: Place a fully charged automotive battery next to the Air unit on a wooden board to insulate it from the cart and raise it above any condensation that could come from the Air Conditioner
A25: 21 | B25: Install press section monitoring adapter orange case to 2 main cables and 2 thermocouple connections at top of press section
A26: 22 | B26: Connect monitoring adapter to the Battery, Blue LED should come on
A27: 23 | B27: Connect extended USB cable to laptop located at the pressurization supply and control area.
A28: 24 | B28: on Laptop, open press terminal shortcut.
A29: 25 | B29: Under the system tab Open settings and select settings appropriate to the press section you are servicing
A30: 26 | B30: When the settings window opens click on apply
A31: 27 | B31: Connect to the press section GSE adapter using the connect button in the open window on the laptop
A32: 28 | B32: Click on F checked for thermocouple data in Fahrenheit and click on filter to get more consistent readings
A33: 29 | B33: Numbers close to the travel pressure and a reasonable approximation of temperature should appear. If not, trouble shoot system for leaks, sensor failures, etc. Note Temp and pressure. _________________________
B34: PRESSURIZATION
A35: 30 | B35: With the plumbing assembled and not connected to the receiving tank. Secure the high pressure outlet end of the hose to prevent/eliminate hose whip when blowing the line clear
A36: 31 | B36: Close all cylinder valves on the helium 6 pack.
A37: 32 | B37: Close the CONCOA 6Kpsi regulator
A38: 33 | B38: Open the first cylinder to be used on the Helium 6 pack and the main valve and briefly open then close the regulator to blow the entire line clear
A39: 34 | B39: Connect the booster pump pressure outlet hose to pressure section of the rocket
A40: 35 | B40: Connect thermocouple extensions on the high pressure side of the booster pump to the thermocouple readout unit
A41: 36 | B41: Close the High pressure line vent valve
A42: 37 | B42: Pressurize the system to 200psi close the regulator and check for leaks with soapy water if available.
A43: 38 | B43: Relieve the pressure in the system to avoid rapid overpressure of the rocket high pressure tank if it has lost its pressure charge
...

Sheet Engine Bay Preflight Checklist
B1: Engine Bay Preflight Checklist
B3: Tools Needed:
B4: 2) 9-16" Wrenches
B5: 1) Small Cresent Wrench
B6: 1) 7-16" Wrench
B7: 1) 3-16" Allen Wrench
B8: 1) -10 AN Wrench
B9: 1) SMA Torque Wrench (assembly to airframe)
B11: (TS) = verify Torque Seal Paint is intact.
B12: PLUMBING
A13: 1 | B13: Fuel pressure transducer hardline both ends (TS)
A14: 2 | B14: Fuel overboard dump connection both ends on dump valve inlet side (TS)
A15: 3 | B15: Fuel overboard dump hose to valve outlet (PRE-Launch only)
A16: 4 | B16: FUEL sanitary From tank adapter to top of valves
A17: 5 | B17: FUEL Fill/drain extension on inter-valve plumbing
A18: 6 | B18: Flex line from fill/drain extension to igniter solenoid both ends
A19: 7 | B19: Fuel Purge connection at bottom of valve set both ends
A20: 8 | B20: Fuel Sanitary connection to Main line at bottom of valves
A21: 9 | B21: Fuel Sanitary connection from main line to engine
A22: 10 | B22: Fuel purge feed from ullage pipe to purge solenoid both ends
A23: 11 | B23: ACS Gas feed connection to Ullage pipe
A24: 12 | B24: Sanitary clamp connecting LOX downpipe to flex line
... A44: 32 | B44: Main ACS connection on Fin Can (1 AN-10 Hose 42" long) (TS)
B45: HARDWARE AND ACTUATORS
A46: 33 | B46: Check gimbal beams for weld cracks
A47: 34 | B47: Bolts on LOX fill/drain extension (2) (TS)
A48: 35 | B48: Bolts on FUEL fill/drain extension (2) (TS)
A49: 36 | B49: Nuts on Purge solenoids' bracket (2) (TS)
A50: 37 | B50: Gimbal Linear Actuator u-joint bolts to gimbal beams (2)
A51: 38 | B51: Gimbal linear actuators lock nuts on threaded shaft to heim joint (4) (TS)
A52: 39 | B52: Engine gimbal actuator attach points bolts and lock nuts (2) (TS)
A53: 40 | B53: Valve assembly clevis pins and retainer clips (circlips) (2)
A54: 41 | B54: Valve actuator clamp rings (2) (TS)
A55: 42 | B55: Bolts for Heim joints from thrust cross to gimbal ring (2) (TS)
A56: 43 | B56: Gimbal ring bolts (4) (TS)
A57: 44 | B57: Lock nuts on engine swing limit bolts (2 on cross 2 on engine) (TS)
... A61: 48 | B61: Bolts on bottom of igniter solenoids (4) (TS)
B62: ELECTRICAL CONNECTIONS
A63: 49 | B63: LOX pressure transducer
A64: 50 | B64: Fuel pressure transducer
...

Sheet Pad Ops Tools Checklist
A1: Pad Ops Tools Checklist
A2: Pad Tools List
A3: # | B3: Description | C3: Check
A4: 1 | B4: Large Sanitary "T" Handle
A5: 2 | B5: Vent Valve Handle
A6: 3 | B6: Cap T Handles
A7: 4 | B7: 2 Crescent Wrenches
A8: 5 | B8: Power Supply Box
A9: 6 | B9: 2 Inverter Boxes
A10: 7 | B10: 2 Extension cords
A11: 8 | B11: 12V Heavy duty "Y" Cable
A12: 9 | B12: Medium Large Needle Nose Pliars
A13: 10 | B13: Wire Cutters
A14: 11 | B14: 2 Phillips Screw Drivers
A15: 12 | B15: 1 Slot Screw Driver
... A17: 14 | B17: Trash Bucket
A18: 15

Sheet Rocket Retrieval Tools Checklis
A1: Rocket Retreival Tools Checklist
A2: # | B2: Description | C2: QTY
A3: 1 | B3: Yellow Stand
A4: 2 | B4: Small Electric Screwdrivers
A5: 3 | B5: Manual Screwdrivers
A6: 4 | B6: 7/16" Wrenches
A7: 5 | B7: 3/4" Socket and ratchet
A8: 6 | B8: Dykes
A9: 7 | B9: Tank Vent Wrench
A10: 8 | B10: Tie Wraps
A11: 9 | B11: Containers for screws
A12: 10 | B12: Recovery blanket for Main Parachute
A13: 11 | B13: Large bin for Main Parachute
A14: 12 | B14: Plywood or cardboard to keep dirt out of recovery section
... A17: 15 | B17: Battery for Lift Device

Sheet Personal Equipment Checklist
A1: Personal Equipment and Tools Checklist, Phil
A2: Checklist for: Phil
A3: # | B3: Description | C3: Check
A4: 1 | B4: Flight Suit
A5: 2 | B5: Hat
A6: 3 | B6: Goggles
A7: 4 | B7: Extra Dessert Shoes
A8: 5 | B8: Spare Rocket Tracking Radio and GPS Equipment
A9: 6 | B9: Spare Audio Patch Cords
A10: 7 | B10: Recovery System Tool Box
A11: 8 | B11: Recovery Laptop
A12: 9
A13: 10
A14: 11
A15: 12
A16: 13
A17: 14
A18: 15
